Workbook

Sheet VARIABLES
A1: BitWealth (Pty) Ltd — Cashflow Model Variables
A2: v4.0 · 96-Month Forecast (8 Years) · Adjust YELLOW cells · Forecast tab auto-recalculates · FSP: CAEP (fixed cost)
A4: RETURN & PERFORMANCE ASSUMPTIONS
A5: Annual portfolio return — Years 1–3 (p.a.) | B5: 0.6 | C5: 60% p.a. BTC bull cycle (months 1 → y4_start-1); divided by 12 for monthly
A6: Annual portfolio return — Year 4 (p.a.) | B6: 0.1 | C6: 10% moderate/consolidation (months y4_start → y5_start-1)
A7: Year 4 starts (model month #) | B7: 37 | C7: Month 37 = July 2029
A8: Year 5 starts (model month #) | B8: 49 | C8: Month 49 = July 2030 — start of next BTC halving cycle
A9: Annual portfolio return — Years 5–7 (p.a.) | B9: 0.5 | C9: Bull cycle (months y5_start → y8_start-1). Default 50% — adjust for conservative scenario
A10: Year 8 starts (model month #) | B10: 85 | C10: Month 85 = July 2033 — final bear/consolidation year
A11: Annual portfolio return — Year 8 (p.a.) | B11: 0.1 | C11: Final year bear/consolidation. Mirrors Y4 assumption. Change to 0% for severe bear
A12: Performance fee crystallisation period (months) | B12: 12 | C12: 12 = annual crystallisation (simplified to monthly accrual in formulas)
A13: Monthly liquidity buffer provision (R) | B13: 0 | C13: Set aside in Y1-3 AND Y5-7 (bull years). Not provisioned in Y4 and Y8 (bear years). Reserve Fund Bal tracks cumulative total
A15: EXCHANGE FEE SHARE REVENUE (VALR revenue-share deal)
A16: VALR exchange fee rate per trade | B16: 0.001 | C16: 0.1% default. Covers ZAR/USDT, USDT/BTC, and USDT/USDPC conversions. Adjust if VALR rate changes
A17: BitWealth share of exchange fees | B17: 0.5 | C17: 50% — as negotiated with VALR. Applied to both AUM-trading and new-contribution revenue streams
A18: % of total AUM traded per month (rebalancing/DCA) | B18: 0.25 | C18: 25% default: a quarter of existing AUM is traded/rebalanced each month. AUM revenue = prev_AUM × trade_pct × fee_rate × share
A20: FSP COSTS — CAEP (fixed cost model)
A21: CAEP onboarding fee (once-off, Month 1) | B21: 57500 | C21: Juristic Representative appointment; non-recurring
A22: CAEP hosting — Months 1–3 (per month) | B22: 23000
A23: CAEP hosting — Months 4–6 (per month) | B23: 34500
A24: CAEP hosting — Month 7+ (per month, steady-state) | B24: 46000 | C24: Negotiate a contractual cap; dominant cost driver
A25: CAEP hosting annual inflation rate | B25: 0.06 | C25: 6% p.a. default. Compounds year-on-year from Year 2 on all hosting tiers (Year 1 = base rate)
A26: CAEP AUM fee (% of AUM, billed annually) | B26: 0.0025 | C26: 0.25% p.a.; charged in months 12, 24, 36 … 96 on end-of-month AUM
A27: Software & infrastructure (monthly) | B27: 5000 | C27: Cloud, Supabase, VALR API, domain etc.
A28: Company secretarial (annual, months 12/24/36 …) | B28: 3000 | C28: CIPC annual return + company secretary
A30: CLIENT 1 (Founding — preferential 2.5% perf fee)
A31: Start month | B31: 1 | C31: Month 1 = June 2026
A32: Initial lump sum (R) | B32: 300000
A33: Monthly contribution (R) | B33: 200000
A34: Platform fee rate | B34: 0.0075 | C34: 0.75%
A35: Performance fee rate | B35: 0.025 | C35: 2.5% preferential
A37: CLIENT 2 (Founding)
A38: Start month | B38: 2 | C38: Month 2 = July 2026
A39: Initial lump sum (R) | B39: 0
A40: Monthly contribution (R) | B40: 40000
A41: Platform fee rate | B41: 0.0075
A42: Performance fee rate | B42: 0.1 | C42: Standard 10%
A44: CLIENT 3 (Founding — large lump sum, no monthly contributions)
A45: Start month | B45: 2 | C45: Month 2 = July 2026
A46: Initial lump sum (R) | B46: 5000000 | C46: 0.75% platform fee = R37 500 on day 1
...

Sheet MONTHLY FORECAST
A1: BitWealth (Pty) Ltd — 96-Month Cashflow Forecast v4.0 · FSP: CAEP · All formulas auto-update when VARIABLES sheet changes
A2: PERIOD | D2: CLIENT DETAIL (hidden — click + to expand) | Y2: REVENUE | AD2: TOTAL AUM | AE2: COSTS | AK2: RESERVE | AL2: CASHFLOW
A3: Month # | B3: Month | C3: Monthly Return % | D3: C1 Contrib | E3: C1 Plat | F3: C1 Perf | G3: C1 AUM | H3: C2 Contrib | I3: C2 Plat | J3: C2 Perf | K3: C2 AUM | L3: C3 Contrib | M3: C3 Plat | N3: C3 Perf | O3: C3 AUM | P3: C4 Contrib | Q3: C4 Plat | R3: C4 Perf | S3: C4 AUM | T3: NC Clients | U3: NC Contrib | V3: NC Plat | W3: NC Perf | X3: NC AUM | Y3: Total Contrib | Z3: Total Plat Fee | AA3: Total Perf Fee | AB3: Exchange Fee Rev | AC3: TOTAL REVENUE | AD3: TOTAL AUM | AE3: CAEP Onboard | AF3: CAEP Hosting | AG3: CAEP AUM Fee | AH3: Software | AI3: Co Sec | AJ3: TOTAL COSTS | AK3: Reserve Provision | AL3: NET CASH (after reserve) | AM3: CUMULATIVE CASH | AN3: Reserve Fund Bal
A4: 1 | B4: =TEXT(DATE(VARIABLES!$B$70+INT((VARIABLES!$B$71+$A4-2)/12),MOD(VARIABLES!$B$71+$A4-2,12)+1,1),"mmm-yy") -> Jun-26 | C4: =IF($A4<VARIABLES!$B$7,VARIABLES!$B$5/12,IF($A4<VARIABLES!$B$8,VARIABLES!$B$6/12,IF($A4<VARIABLES!$B$10,VARIABLES!$B$9/12,VARIABLES!$B$11/12))) -> 0.05 | D4: =IF($A4<VARIABLES!$B$31,0,IF($A4=VARIABLES!$B$31,VARIABLES!$B$32+VARIABLES!$B$33,VARIABLES!$B$33)) -> 500000 | E4: =D4*VARIABLES!$B$34 -> 3750 | F4: =IF($A4<VARIABLES!$B$31,0,(IF($A4=VARIABLES!$B$31,0,G3)+D4)*C4*VARIABLES!$B$35) -> 625 | G4: =IF($A4<VARIABLES!$B$31,0,(IF($A4=VARIABLES!$B$31,0,G3)+D4)*(1+C4)-F4) -> 524375 | H4: =IF($A4<VARIABLES!$B$38,0,IF($A4=VARIABLES!$B$38,VARIABLES!$B$39+VARIABLES!$B$40,VARIABLES!$B$40)) -> 0 | I4: =H4*VARIABLES!$B$41 -> 0 | J4: =IF($A4<VARIABLES!$B$38,0,(IF($A4=VARIABLES!$B$38,0,K3)+H4)*C4*VARIABLES!$B$42) -> 0 | K4: =IF($A4<VARIABLES!$B$38,0,(IF($A4=VARIABLES!$B$38,0,K3)+H4)*(1+C4)-J4) -> 0 | L4: =IF($A4<VARIABLES!$B$45,0,IF($A4=VARIABLES!$B$45,VARIABLES!$B$46+VARIABLES!$B$47,VARIABLES!$B$47)) -> 0 | M4: =L4*VARIABLES!$B$48 -> 0 | N4: =IF($A4<VARIABLES!$B$45,0,(IF($A4=VARIABLES!$B$45,0,O3)+L4)*C4*VARIABLES!$B$49) -> 0 | O4: =IF($A4<VARIABLES!$B$45,0,(IF($A4=VARIABLES!$B$45,0,O3)+L4)*(1+C4)-N4) -> 0 | P4: =IF($A4<VARIABLES!$B$52,0,IF($A4=VARIABLES!$B$52,VARIABLES!$B$53+VARIABLES!$B$54,VARIABLES!$B$54)) -> 0 | Q4: =P4*VARIABLES!$B$55 -> 0 | R4: =IF($A4<VARIABLES!$B$52,0,(IF($A4=VARIABLES!$B$52,0,S3)+P4)*C4*VARIABLES!$B$56) -> 0 | S4: =IF($A4<VARIABLES!$B$52,0,(IF($A4=VARIABLES!$B$52,0,S3)+P4)*(1+C4)-R4) -> 0 | T4: =IF($A4<VARIABLES!$B$60,0,MIN(VARIABLES!$B$59,INT(($A4-VARIABLES!$B$60)/VARIABLES!$B$61)+1)*VARIABLES!$B$62) -> 0 | U4: =T4*VARIABLES!$B$64+IF(AND($A4>=VARIABLES!$B$60,MOD($A4-VARIABLES!$B$60,VARIABLES!$B$61)=0,INT(($A4-VARIABLES!$B$60)/VARIABLES!$B$61)<VARIABLES!$B$59),VARIABLES!$B$62*VARIABLES!$B$63,0) -> 0 | V4: =U4*VARIABLES!$B$65 -> 0 | W4: =IF($A4<VARIABLES!$B$60,0,(IF($A4<VARIABLES!$B$60+1,0,X3)+U4)*C4*VARIABLES!$B$66) -> 0 | X4: =IF($A4<VARIABLES!$B$60,0,(IF($A4<VARIABLES!$B$60+1,0,X3)+U4)*(1+C4)-W4) -> 0 | Y4: =D4+H4+L4+P4+U4 -> 500000 | Z4: =E4+I4+M4+Q4+V4 -> 3750 | AA4: =F4+J4+N4+R4+W4 -> 625 | AB4: =(IF($A4=1,0,AD3)*VARIABLES!$B$18*VARIABLES!$B$16*VARIABLES!$B$17)+(Y4*VARIABLES!$B$16*VARIABLES!$B$17) -> 250 | AC4: =Z4+AA4+AB4 -> 4625 | AD4: =G4+K4+O4+S4+X4 -> 524375 | AE4: =IF($A4=1,VARIABLES!$B$21,0) -> 57500 | AF4: =IF($A4<=3,VARIABLES!$B$22,IF($A4<=6,VARIABLES!$B$23,VARIABLES!$B$24))*(1+VARIABLES!$B$25)^INT(($A4-1)/12) -> 23000 | AG4: =IF(MOD($A4,12)=0,AD4*VARIABLES!$B$26,0) -> 0 | AH4: =VARIABLES!$B$27 -> 5000 | AI4: =IF(MOD($A4,12)=0,VARIABLES!$B$28,0) -> 0 | AJ4: =AE4+AF4+AG4+AH4+AI4 -> 85500 | AK4: =IF(OR($A4<VARIABLES!$B$7,AND($A4>=VARIABLES!$B$8,$A4<VARIABLES!$B$10)),VARIABLES!$B$13,0) -> 0 | AL4: =AC4-AJ4-AK4 -> -80875 | AM4: =AL4 -> -80875 | AN4: =AK4 -> 0
A5: 2 | B5: =TEXT(DATE(VARIABLES!$B$70+INT((VARIABLES!$B$71+$A5-2)/12),MOD(VARIABLES!$B$71+$A5-2,12)+1,1),"mmm-yy") -> Jul-26 | C5: =IF($A5<VARIABLES!$B$7,VARIABLES!$B$5/12,IF($A5<VARIABLES!$B$8,VARIABLES!$B$6/12,IF($A5<VARIABLES!$B$10,VARIABLES!$B$9/12,VARIABLES!$B$11/12))) -> 0.05 | D5: =IF($A5<VARIABLES!$B$31,0,IF($A5=VARIABLES!$B$31,VARIABLES!$B$32+VARIABLES!$B$33,VARIABLES!$B$33)) -> 200000 | E5: =D5*VARIABLES!$B$34 -> 1500 | F5: =IF($A5<VARIABLES!$B$31,0,(IF($A5=VARIABLES!$B$31,0,G4)+D5)*C5*VARIABLES!$B$35) -> 905.46875 | G5: =IF($A5<VARIABLES!$B$31,0,(IF($A5=VARIABLES!$B$31,0,G4)+D5)*(1+C5)-F5) -> 759688.28 | H5: =IF($A5<VARIABLES!$B$38,0,IF($A5=VARIABLES!$B$38,VARIABLES!$B$39+VARIABLES!$B$40,VARIABLES!$B$40)) -> 40000 | I5: =H5*VARIABLES!$B$41 -> 300 | J5: =IF($A5<VARIABLES!$B$38,0,(IF($A5=VARIABLES!$B$38,0,K4)+H5)*C5*VARIABLES!$B$42) -> 200 | K5: =IF($A5<VARIABLES!$B$38,0,(IF($A5=VARIABLES!$B$38,0,K4)+H5)*(1+C5)-J5) -> 41800 | L5: =IF($A5<VARIABLES!$B$45,0,IF($A5=VARIABLES!$B$45,VARIABLES!$B$46+VARIABLES!$B$47,VARIABLES!$B$47)) -> 5000000 | M5: =L5*VARIABLES!$B$48 -> 37500 | N5: =IF($A5<VARIABLES!$B$45,0,(IF($A5=VARIABLES!$B$45,0,O4)+L5)*C5*VARIABLES!$B$49) -> 25000 | O5: =IF($A5<VARIABLES!$B$45,0,(IF($A5=VARIABLES!$B$45,0,O4)+L5)*(1+C5)-N5) -> 5225000 | P5: =IF($A5<VARIABLES!$B$52,0,IF($A5=VARIABLES!$B$52,VARIABLES!$B$53+VARIABLES!$B$54,VARIABLES!$B$54)) -> 20000 | Q5: =P5*VARIABLES!$B$55 -> 150 | R5: =IF($A5<VARIABLES!$B$52,0,(IF($A5=VARIABLES!$B$52,0,S4)+P5)*C5*VARIABLES!$B$56) -> 25 | S5: =IF($A5<VARIABLES!$B$52,0,(IF($A5=VARIABLES!$B$52,0,S4)+P5)*(1+C5)-R5) -> 20975 | T5: =IF($A5<VARIABLES!$B$60,0,MIN(VARIABLES!$B$59,INT(($A5-VARIABLES!$B$60)/VARIABLES!$B$61)+1)*VARIABLES!$B$62) -> 0 | U5: =T5*VARIABLES!$B$64+IF(AND($A5>=VARIABLES!$B$60,MOD($A5-VARIABLES!$B$60,VARIABLES!$B$61)=0,INT(($A5-VARIABLES!$B$60)/VARIABLES!$B$61)<VARIABLES!$B$59),VARIABLES!$B$62*VARIABLES!$B$63,0) -> 0 | V5: =U5*VARIABLES!$B$65 -> 0 | W5: =IF($A5<VARIABLES!$B$60,0,(IF($A5<VARIABLES!$B$60+1,0,X4)+U5)*C5*VARIABLES!$B$66) -> 0 | X5: =IF($A5<VARIABLES!$B$60,0,(IF($A5<VARIABLES!$B$60+1,0,X4)+U5)*(1+C5)-W5) -> 0 | Y5: =D5+H5+L5+P5+U5 -> 5260000 | Z5: =E5+I5+M5+Q5+V5 -> 39450 | AA5: =F5+J5+N5+R5+W5 -> 26130.469 | AB5: =(IF($A5=1,0,AD4)*VARIABLES!$B$18*VARIABLES!$B$16*VARIABLES!$B$17)+(Y5*VARIABLES!$B$16*VARIABLES!$B$17) -> 2695.5469 | AC5: =Z5+AA5+AB5 -> 68276.016 | AD5: =G5+K5+O5+S5+X5 -> 6047463.3 | AE5: =IF($A5=1,VARIABLES!$B$21,0) -> 0 | AF5: =IF($A5<=3,VARIABLES!$B$22,IF($A5<=6,VARIABLES!$B$23,VARIABLES!$B$24))*(1+VARIABLES!$B$25)^INT(($A5-1)/12) -> 23000 | AG5: =IF(MOD($A5,12)=0,AD5*VARIABLES!$B$26,0) -> 0 | AH5: =VARIABLES!$B$27 -> 5000 | AI5: =IF(MOD($A5,12)=0,VARIABLES!$B$28,0) -> 0 | AJ5: =AE5+AF5+AG5+AH5+AI5 -> 28000 | AK5: =IF(OR($A5<VARIABLES!$B$7,AND($A5>=VARIABLES!$B$8,$A5<VARIABLES!$B$10)),VARIABLES!$B$13,0) -> 0 | AL5: =AC5-AJ5-AK5 -> 40276.016 | AM5: =AM4+AL5 -> -40598.984 | AN5: =AN4+AK5 -> 0
A6: 3 | B6: =TEXT(DATE(VARIABLES!$B$70+INT((VARIABLES!$B$71+$A6-2)/12),MOD(VARIABLES!$B$71+$A6-2,12)+1,1),"mmm-yy") -> Aug-26 | C6: =IF($A6<VARIABLES!$B$7,VARIABLES!$B$5/12,IF($A6<VARIABLES!$B$8,VARIABLES!$B$6/12,IF($A6<VARIABLES!$B$10,VARIABLES!$B$9/12,VARIABLES!$B$11/12))) -> 0.05 | D6: =IF($A6<VARIABLES!$B$31,0,IF($A6=VARIABLES!$B$31,VARIABLES!$B$32+VARIABLES!$B$33,VARIABLES!$B$33)) -> 200000 | E6: =D6*VARIABLES!$B$34 -> 1500 | F6: =IF($A6<VARIABLES!$B$31,0,(IF($A6=VARIABLES!$B$31,0,G5)+D6)*C6*VARIABLES!$B$35) -> 1199.6104 | G6: =IF($A6<VARIABLES!$B$31,0,(IF($A6=VARIABLES!$B$31,0,G5)+D6)*(1+C6)-F6) -> 1006473.1 | H6: =IF($A6<VARIABLES!$B$38,0,IF($A6=VARIABLES!$B$38,VARIABLES!$B$39+VARIABLES!$B$40,VARIABLES!$B$40)) -> 40000 | I6: =H6*VARIABLES!$B$41 -> 300 | J6: =IF($A6<VARIABLES!$B$38,0,(IF($A6=VARIABLES!$B$38,0,K5)+H6)*C6*VARIABLES!$B$42) -> 409 | K6: =IF($A6<VARIABLES!$B$38,0,(IF($A6=VARIABLES!$B$38,0,K5)+H6)*(1+C6)-J6) -> 85481 | L6: =IF($A6<VARIABLES!$B$45,0,IF($A6=VARIABLES!$B$45,VARIABLES!$B$46+VARIABLES!$B$47,VARIABLES!$B$47)) -> 0 | M6: =L6*VARIABLES!$B$48 -> 0 | N6: =IF($A6<VARIABLES!$B$45,0,(IF($A6=VARIABLES!$B$45,0,O5)+L6)*C6*VARIABLES!$B$49) -> 26125 | O6: =IF($A6<VARIABLES!$B$45,0,(IF($A6=VARIABLES!$B$45,0,O5)+L6)*(1+C6)-N6) -> 5460125 | P6: =IF($A6<VARIABLES!$B$52,0,IF($A6=VARIABLES!$B$52,VARIABLES!$B$53+VARIABLES!$B$54,VARIABLES!$B$54)) -> 20000 | Q6: =P6*VARIABLES!$B$55 -> 150 | R6: =IF($A6<VARIABLES!$B$52,0,(IF($A6=VARIABLES!$B$52,0,S5)+P6)*C6*VARIABLES!$B$56) -> 51.21875 | S6: =IF($A6<VARIABLES!$B$52,0,(IF($A6=VARIABLES!$B$52,0,S5)+P6)*(1+C6)-R6) -> 42972.531 | T6: =IF($A6<VARIABLES!$B$60,0,MIN(VARIABLES!$B$59,INT(($A6-VARIABLES!$B$60)/VARIABLES!$B$61)+1)*VARIABLES!$B$62) -> 1 | U6: =T6*VARIABLES!$B$64+IF(AND($A6>=VARIABLES!$B$60,MOD($A6-VARIABLES!$B$60,VARIABLES!$B$61)=0,INT(($A6-VARIABLES!$B$60)/VARIABLES!$B$61)<VARIABLES!$B$59),VARIABLES!$B$62*VARIABLES!$B$63,0) -> 55000 | V6: =U6*VARIABLES!$B$65 -> 412.5 | W6: =IF($A6<VARIABLES!$B$60,0,(IF($A6<VARIABLES!$B$60+1,0,X5)+U6)*C6*VARIABLES!$B$66) -> 275 | X6: =IF($A6<VARIABLES!$B$60,0,(IF($A6<VARIABLES!$B$60+1,0,X5)+U6)*(1+C6)-W6) -> 57475 | Y6: =D6+H6+L6+P6+U6 -> 315000 | Z6: =E6+I6+M6+Q6+V6 -> 2362.5 | AA6: =F6+J6+N6+R6+W6 -> 28059.829 | AB6: =(IF($A6=1,0,AD5)*VARIABLES!$B$18*VARIABLES!$B$16*VARIABLES!$B$17)+(Y6*VARIABLES!$B$16*VARIABLES!$B$17) -> 913.43291 | AC6: =Z6+AA6+AB6 -> 31335.762 | AD6: =G6+K6+O6+S6+X6 -> 6652526.6 | AE6: =IF($A6=1,VARIABLES!$B$21,0) -> 0 | AF6: =IF($A6<=3,VARIABLES!$B$22,IF($A6<=6,VARIABLES!$B$23,VARIABLES!$B$24))*(1+VARIABLES!$B$25)^INT(($A6-1)/12) -> 23000 | AG6: =IF(MOD($A6,12)=0,AD6*VARIABLES!$B$26,0) -> 0 | AH6: =VARIABLES!$B$27 -> 5000 | AI6: =IF(MOD($A6,12)=0,VARIABLES!$B$28,0) -> 0 | AJ6: =AE6+AF6+AG6+AH6+AI6 -> 28000 | AK6: =IF(OR($A6<VARIABLES!$B$7,AND($A6>=VARIABLES!$B$8,$A6<VARIABLES!$B$10)),VARIABLES!$B$13,0) -> 0 | AL6: =AC6-AJ6-AK6 -> 3335.762 | AM6: =AM5+AL6 -> -37263.222 | AN6: =AN5+AK6 -> 0
A7: 4 | B7: =TEXT(DATE(VARIABLES!$B$70+INT((VARIABLES!$B$71+$A7-2)/12),MOD(VARIABLES!$B$71+$A7-2,12)+1,1),"mmm-yy") -> Sept-26 | C7: =IF($A7<VARIABLES!$B$7,VARIABLES!$B$5/12,IF($A7<VARIABLES!$B$8,VARIABLES!$B$6/12,IF($A7<VARIABLES!$B$10,VARIABLES!$B$9/12,VARIABLES!$B$11/12))) -> 0.05 | D7: =IF($A7<VARIABLES!$B$31,0,IF($A7=VARIABLES!$B$31,VARIABLES!$B$32+VARIABLES!$B$33,VARIABLES!$B$33)) -> 200000 | E7: =D7*VARIABLES!$B$34 -> 1500 | F7: =IF($A7<VARIABLES!$B$31,0,(IF($A7=VARIABLES!$B$31,0,G6)+D7)*C7*VARIABLES!$B$35) -> 1508.0914 | G7: =IF($A7<VARIABLES!$B$31,0,(IF($A7=VARIABLES!$B$31,0,G6)+D7)*(1+C7)-F7) -> 1265288.6 | H7: =IF($A7<VARIABLES!$B$38,0,IF($A7=VARIABLES!$B$38,VARIABLES!$B$39+VARIABLES!$B$40,VARIABLES!$B$40)) -> 40000 | I7: =H7*VARIABLES!$B$41 -> 300 | J7: =IF($A7<VARIABLES!$B$38,0,(IF($A7=VARIABLES!$B$38,0,K6)+H7)*C7*VARIABLES!$B$42) -> 627.405 | K7: =IF($A7<VARIABLES!$B$38,0,(IF($A7=VARIABLES!$B$38,0,K6)+H7)*(1+C7)-J7) -> 131127.65 | L7: =IF($A7<VARIABLES!$B$45,0,IF($A7=VARIABLES!$B$45,VARIABLES!$B$46+VARIABLES!$B$47,VARIABLES!$B$47)) -> 0 | M7: =L7*VARIABLES!$B$48 -> 0 | N7: =IF($A7<VARIABLES!$B$45,0,(IF($A7=VARIABLES!$B$45,0,O6)+L7)*C7*VARIABLES!$B$49) -> 27300.625 | O7: =IF($A7<VARIABLES!$B$45,0,(IF($A7=VARIABLES!$B$45,0,O6)+L7)*(1+C7)-N7) -> 5705830.6 | P7: =IF($A7<VARIABLES!$B$52,0,IF($A7=VARIABLES!$B$52,VARIABLES!$B$53+VARIABLES!$B$54,VARIABLES!$B$54)) -> 20000 | Q7: =P7*VARIABLES!$B$55 -> 150 | R7: =IF($A7<VARIABLES!$B$52,0,(IF($A7=VARIABLES!$B$52,0,S6)+P7)*C7*VARIABLES!$B$56) -> 78.715664 | S7: =IF($A7<VARIABLES!$B$52,0,(IF($A7=VARIABLES!$B$52,0,S6)+P7)*(1+C7)-R7) -> 66042.442 | T7: =IF($A7<VARIABLES!$B$60,0,MIN(VARIABLES!$B$59,INT(($A7-VARIABLES!$B$60)/VARIABLES!$B$61)+1)*VARIABLES!$B$62) -> 2 | U7: =T7*VARIABLES!$B$64+IF(AND($A7>=VARIABLES!$B$60,MOD($A7-VARIABLES!$B$60,VARIABLES!$B$61)=0,INT(($A7-VARIABLES!$B$60)/VARIABLES!$B$61)<VARIABLES!$B$59),VARIABLES!$B$62*VARIABLES!$B$63,0) -> 60000 | V7: =U7*VARIABLES!$B$65 -> 450 | W7: =IF($A7<VARIABLES!$B$60,0,(IF($A7<VARIABLES!$B$60+1,0,X6)+U7)*C7*VARIABLES!$B$66) -> 587.375 | X7: =IF($A7<VARIABLES!$B$60,0,(IF($A7<VARIABLES!$B$60+1,0,X6)+U7)*(1+C7)-W7) -> 122761.38 | Y7: =D7+H7+L7+P7+U7 -> 320000 | Z7: =E7+I7+M7+Q7+V7 -> 2400 | AA7: =F7+J7+N7+R7+W7 -> 30102.212 | AB7: =(IF($A7=1,0,AD6)*VARIABLES!$B$18*VARIABLES!$B$16*VARIABLES!$B$17)+(Y7*VARIABLES!$B$16*VARIABLES!$B$17) -> 991.56583 | AC7: =Z7+AA7+AB7 -> 33493.778 | AD7: =G7+K7+O7+S7+X7 -> 7291050.7 | AE7: =IF($A7=1,VARIABLES!$B$21,0) -> 0 | AF7: =IF($A7<=3,VARIABLES!$B$22,IF($A7<=6,VARIABLES!$B$23,VARIABLES!$B$24))*(1+VARIABLES!$B$25)^INT(($A7-1)/12) -> 34500 | AG7: =IF(MOD($A7,12)=0,AD7*VARIABLES!$B$26,0) -> 0 | AH7: =VARIABLES!$B$27 -> 5000 | AI7: =IF(MOD($A7,12)=0,VARIABLES!$B$28,0) -> 0 | AJ7: =AE7+AF7+AG7+AH7+AI7 -> 39500 | AK7: =IF(OR($A7<VARIABLES!$B$7,AND($A7>=VARIABLES!$B$8,$A7<VARIABLES!$B$10)),VARIABLES!$B$13,0) -> 0 | AL7: =AC7-AJ7-AK7 -> -6006.2222 | AM7: =AM6+AL7 -> -43269.445 | AN7: =AN6+AK7 -> 0
A8: 5 | B8: =TEXT(DATE(VARIABLES!$B$70+INT((VARIABLES!$B$71+$A8-2)/12),MOD(VARIABLES!$B$71+$A8-2,12)+1,1),"mmm-yy") -> Oct-26 | C8: =IF($A8<VARIABLES!$B$7,VARIABLES!$B$5/12,IF($A8<VARIABLES!$B$8,VARIABLES!$B$6/12,IF($A8<VARIABLES!$B$10,VARIABLES!$B$9/12,VARIABLES!$B$11/12))) -> 0.05 | D8: =IF($A8<VARIABLES!$B$31,0,IF($A8=VARIABLES!$B$31,VARIABLES!$B$32+VARIABLES!$B$33,VARIABLES!$B$33)) -> 200000 | E8: =D8*VARIABLES!$B$34 -> 1500 | F8: =IF($A8<VARIABLES!$B$31,0,(IF($A8=VARIABLES!$B$31,0,G7)+D8)*C8*VARIABLES!$B$35) -> 1831.6108 | G8: =IF($A8<VARIABLES!$B$31,0,(IF($A8=VARIABLES!$B$31,0,G7)+D8)*(1+C8)-F8) -> 1536721.5 | H8: =IF($A8<VARIABLES!$B$38,0,IF($A8=VARIABLES!$B$38,VARIABLES!$B$39+VARIABLES!$B$40,VARIABLES!$B$40)) -> 40000 | I8: =H8*VARIABLES!$B$41 -> 300 | J8: =IF($A8<VARIABLES!$B$38,0,(IF($A8=VARIABLES!$B$38,0,K7)+H8)*C8*VARIABLES!$B$42) -> 855.63823 | K8: =IF($A8<VARIABLES!$B$38,0,(IF($A8=VARIABLES!$B$38,0,K7)+H8)*(1+C8)-J8) -> 178828.39 | L8: =IF($A8<VARIABLES!$B$45,0,IF($A8=VARIABLES!$B$45,VARIABLES!$B$46+VARIABLES!$B$47,VARIABLES!$B$47)) -> 0 | M8: =L8*VARIABLES!$B$48 -> 0 | N8: =IF($A8<VARIABLES!$B$45,0,(IF($A8=VARIABLES!$B$45,0,O7)+L8)*C8*VARIABLES!$B$49) -> 28529.153 | O8: =IF($A8<VARIABLES!$B$45,0,(IF($A8=VARIABLES!$B$45,0,O7)+L8)*(1+C8)-N8) -> 5962593 | P8: =IF($A8<VARIABLES!$B$52,0,IF($A8=VARIABLES!$B$52,VARIABLES!$B$53+VARIABLES!$B$54,VARIABLES!$B$54)) -> 20000 | Q8: =P8*VARIABLES!$B$55 -> 150 | R8: =IF($A8<VARIABLES!$B$52,0,(IF($A8=VARIABLES!$B$52,0,S7)+P8)*C8*VARIABLES!$B$56) -> 107.55305 | S8: =IF($A8<VARIABLES!$B$52,0,(IF($A8=VARIABLES!$B$52,0,S7)+P8)*(1+C8)-R8) -> 90237.011 | T8: =IF($A8<VARIABLES!$B$60,0,MIN(VARIABLES!$B$59,INT(($A8-VARIABLES!$B$60)/VARIABLES!$B$61)+1)*VARIABLES!$B$62) -> 3 | U8: =T8*VARIABLES!$B$64+IF(AND($A8>=VARIABLES!$B$60,MOD($A8-VARIABLES!$B$60,VARIABLES!$B$61)=0,INT(($A8-VARIABLES!$B$60)/VARIABLES!$B$61)<VARIABLES!$B$59),VARIABLES!$B$62*VARIABLES!$B$63,0) -> 65000 | V8: =U8*VARIABLES!$B$65 -> 487.5 | W8: =IF($A8<VARIABLES!$B$60,0,(IF($A8<VARIABLES!$B$60+1,0,X7)+U8)*C8*VARIABLES!$B$66) -> 938.80687 | X8: =IF($A8<VARIABLES!$B$60,0,(IF($A8<VARIABLES!$B$60+1,0,X7)+U8)*(1+C8)-W8) -> 196210.64 | Y8: =D8+H8+L8+P8+U8 -> 325000 | Z8: =E8+I8+M8+Q8+V8 -> 2437.5 | AA8: =F8+J8+N8+R8+W8 -> 32262.762 | AB8: =(IF($A8=1,0,AD7)*VARIABLES!$B$18*VARIABLES!$B$16*VARIABLES!$B$17)+(Y8*VARIABLES!$B$16*VARIABLES!$B$17) -> 1073.8813 | AC8: =Z8+AA8+AB8 -> 35774.143 | AD8: =G8+K8+O8+S8+X8 -> 7964590.5 | AE8: =IF($A8=1,VARIABLES!$B$21,0) -> 0 | AF8: =IF($A8<=3,VARIABLES!$B$22,IF($A8<=6,VARIABLES!$B$23,VARIABLES!$B$24))*(1+VARIABLES!$B$25)^INT(($A8-1)/12) -> 34500 | AG8: =IF(MOD($A8,12)=0,AD8*VARIABLES!$B$26,0) -> 0 | AH8: =VARIABLES!$B$27 -> 5000 | AI8: =IF(MOD($A8,12)=0,VARIABLES!$B$28,0) -> 0 | AJ8: =AE8+AF8+AG8+AH8+AI8 -> 39500 | AK8: =IF(OR($A8<VARIABLES!$B$7,AND($A8>=VARIABLES!$B$8,$A8<VARIABLES!$B$10)),VARIABLES!$B$13,0) -> 0 | AL8: =AC8-AJ8-AK8 -> -3725.8566 | AM8: =AM7+AL8 -> -46995.301 | AN8: =AN7+AK8 -> 0
A9: 6 | B9: =TEXT(DATE(VARIABLES!$B$70+INT((VARIABLES!$B$71+$A9-2)/12),MOD(VARIABLES!$B$71+$A9-2,12)+1,1),"mmm-yy") -> Nov-26 | C9: =IF($A9<VARIABLES!$B$7,VARIABLES!$B$5/12,IF($A9<VARIABLES!$B$8,VARIABLES!$B$6/12,IF($A9<VARIABLES!$B$10,VARIABLES!$B$9/12,VARIABLES!$B$11/12))) -> 0.05 | D9: =IF($A9<VARIABLES!$B$31,0,IF($A9=VARIABLES!$B$31,VARIABLES!$B$32+VARIABLES!$B$33,VARIABLES!$B$33)) -> 200000 | E9: =D9*VARIABLES!$B$34 -> 1500 | F9: =IF($A9<VARIABLES!$B$31,0,(IF($A9=VARIABLES!$B$31,0,G8)+D9)*C9*VARIABLES!$B$35) -> 2170.9018 | G9: =IF($A9<VARIABLES!$B$31,0,(IF($A9=VARIABLES!$B$31,0,G8)+D9)*(1+C9)-F9) -> 1821386.6 | H9: =IF($A9<VARIABLES!$B$38,0,IF($A9=VARIABLES!$B$38,VARIABLES!$B$39+VARIABLES!$B$40,VARIABLES!$B$40)) -> 40000 | I9: =H9*VARIABLES!$B$41 -> 300 | J9: =IF($A9<VARIABLES!$B$38,0,(IF($A9=VARIABLES!$B$38,0,K8)+H9)*C9*VARIABLES!$B$42) -> 1094.1419 | K9: =IF($A9<VARIABLES!$B$38,0,(IF($A9=VARIABLES!$B$38,0,K8)+H9)*(1+C9)-J9) -> 228675.67 | L9: =IF($A9<VARIABLES!$B$45,0,IF($A9=VARIABLES!$B$45,VARIABLES!$B$46+VARIABLES!$B$47,VARIABLES!$B$47)) -> 0 | M9: =L9*VARIABLES!$B$48 -> 0 | N9: =IF($A9<VARIABLES!$B$45,0,(IF($A9=VARIABLES!$B$45,0,O8)+L9)*C9*VARIABLES!$B$49) -> 29812.965 | O9: =IF($A9<VARIABLES!$B$45,0,(IF($A9=VARIABLES!$B$45,0,O8)+L9)*(1+C9)-N9) -> 6230909.7 | P9: =IF($A9<VARIABLES!$B$52,0,IF($A9=VARIABLES!$B$52,VARIABLES!$B$53+VARIABLES!$B$54,VARIABLES!$B$54)) -> 20000 | Q9: =P9*VARIABLES!$B$55 -> 150 | R9: =IF($A9<VARIABLES!$B$52,0,(IF($A9=VARIABLES!$B$52,0,S8)+P9)*C9*VARIABLES!$B$56) -> 137.79626 | S9: =IF($A9<VARIABLES!$B$52,0,(IF($A9=VARIABLES!$B$52,0,S8)+P9)*(1+C9)-R9) -> 115611.07 | T9: =IF($A9<VARIABLES!$B$60,0,MIN(VARIABLES!$B$59,INT(($A9-VARIABLES!$B$60)/VARIABLES!$B$61)+1)*VARIABLES!$B$62) -> 4 | U9: =T9*VARIABLES!$B$64+IF(AND($A9>=VARIABLES!$B$60,MOD($A9-VARIABLES!$B$60,VARIABLES!$B$61)=0,INT(($A9-VARIABLES!$B$60)/VARIABLES!$B$61)<VARIABLES!$B$59),VARIABLES!$B$62*VARIABLES!$B$63,0) -> 70000 | V9: =U9*VARIABLES!$B$65 -> 525 | W9: =IF($A9<VARIABLES!$B$60,0,(IF($A9<VARIABLES!$B$60+1,0,X8)+U9)*C9*VARIABLES!$B$66) -> 1331.0532 | X9: =IF($A9<VARIABLES!$B$60,0,(IF($A9<VARIABLES!$B$60+1,0,X8)+U9)*(1+C9)-W9) -> 278190.12 | Y9: =D9+H9+L9+P9+U9 -> 330000 | Z9: =E9+I9+M9+Q9+V9 -> 2475 | AA9: =F9+J9+N9+R9+W9 -> 34546.858 | AB9: =(IF($A9=1,0,AD8)*VARIABLES!$B$18*VARIABLES!$B$16*VARIABLES!$B$17)+(Y9*VARIABLES!$B$16*VARIABLES!$B$17) -> 1160.5738 | AC9: =Z9+AA9+AB9 -> 38182.432 | AD9: =G9+K9+O9+S9+X9 -> 8674773.2 | AE9: =IF($A9=1,VARIABLES!$B$21,0) -> 0 | AF9: =IF($A9<=3,VARIABLES!$B$22,IF($A9<=6,VARIABLES!$B$23,VARIABLES!$B$24))*(1+VARIABLES!$B$25)^INT(($A9-1)/12) -> 34500 | AG9: =IF(MOD($A9,12)=0,AD9*VARIABLES!$B$26,0) -> 0 | AH9: =VARIABLES!$B$27 -> 5000 | AI9: =IF(MOD($A9,12)=0,VARIABLES!$B$28,0) -> 0 | AJ9: =AE9+AF9+AG9+AH9+AI9 -> 39500 | AK9: =IF(OR($A9<VARIABLES!$B$7,AND($A9>=VARIABLES!$B$8,$A9<VARIABLES!$B$10)),VARIABLES!$B$13,0) -> 0 | AL9: =AC9-AJ9-AK9 -> -1317.5679 | AM9: =AM8+AL9 -> -48312.869 | AN9: =AN8+AK9 -> 0
A10: 7 | B10: =TEXT(DATE(VARIABLES!$B$70+INT((VARIABLES!$B$71+$A10-2)/12),MOD(VARIABLES!$B$71+$A10-2,12)+1,1),"mmm-yy") -> Dec-26 | C10: =IF($A10<VARIABLES!$B$7,VARIABLES!$B$5/12,IF($A10<VARIABLES!$B$8,VARIABLES!$B$6/12,IF($A10<VARIABLES!$B$10,VARIABLES!$B$9/12,VARIABLES!$B$11/12))) -> 0.05 | D10: =IF($A10<VARIABLES!$B$31,0,IF($A10=VARIABLES!$B$31,VARIABLES!$B$32+VARIABLES!$B$33,VARIABLES!$B$33)) -> 200000 | E10: =D10*VARIABLES!$B$34 -> 1500 | F10: =IF($A10<VARIABLES!$B$31,0,(IF($A10=VARIABLES!$B$31,0,G9)+D10)*C10*VARIABLES!$B$35) -> 2526.7333 | G10: =IF($A10<VARIABLES!$B$31,0,(IF($A10=VARIABLES!$B$31,0,G9)+D10)*(1+C10)-F10) -> 2119929.2 | H10: =IF($A10<VARIABLES!$B$38,0,IF($A10=VARIABLES!$B$38,VARIABLES!$B$39+VARIABLES!$B$40,VARIABLES!$B$40)) -> 40000 | I10: =H10*VARIABLES!$B$41 -> 300 | J10: =IF($A10<VARIABLES!$B$38,0,(IF($A10=VARIABLES!$B$38,0,K9)+H10)*C10*VARIABLES!$B$42) -> 1343.3783 | K10: =IF($A10<VARIABLES!$B$38,0,(IF($A10=VARIABLES!$B$38,0,K9)+H10)*(1+C10)-J10) -> 280766.07 | L10: =IF($A10<VARIABLES!$B$45,0,IF($A10=VARIABLES!$B$45,VARIABLES!$B$46+VARIABLES!$B$47,VARIABLES!$B$47)) -> 0 | M10: =L10*VARIABLES!$B$48 -> 0 | N10: =IF($A10<VARIABLES!$B$45,0,(IF($A10=VARIABLES!$B$45,0,O9)+L10)*C10*VARIABLES!$B$49) -> 31154.548 | O10: =IF($A10<VARIABLES!$B$45,0,(IF($A10=VARIABLES!$B$45,0,O9)+L10)*(1+C10)-N10) -> 6511300.6 | P10: =IF($A10<VARIABLES!$B$52,0,IF($A10=VARIABLES!$B$52,VARIABLES!$B$53+VARIABLES!$B$54,VARIABLES!$B$54)) -> 20000 | Q10: =P10*VARIABLES!$B$55 -> 150 | R10: =IF($A10<VARIABLES!$B$52,0,(IF($A10=VARIABLES!$B$52,0,S9)+P10)*C10*VARIABLES!$B$56) -> 169.51383 | S10: =IF($A10<VARIABLES!$B$52,0,(IF($A10=VARIABLES!$B$52,0,S9)+P10)*(1+C10)-R10) -> 142222.1 | T10: =IF($A10<VARIABLES!$B$60,0,MIN(VARIABLES!$B$59,INT(($A10-VARIABLES!$B$60)/VARIABLES!$B$61)+1)*VARIABLES!$B$62) -> 5 | U10: =T10*VARIABLES!$B$64+IF(AND($A10>=VARIABLES!$B$60,MOD($A10-VARIABLES!$B$60,VARIABLES!$B$61)=0,INT(($A10-VARIABLES!$B$60)/VARIABLES!$B$61)<VARIABLES!$B$59),VARIABLES!$B$62*VARIABLES!$B$63,0) -> 75000 | V10: =U10*VARIABLES!$B$65 -> 562.5 | W10: =IF($A10<VARIABLES!$B$60,0,(IF($A10<VARIABLES!$B$60+1,0,X9)+U10)*C10*VARIABLES!$B$66) -> 1765.9506 | X10: =IF($A10<VARIABLES!$B$60,0,(IF($A10<VARIABLES!$B$60+1,0,X9)+U10)*(1+C10)-W10) -> 369083.67 | Y10: =D10+H10+L10+P10+U10 -> 335000 | Z10: =E10+I10+M10+Q10+V10 -> 2512.5 | AA10: =F10+J10+N10+R10+W10 -> 36960.124 | AB10: =(IF($A10=1,0,AD9)*VARIABLES!$B$18*VARIABLES!$B$16*VARIABLES!$B$17)+(Y10*VARIABLES!$B$16*VARIABLES!$B$17) -> 1251.8466 | AC10: =Z10+AA10+AB10 -> 40724.471 | AD10: =G10+K10+O10+S10+X10 -> 9423301.7 | AE10: =IF($A10=1,VARIABLES!$B$21,0) -> 0 | AF10: =IF($A10<=3,VARIABLES!$B$22,IF($A10<=6,VARIABLES!$B$23,VARIABLES!$B$24))*(1+VARIABLES!$B$25)^INT(($A10-1)/12) -> 46000 | AG10: =IF(MOD($A10,12)=0,AD10*VARIABLES!$B$26,0) -> 0 | AH10: =VARIABLES!$B$27 -> 5000 | AI10: =IF(MOD($A10,12)=0,VARIABLES!$B$28,0) -> 0 | AJ10: =AE10+AF10+AG10+AH10+AI10 -> 51000 | AK10: =IF(OR($A10<VARIABLES!$B$7,AND($A10>=VARIABLES!$B$8,$A10<VARIABLES!$B$10)),VARIABLES!$B$13,0) -> 0 | AL10: =AC10-AJ10-AK10 -> -10275.529 | AM10: =AM9+AL10 -> -58588.398 | AN10: =AN9+AK10 -> 0
A11: 8 | B11: =TEXT(DATE(VARIABLES!$B$70+INT((VARIABLES!$B$71+$A11-2)/12),MOD(VARIABLES!$B$71+$A11-2,12)+1,1),"mmm-yy") -> Jan-27 | C11: =IF($A11<VARIABLES!$B$7,VARIABLES!$B$5/12,IF($A11<VARIABLES!$B$8,VARIABLES!$B$6/12,IF($A11<VARIABLES!$B$10,VARIABLES!$B$9/12,VARIABLES!$B$11/12))) -> 0.05 | D11: =IF($A11<VARIABLES!$B$31,0,IF($A11=VARIABLES!$B$31,VARIABLES!$B$32+VARIABLES!$B$33,VARIABLES!$B$33)) -> 200000 | E11: =D11*VARIABLES!$B$34 -> 1500 | F11: =IF($A11<VARIABLES!$B$31,0,(IF($A11=VARIABLES!$B$31,0,G10)+D11)*C11*VARIABLES!$B$35) -> 2899.9115 | G11: =IF($A11<VARIABLES!$B$31,0,(IF($A11=VARIABLES!$B$31,0,G10)+D11)*(1+C11)-F11) -> 2433025.8 | H11: =IF($A11<VARIABLES!$B$38,0,IF($A11=VARIABLES!$B$38,VARIABLES!$B$39+VARIABLES!$B$40,VARIABLES!$B$40)) -> 40000 | I11: =H11*VARIABLES!$B$41 -> 300 | J11: =IF($A11<VARIABLES!$B$38,0,(IF($A11=VARIABLES!$B$38,0,K10)+H11)*C11*VARIABLES!$B$42) -> 1603.8304 | K11: =IF($A11<VARIABLES!$B$38,0,(IF($A11=VARIABLES!$B$38,0,K10)+H11)*(1+C11)-J11) -> 335200.54 | L11: =IF($A11<VARIABLES!$B$45,0,IF($A11=VARIABLES!$B$45,VARIABLES!$B$46+VARIABLES!$B$47,VARIABLES!$B$47)) -> 0 | M11: =L11*VARIABLES!$B$48 -> 0 | N11: =IF($A11<VARIABLES!$B$45,0,(IF($A11=VARIABLES!$B$45,0,O10)+L11)*C11*VARIABLES!$B$49) -> 32556.503 | O11: =IF($A11<VARIABLES!$B$45,0,(IF($A11=VARIABLES!$B$45,0,O10)+L11)*(1+C11)-N11) -> 6804309.2 | P11: =IF($A11<VARIABLES!$B$52,0,IF($A11=VARIABLES!$B$52,VARIABLES!$B$53+VARIABLES!$B$54,VARIABLES!$B$54)) -> 20000 | Q11: =P11*VARIABLES!$B$55 -> 150 | R11: =IF($A11<VARIABLES!$B$52,0,(IF($A11=VARIABLES!$B$52,0,S10)+P11)*C11*VARIABLES!$B$56) -> 202.77763 | S11: =IF($A11<VARIABLES!$B$52,0,(IF($A11=VARIABLES!$B$52,0,S10)+P11)*(1+C11)-R11) -> 170130.43 | T11: =IF($A11<VARIABLES!$B$60,0,MIN(VARIABLES!$B$59,INT(($A11-VARIABLES!$B$60)/VARIABLES!$B$61)+1)*VARIABLES!$B$62) -> 6 | U11: =T11*VARIABLES!$B$64+IF(AND($A11>=VARIABLES!$B$60,MOD($A11-VARIABLES!$B$60,VARIABLES!$B$61)=0,INT(($A11-VARIABLES!$B$60)/VARIABLES!$B$61)<VARIABLES!$B$59),VARIABLES!$B$62*VARIABLES!$B$63,0) -> 80000 | V11: =U11*VARIABLES!$B$65 -> 600 | W11: =IF($A11<VARIABLES!$B$60,0,(IF($A11<VARIABLES!$B$60+1,0,X10)+U11)*C11*VARIABLES!$B$66) -> 2245.4184 | X11: =IF($A11<VARIABLES!$B$60,0,(IF($A11<VARIABLES!$B$60+1,0,X10)+U11)*(1+C11)-W11) -> 469292.44 | Y11: =D11+H11+L11+P11+U11 -> 340000 | Z11: =E11+I11+M11+Q11+V11 -> 2550 | AA11: =F11+J11+N11+R11+W11 -> 39508.441 | AB11: =(IF($A11=1,0,AD10)*VARIABLES!$B$18*VARIABLES!$B$16*VARIABLES!$B$17)+(Y11*VARIABLES!$B$16*VARIABLES!$B$17) -> 1347.9127 | AC11: =Z11+AA11+AB11 -> 43406.354 | AD11: =G11+K11+O11+S11+X11 -> 10211958 | AE11: =IF($A11=1,VARIABLES!$B$21,0) -> 0 | AF11: =IF($A11<=3,VARIABLES!$B$22,IF($A11<=6,VARIABLES!$B$23,VARIABLES!$B$24))*(1+VARIABLES!$B$25)^INT(($A11-1)/12) -> 46000 | AG11: =IF(MOD($A11,12)=0,AD11*VARIABLES!$B$26,0) -> 0 | AH11: =VARIABLES!$B$27 -> 5000 | AI11: =IF(MOD($A11,12)=0,VARIABLES!$B$28,0) -> 0 | AJ11: =AE11+AF11+AG11+AH11+AI11 -> 51000 | AK11: =IF(OR($A11<VARIABLES!$B$7,AND($A11>=VARIABLES!$B$8,$A11<VARIABLES!$B$10)),VARIABLES!$B$13,0) -> 0 | AL11: =AC11-AJ11-AK11 -> -7593.6463 | AM11: =AM10+AL11 -> -66182.044 | AN11: =AN10+AK11 -> 0
A12: 9 | B12: =TEXT(DATE(VARIABLES!$B$70+INT((VARIABLES!$B$71+$A12-2)/12),MOD(VARIABLES!$B$71+$A12-2,12)+1,1),"mmm-yy") -> Feb-27 | C12: =IF($A12<VARIABLES!$B$7,VARIABLES!$B$5/12,IF($A12<VARIABLES!$B$8,VARIABLES!$B$6/12,IF($A12<VARIABLES!$B$10,VARIABLES!$B$9/12,VARIABLES!$B$11/12))) -> 0.05 | D12: =IF($A12<VARIABLES!$B$31,0,IF($A12=VARIABLES!$B$31,VARIABLES!$B$32+VARIABLES!$B$33,VARIABLES!$B$33)) -> 200000 | E12: =D12*VARIABLES!$B$34 -> 1500 | F12: =IF($A12<VARIABLES!$B$31,0,(IF($A12=VARIABLES!$B$31,0,G11)+D12)*C12*VARIABLES!$B$35) -> 3291.2822 | G12: =IF($A12<VARIABLES!$B$31,0,(IF($A12=VARIABLES!$B$31,0,G11)+D12)*(1+C12)-F12) -> 2761385.8 | H12: =IF($A12<VARIABLES!$B$38,0,IF($A12=VARIABLES!$B$38,VARIABLES!$B$39+VARIABLES!$B$40,VARIABLES!$B$40)) -> 40000 | I12: =H12*VARIABLES!$B$41 -> 300 | J12: =IF($A12<VARIABLES!$B$38,0,(IF($A12=VARIABLES!$B$38,0,K11)+H12)*C12*VARIABLES!$B$42) -> 1876.0027 | K12: =IF($A12<VARIABLES!$B$38,0,(IF($A12=VARIABLES!$B$38,0,K11)+H12)*(1+C12)-J12) -> 392084.57 | L12: =IF($A12<VARIABLES!$B$45,0,IF($A12=VARIABLES!$B$45,VARIABLES!$B$46+VARIABLES!$B$47,VARIABLES!$B$47)) -> 0 | M12: =L12*VARIABLES!$B$48 -> 0 | N12: =IF($A12<VARIABLES!$B$45,0,(IF($A12=VARIABLES!$B$45,0,O11)+L12)*C12*VARIABLES!$B$49) -> 34021.546 | O12: =IF($A12<VARIABLES!$B$45,0,(IF($A12=VARIABLES!$B$45,0,O11)+L12)*(1+C12)-N12) -> 7110503.1 | P12: =IF($A12<VARIABLES!$B$52,0,IF($A12=VARIABLES!$B$52,VARIABLES!$B$53+VARIABLES!$B$54,VARIABLES!$B$54)) -> 20000 | Q12: =P12*VARIABLES!$B$55 -> 150 | R12: =IF($A12<VARIABLES!$B$52,0,(IF($A12=VARIABLES!$B$52,0,S11)+P12)*C12*VARIABLES!$B$56) -> 237.66304 | S12: =IF($A12<VARIABLES!$B$52,0,(IF($A12=VARIABLES!$B$52,0,S11)+P12)*(1+C12)-R12) -> 199399.29 | T12: =IF($A12<VARIABLES!$B$60,0,MIN(VARIABLES!$B$59,INT(($A12-VARIABLES!$B$60)/VARIABLES!$B$61)+1)*VARIABLES!$B$62) -> 7 | U12: =T12*VARIABLES!$B$64+IF(AND($A12>=VARIABLES!$B$60,MOD($A12-VARIABLES!$B$60,VARIABLES!$B$61)=0,INT(($A12-VARIABLES!$B$60)/VARIABLES!$B$61)<VARIABLES!$B$59),VARIABLES!$B$62*VARIABLES!$B$63,0) -> 85000 | V12: =U12*VARIABLES!$B$65 -> 637.5 | W12: =IF($A12<VARIABLES!$B$60,0,(IF($A12<VARIABLES!$B$60+1,0,X11)+U12)*C12*VARIABLES!$B$66) -> 2771.4622 | X12: =IF($A12<VARIABLES!$B$60,0,(IF($A12<VARIABLES!$B$60+1,0,X11)+U12)*(1+C12)-W12) -> 579235.6 | Y12: =D12+H12+L12+P12+U12 -> 345000 | Z12: =E12+I12+M12+Q12+V12 -> 2587.5 | AA12: =F12+J12+N12+R12+W12 -> 42197.956 | AB12: =(IF($A12=1,0,AD11)*VARIABLES!$B$18*VARIABLES!$B$16*VARIABLES!$B$17)+(Y12*VARIABLES!$B$16*VARIABLES!$B$17) -> 1448.9948 | AC12: =Z12+AA12+AB12 -> 46234.451 | AD12: =G12+K12+O12+S12+X12 -> 11042608 | AE12: =IF($A12=1,VARIABLES!$B$21,0) -> 0 | AF12: =IF($A12<=3,VARIABLES!$B$22,IF($A12<=6,VARIABLES!$B$23,VARIABLES!$B$24))*(1+VARIABLES!$B$25)^INT(($A12-1)/12) -> 46000 | AG12: =IF(MOD($A12,12)=0,AD12*VARIABLES!$B$26,0) -> 0 | AH12: =VARIABLES!$B$27 -> 5000 | AI12: =IF(MOD($A12,12)=0,VARIABLES!$B$28,0) -> 0 | AJ12: =AE12+AF12+AG12+AH12+AI12 -> 51000 | AK12: =IF(OR($A12<VARIABLES!$B$7,AND($A12>=VARIABLES!$B$8,$A12<VARIABLES!$B$10)),VARIABLES!$B$13,0) -> 0 | AL12: =AC12-AJ12-AK12 -> -4765.5493 | AM12: =AM11+AL12 -> -70947.593 | AN12: =AN11+AK12 -> 0
A13: 10 | B13: =TEXT(DATE(VARIABLES!$B$70+INT((VARIABLES!$B$71+$A13-2)/12),MOD(VARIABLES!$B$71+$A13-2,12)+1,1),"mmm-yy") -> Mar-27 | C13: =IF($A13<VARIABLES!$B$7,VARIABLES!$B$5/12,IF($A13<VARIABLES!$B$8,VARIABLES!$B$6/12,IF($A13<VARIABLES!$B$10,VARIABLES!$B$9/12,VARIABLES!$B$11/12))) -> 0.05 | D13: =IF($A13<VARIABLES!$B$31,0,IF($A13=VARIABLES!$B$31,VARIABLES!$B$32+VARIABLES!$B$33,VARIABLES!$B$33)) -> 200000 | E13: =D13*VARIABLES!$B$34 -> 1500 | F13: =IF($A13<VARIABLES!$B$31,0,(IF($A13=VARIABLES!$B$31,0,G12)+D13)*C13*VARIABLES!$B$35) -> 3701.7322 | G13: =IF($A13<VARIABLES!$B$31,0,(IF($A13=VARIABLES!$B$31,0,G12)+D13)*(1+C13)-F13) -> 3105753.4 | H13: =IF($A13<VARIABLES!$B$38,0,IF($A13=VARIABLES!$B$38,VARIABLES!$B$39+VARIABLES!$B$40,VARIABLES!$B$40)) -> 40000 | I13: =H13*VARIABLES!$B$41 -> 300 | J13: =IF($A13<VARIABLES!$B$38,0,(IF($A13=VARIABLES!$B$38,0,K12)+H13)*C13*VARIABLES!$B$42) -> 2160.4228 | K13: =IF($A13<VARIABLES!$B$38,0,(IF($A13=VARIABLES!$B$38,0,K12)+H13)*(1+C13)-J13) -> 451528.37 | L13: =IF($A13<VARIABLES!$B$45,0,IF($A13=VARIABLES!$B$45,VARIABLES!$B$46+VARIABLES!$B$47,VARIABLES!$B$47)) -> 0 | M13: =L13*VARIABLES!$B$48 -> 0 | N13: =IF($A13<VARIABLES!$B$45,0,(IF($A13=VARIABLES!$B$45,0,O12)+L13)*C13*VARIABLES!$B$49) -> 35552.515 | O13: =IF($A13<VARIABLES!$B$45,0,(IF($A13=VARIABLES!$B$45,0,O12)+L13)*(1+C13)-N13) -> 7430475.7 | P13: =IF($A13<VARIABLES!$B$52,0,IF($A13=VARIABLES!$B$52,VARIABLES!$B$53+VARIABLES!$B$54,VARIABLES!$B$54)) -> 20000 | Q13: =P13*VARIABLES!$B$55 -> 150 | R13: =IF($A13<VARIABLES!$B$52,0,(IF($A13=VARIABLES!$B$52,0,S12)+P13)*C13*VARIABLES!$B$56) -> 274.24911 | S13: =IF($A13<VARIABLES!$B$52,0,(IF($A13=VARIABLES!$B$52,0,S12)+P13)*(1+C13)-R13) -> 230095.01 | T13: =IF($A13<VARIABLES!$B$60,0,MIN(VARIABLES!$B$59,INT(($A13-VARIABLES!$B$60)/VARIABLES!$B$61)+1)*VARIABLES!$B$62) -> 8 | U13: =T13*VARIABLES!$B$64+IF(AND($A13>=VARIABLES!$B$60,MOD($A13-VARIABLES!$B$60,VARIABLES!$B$61)=0,INT(($A13-VARIABLES!$B$60)/VARIABLES!$B$61)<VARIABLES!$B$59),VARIABLES!$B$62*VARIABLES!$B$63,0) -> 90000 | V13: =U13*VARIABLES!$B$65 -> 675 | W13: =IF($A13<VARIABLES!$B$60,0,(IF($A13<VARIABLES!$B$60+1,0,X12)+U13)*C13*VARIABLES!$B$66) -> 3346.178 | X13: =IF($A13<VARIABLES!$B$60,0,(IF($A13<VARIABLES!$B$60+1,0,X12)+U13)*(1+C13)-W13) -> 699351.2 | Y13: =D13+H13+L13+P13+U13 -> 350000 | Z13: =E13+I13+M13+Q13+V13 -> 2625 | AA13: =F13+J13+N13+R13+W13 -> 45035.098 | AB13: =(IF($A13=1,0,AD12)*VARIABLES!$B$18*VARIABLES!$B$16*VARIABLES!$B$17)+(Y13*VARIABLES!$B$16*VARIABLES!$B$17) -> 1555.326 | AC13: =Z13+AA13+AB13 -> 49215.424 | AD13: =G13+K13+O13+S13+X13 -> 11917204 | AE13: =IF($A13=1,VARIABLES!$B$21,0) -> 0 | AF13: =IF($A13<=3,VARIABLES!$B$22,IF($A13<=6,VARIABLES!$B$23,VARIABLES!$B$24))*(1+VARIABLES!$B$25)^INT(($A13-1)/12) -> 46000 | AG13: =IF(MOD($A13,12)=0,AD13*VARIABLES!$B$26,0) -> 0 | AH13: =VARIABLES!$B$27 -> 5000 | AI13: =IF(MOD($A13,12)=0,VARIABLES!$B$28,0) -> 0 | AJ13: =AE13+AF13+AG13+AH13+AI13 -> 51000 | AK13: =IF(OR($A13<VARIABLES!$B$7,AND($A13>=VARIABLES!$B$8,$A13<VARIABLES!$B$10)),VARIABLES!$B$13,0) -> 0 | AL13: =AC13-AJ13-AK13 -> -1784.5765 | AM13: =AM12+AL13 -> -72732.17 | AN13: =AN12+AK13 -> 0
A14: 11 | B14: =TEXT(DATE(VARIABLES!$B$70+INT((VARIABLES!$B$71+$A14-2)/12),MOD(VARIABLES!$B$71+$A14-2,12)+1,1),"mmm-yy") -> Apr-27 | C14: =IF($A14<VARIABLES!$B$7,VARIABLES!$B$5/12,IF($A14<VARIABLES!$B$8,VARIABLES!$B$6/12,IF($A14<VARIABLES!$B$10,VARIABLES!$B$9/12,VARIABLES!$B$11/12))) -> 0.05 | D14: =IF($A14<VARIABLES!$B$31,0,IF($A14=VARIABLES!$B$31,VARIABLES!$B$32+VARIABLES!$B$33,VARIABLES!$B$33)) -> 200000 | E14: =D14*VARIABLES!$B$34 -> 1500 | F14: =IF($A14<VARIABLES!$B$31,0,(IF($A14=VARIABLES!$B$31,0,G13)+D14)*C14*VARIABLES!$B$35) -> 4132.1917 | G14: =IF($A14<VARIABLES!$B$31,0,(IF($A14=VARIABLES!$B$31,0,G13)+D14)*(1+C14)-F14) -> 3466908.8 | H14: =IF($A14<VARIABLES!$B$38,0,IF($A14=VARIABLES!$B$38,VARIABLES!$B$39+VARIABLES!$B$40,VARIABLES!$B$40)) -> 40000 | I14: =H14*VARIABLES!$B$41 -> 300 | J14: =IF($A14<VARIABLES!$B$38,0,(IF($A14=VARIABLES!$B$38,0,K13)+H14)*C14*VARIABLES!$B$42) -> 2457.6419 | K14: =IF($A14<VARIABLES!$B$38,0,(IF($A14=VARIABLES!$B$38,0,K13)+H14)*(1+C14)-J14) -> 513647.15 | L14: =IF($A14<VARIABLES!$B$45,0,IF($A14=VARIABLES!$B$45,VARIABLES!$B$46+VARIABLES!$B$47,VARIABLES!$B$47)) -> 0 | M14: =L14*VARIABLES!$B$48 -> 0 | N14: =IF($A14<VARIABLES!$B$45,0,(IF($A14=VARIABLES!$B$45,0,O13)+L14)*C14*VARIABLES!$B$49) -> 37152.379 | O14: =IF($A14<VARIABLES!$B$45,0,(IF($A14=VARIABLES!$B$45,0,O13)+L14)*(1+C14)-N14) -> 7764847.1 | P14: =IF($A14<VARIABLES!$B$52,0,IF($A14=VARIABLES!$B$52,VARIABLES!$B$53+VARIABLES!$B$54,VARIABLES!$B$54)) -> 20000 | Q14: =P14*VARIABLES!$B$55 -> 150 | R14: =IF($A14<VARIABLES!$B$52,0,(IF($A14=VARIABLES!$B$52,0,S13)+P14)*C14*VARIABLES!$B$56) -> 312.61876 | S14: =IF($A14<VARIABLES!$B$52,0,(IF($A14=VARIABLES!$B$52,0,S13)+P14)*(1+C14)-R14) -> 262287.14 | T14: =IF($A14<VARIABLES!$B$60,0,MIN(VARIABLES!$B$59,INT(($A14-VARIABLES!$B$60)/VARIABLES!$B$61)+1)*VARIABLES!$B$62) -> 9 | U14: =T14*VARIABLES!$B$64+IF(AND($A14>=VARIABLES!$B$60,MOD($A14-VARIABLES!$B$60,VARIABLES!$B$61)=0,INT(($A14-VARIABLES!$B$60)/VARIABLES!$B$61)<VARIABLES!$B$59),VARIABLES!$B$62*VARIABLES!$B$63,0) -> 95000 | V14: =U14*VARIABLES!$B$65 -> 712.5 | W14: =IF($A14<VARIABLES!$B$60,0,(IF($A14<VARIABLES!$B$60+1,0,X13)+U14)*C14*VARIABLES!$B$66) -> 3971.756 | X14: =IF($A14<VARIABLES!$B$60,0,(IF($A14<VARIABLES!$B$60+1,0,X13)+U14)*(1+C14)-W14) -> 830097 | Y14: =D14+H14+L14+P14+U14 -> 355000 | Z14: =E14+I14+M14+Q14+V14 -> 2662.5 | AA14: =F14+J14+N14+R14+W14 -> 48026.587 | AB14: =(IF($A14=1,0,AD13)*VARIABLES!$B$18*VARIABLES!$B$16*VARIABLES!$B$17)+(Y14*VARIABLES!$B$16*VARIABLES!$B$17) -> 1667.1505 | AC14: =Z14+AA14+AB14 -> 52356.237 | AD14: =G14+K14+O14+S14+X14 -> 12837787 | AE14: =IF($A14=1,VARIABLES!$B$21,0) -> 0 | AF14: =IF($A14<=3,VARIABLES!$B$22,IF($A14<=6,VARIABLES!$B$23,VARIABLES!$B$24))*(1+VARIABLES!$B$25)^INT(($A14-1)/12) -> 46000 | AG14: =IF(MOD($A14,12)=0,AD14*VARIABLES!$B$26,0) -> 0 | AH14: =VARIABLES!$B$27 -> 5000 | AI14: =IF(MOD($A14,12)=0,VARIABLES!$B$28,0) -> 0 | AJ14: =AE14+AF14+AG14+AH14+AI14 -> 51000 | AK14: =IF(OR($A14<VARIABLES!$B$7,AND($A14>=VARIABLES!$B$8,$A14<VARIABLES!$B$10)),VARIABLES!$B$13,0) -> 0 | AL14: =AC14-AJ14-AK14 -> 1356.2373 | AM14: =AM13+AL14 -> -71375.933 | AN14: =AN13+AK14 -> 0
A15: 12 | B15: =TEXT(DATE(VARIABLES!$B$70+INT((VARIABLES!$B$71+$A15-2)/12),MOD(VARIABLES!$B$71+$A15-2,12)+1,1),"mmm-yy") -> May-27 | C15: =IF($A15<VARIABLES!$B$7,VARIABLES!$B$5/12,IF($A15<VARIABLES!$B$8,VARIABLES!$B$6/12,IF($A15<VARIABLES!$B$10,VARIABLES!$B$9/12,VARIABLES!$B$11/12))) -> 0.05 | D15: =IF($A15<VARIABLES!$B$31,0,IF($A15=VARIABLES!$B$31,VARIABLES!$B$32+VARIABLES!$B$33,VARIABLES!$B$33)) -> 200000 | E15: =D15*VARIABLES!$B$34 -> 1500 | F15: =IF($A15<VARIABLES!$B$31,0,(IF($A15=VARIABLES!$B$31,0,G14)+D15)*C15*VARIABLES!$B$35) -> 4583.636 | G15: =IF($A15<VARIABLES!$B$31,0,(IF($A15=VARIABLES!$B$31,0,G14)+D15)*(1+C15)-F15) -> 3845670.6 | H15: =IF($A15<VARIABLES!$B$38,0,IF($A15=VARIABLES!$B$38,VARIABLES!$B$39+VARIABLES!$B$40,VARIABLES!$B$40)) -> 40000 | I15: =H15*VARIABLES!$B$41 -> 300 | J15: =IF($A15<VARIABLES!$B$38,0,(IF($A15=VARIABLES!$B$38,0,K14)+H15)*C15*VARIABLES!$B$42) -> 2768.2358 | K15: =IF($A15<VARIABLES!$B$38,0,(IF($A15=VARIABLES!$B$38,0,K14)+H15)*(1+C15)-J15) -> 578561.27 | L15: =IF($A15<VARIABLES!$B$45,0,IF($A15=VARIABLES!$B$45,VARIABLES!$B$46+VARIABLES!$B$47,VARIABLES!$B$47)) -> 0 | M15: =L15*VARIABLES!$B$48 -> 0 | N15: =IF($A15<VARIABLES!$B$45,0,(IF($A15=VARIABLES!$B$45,0,O14)+L15)*C15*VARIABLES!$B$49) -> 38824.236 | O15: =IF($A15<VARIABLES!$B$45,0,(IF($A15=VARIABLES!$B$45,0,O14)+L15)*(1+C15)-N15) -> 8114265.2 | P15: =IF($A15<VARIABLES!$B$52,0,IF($A15=VARIABLES!$B$52,VARIABLES!$B$53+VARIABLES!$B$54,VARIABLES!$B$54)) -> 20000 | Q15: =P15*VARIABLES!$B$55 -> 150 | R15: =IF($A15<VARIABLES!$B$52,0,(IF($A15=VARIABLES!$B$52,0,S14)+P15)*C15*VARIABLES!$B$56) -> 352.85892 | S15: =IF($A15<VARIABLES!$B$52,0,(IF($A15=VARIABLES!$B$52,0,S14)+P15)*(1+C15)-R15) -> 296048.64 | T15: =IF($A15<VARIABLES!$B$60,0,MIN(VARIABLES!$B$59,INT(($A15-VARIABLES!$B$60)/VARIABLES!$B$61)+1)*VARIABLES!$B$62) -> 10 | U15: =T15*VARIABLES!$B$64+IF(AND($A15>=VARIABLES!$B$60,MOD($A15-VARIABLES!$B$60,VARIABLES!$B$61)=0,INT(($A15-VARIABLES!$B$60)/VARIABLES!$B$61)<VARIABLES!$B$59),VARIABLES!$B$62*VARIABLES!$B$63,0) -> 100000 | V15: =U15*VARIABLES!$B$65 -> 750 | W15: =IF($A15<VARIABLES!$B$60,0,(IF($A15<VARIABLES!$B$60+1,0,X14)+U15)*C15*VARIABLES!$B$66) -> 4650.485 | X15: =IF($A15<VARIABLES!$B$60,0,(IF($A15<VARIABLES!$B$60+1,0,X14)+U15)*(1+C15)-W15) -> 971951.37 | Y15: =D15+H15+L15+P15+U15 -> 360000 | Z15: =E15+I15+M15+Q15+V15 -> 2700 | AA15: =F15+J15+N15+R15+W15 -> 51179.451 | AB15: =(IF($A15=1,0,AD14)*VARIABLES!$B$18*VARIABLES!$B$16*VARIABLES!$B$17)+(Y15*VARIABLES!$B$16*VARIABLES!$B$17) -> 1784.7234 | AC15: =Z15+AA15+AB15 -> 55664.175 | AD15: =G15+K15+O15+S15+X15 -> 13806497 | AE15: =IF($A15=1,VARIABLES!$B$21,0) -> 0 | AF15: =IF($A15<=3,VARIABLES!$B$22,IF($A15<=6,VARIABLES!$B$23,VARIABLES!$B$24))*(1+VARIABLES!$B$25)^INT(($A15-1)/12) -> 46000 | AG15: =IF(MOD($A15,12)=0,AD15*VARIABLES!$B$26,0) -> 34516.243 | AH15: =VARIABLES!$B$27 -> 5000 | AI15: =IF(MOD($A15,12)=0,VARIABLES!$B$28,0) -> 3000 | AJ15: =AE15+AF15+AG15+AH15+AI15 -> 88516.243 | AK15: =IF(OR($A15<VARIABLES!$B$7,AND($A15>=VARIABLES!$B$8,$A15<VARIABLES!$B$10)),VARIABLES!$B$13,0) -> 0 | AL15: =AC15-AJ15-AK15 -> -32852.068 | AM15: =AM14+AL15 -> -104228 | AN15: =AN14+AK15 -> 0
A16: 13 | B16: =TEXT(DATE(VARIABLES!$B$70+INT((VARIABLES!$B$71+$A16-2)/12),MOD(VARIABLES!$B$71+$A16-2,12)+1,1),"mmm-yy") -> Jun-27 | C16: =IF($A16<VARIABLES!$B$7,VARIABLES!$B$5/12,IF($A16<VARIABLES!$B$8,VARIABLES!$B$6/12,IF($A16<VARIABLES!$B$10,VARIABLES!$B$9/12,VARIABLES!$B$11/12))) -> 0.05 | D16: =IF($A16<VARIABLES!$B$31,0,IF($A16=VARIABLES!$B$31,VARIABLES!$B$32+VARIABLES!$B$33,VARIABLES!$B$33)) -> 200000 | E16: =D16*VARIABLES!$B$34 -> 1500 | F16: =IF($A16<VARIABLES!$B$31,0,(IF($A16=VARIABLES!$B$31,0,G15)+D16)*C16*VARIABLES!$B$35) -> 5057.0883 | G16: =IF($A16<VARIABLES!$B$31,0,(IF($A16=VARIABLES!$B$31,0,G15)+D16)*(1+C16)-F16) -> 4242897.1 | H16: =IF($A16<VARIABLES!$B$38,0,IF($A16=VARIABLES!$B$38,VARIABLES!$B$39+VARIABLES!$B$40,VARIABLES!$B$40)) -> 40000 | I16: =H16*VARIABLES!$B$41 -> 300 | J16: =IF($A16<VARIABLES!$B$38,0,(IF($A16=VARIABLES!$B$38,0,K15)+H16)*C16*VARIABLES!$B$42) -> 3092.8064 | K16: =IF($A16<VARIABLES!$B$38,0,(IF($A16=VARIABLES!$B$38,0,K15)+H16)*(1+C16)-J16) -> 646396.53 | L16: =IF($A16<VARIABLES!$B$45,0,IF($A16=VARIABLES!$B$45,VARIABLES!$B$46+VARIABLES!$B$47,VARIABLES!$B$47)) -> 0 | M16: =L16*VARIABLES!$B$48 -> 0 | N16: =IF($A16<VARIABLES!$B$45,0,(IF($A16=VARIABLES!$B$45,0,O15)+L16)*C16*VARIABLES!$B$49) -> 40571.326 | O16: =IF($A16<VARIABLES!$B$45,0,(IF($A16=VARIABLES!$B$45,0,O15)+L16)*(1+C16)-N16) -> 8479407.2 | P16: =IF($A16<VARIABLES!$B$52,0,IF($A16=VARIABLES!$B$52,VARIABLES!$B$53+VARIABLES!$B$54,VARIABLES!$B$54)) -> 20000 | Q16: =P16*VARIABLES!$B$55 -> 150 | R16: =IF($A16<VARIABLES!$B$52,0,(IF($A16=VARIABLES!$B$52,0,S15)+P16)*C16*VARIABLES!$B$56) -> 395.0608 | S16: =IF($A16<VARIABLES!$B$52,0,(IF($A16=VARIABLES!$B$52,0,S15)+P16)*(1+C16)-R16) -> 331456.01 | T16: =IF($A16<VARIABLES!$B$60,0,MIN(VARIABLES!$B$59,INT(($A16-VARIABLES!$B$60)/VARIABLES!$B$61)+1)*VARIABLES!$B$62) -> 11 | U16: =T16*VARIABLES!$B$64+IF(AND($A16>=VARIABLES!$B$60,MOD($A16-VARIABLES!$B$60,VARIABLES!$B$61)=0,INT(($A16-VARIABLES!$B$60)/VARIABLES!$B$61)<VARIABLES!$B$59),VARIABLES!$B$62*VARIABLES!$B$63,0) -> 105000 | V16: =U16*VARIABLES!$B$65 -> 787.5 | W16: =IF($A16<VARIABLES!$B$60,0,(IF($A16<VARIABLES!$B$60+1,0,X15)+U16)*C16*VARIABLES!$B$66) -> 5384.7568 | X16: =IF($A16<VARIABLES!$B$60,0,(IF($A16<VARIABLES!$B$60+1,0,X15)+U16)*(1+C16)-W16) -> 1125414.2 | Y16: =D16+H16+L16+P16+U16 -> 365000 | Z16: =E16+I16+M16+Q16+V16 -> 2737.5 | AA16: =F16+J16+N16+R16+W16 -> 54501.038 | AB16: =(IF($A16=1,0,AD15)*VARIABLES!$B$18*VARIABLES!$B$16*VARIABLES!$B$17)+(Y16*VARIABLES!$B$16*VARIABLES!$B$17) -> 1908.3121 | AC16: =Z16+AA16+AB16 -> 59146.851 | AD16: =G16+K16+O16+S16+X16 -> 14825571 | AE16: =IF($A16=1,VARIABLES!$B$21,0) -> 0 | AF16: =IF($A16<=3,VARIABLES!$B$22,IF($A16<=6,VARIABLES!$B$23,VARIABLES!$B$24))*(1+VARIABLES!$B$25)^INT(($A16-1)/12) -> 48760 | AG16: =IF(MOD($A16,12)=0,AD16*VARIABLES!$B$26,0) -> 0 | AH16: =VARIABLES!$B$27 -> 5000 | AI16: =IF(MOD($A16,12)=0,VARIABLES!$B$28,0) -> 0 | AJ16: =AE16+AF16+AG16+AH16+AI16 -> 53760 | AK16: =IF(OR($A16<VARIABLES!$B$7,AND($A16>=VARIABLES!$B$8,$A16<VARIABLES!$B$10)),VARIABLES!$B$13,0) -> 0 | AL16: =AC16-AJ16-AK16 -> 5386.8506 | AM16: =AM15+AL16 -> -98841.15 | AN16: =AN15+AK16 -> 0
... A99: 96 | B99: =TEXT(DATE(VARIABLES!$B$70+INT((VARIABLES!$B$71+$A99-2)/12),MOD(VARIABLES!$B$71+$A99-2,12)+1,1),"mmm-yy") -> May-34 | C99: =IF($A99<VARIABLES!$B$7,VARIABLES!$B$5/12,IF($A99<VARIABLES!$B$8,VARIABLES!$B$6/12,IF($A99<VARIABLES!$B$10,VARIABLES!$B$9/12,VARIABLES!$B$11/12))) -> 0.0083333333 | D99: =IF($A99<VARIABLES!$B$31,0,IF($A99=VARIABLES!$B$31,VARIABLES!$B$32+VARIABLES!$B$33,VARIABLES!$B$33)) -> 200000 | E99: =D99*VARIABLES!$B$34 -> 1500 | F99: =IF($A99<VARIABLES!$B$31,0,(IF($A99=VARIABLES!$B$31,0,G98)+D99)*C99*VARIABLES!$B$35) -> 29014.193 | G99: =IF($A99<VARIABLES!$B$31,0,(IF($A99=VARIABLES!$B$31,0,G98)+D99)*(1+C99)-F99) -> 1.4039968e+08 | H99: =IF($A99<VARIABLES!$B$38,0,IF($A99=VARIABLES!$B$38,VARIABLES!$B$39+VARIABLES!$B$40,VARIABLES!$B$40)) -> 40000 | I99: =H99*VARIABLES!$B$41 -> 300 | J99: =IF($A99<VARIABLES!$B$38,0,(IF($A99=VARIABLES!$B$38,0,K98)+H99)*C99*VARIABLES!$B$42) -> 17586.339 | K99: =IF($A99<VARIABLES!$B$38,0,(IF($A99=VARIABLES!$B$38,0,K98)+H99)*(1+C99)-J99) -> 21261884 | L99: =IF($A99<VARIABLES!$B$45,0,IF($A99=VARIABLES!$B$45,VARIABLES!$B$46+VARIABLES!$B$47,VARIABLES!$B$47)) -> 0 | M99: =L99*VARIABLES!$B$48 -> 0 | N99: =IF($A99<VARIABLES!$B$45,0,(IF($A99=VARIABLES!$B$45,0,O98)+L99)*C99*VARIABLES!$B$49) -> 86909.445 | O99: =IF($A99<VARIABLES!$B$45,0,(IF($A99=VARIABLES!$B$45,0,O98)+L99)*(1+C99)-N99) -> 1.0507352e+08 | P99: =IF($A99<VARIABLES!$B$52,0,IF($A99=VARIABLES!$B$52,VARIABLES!$B$53+VARIABLES!$B$54,VARIABLES!$B$54)) -> 20000 | Q99: =P99*VARIABLES!$B$55 -> 150 | R99: =IF($A99<VARIABLES!$B$52,0,(IF($A99=VARIABLES!$B$52,0,S98)+P99)*C99*VARIABLES!$B$56) -> 2609.4455 | S99: =IF($A99<VARIABLES!$B$52,0,(IF($A99=VARIABLES!$B$52,0,S98)+P99)*(1+C99)-R99) -> 12627107 | T99: =IF($A99<VARIABLES!$B$60,0,MIN(VARIABLES!$B$59,INT(($A99-VARIABLES!$B$60)/VARIABLES!$B$61)+1)*VARIABLES!$B$62) -> 94 | U99: =T99*VARIABLES!$B$64+IF(AND($A99>=VARIABLES!$B$60,MOD($A99-VARIABLES!$B$60,VARIABLES!$B$61)=0,INT(($A99-VARIABLES!$B$60)/VARIABLES!$B$61)<VARIABLES!$B$59),VARIABLES!$B$62*VARIABLES!$B$63,0) -> 520000 | V99: =U99*VARIABLES!$B$65 -> 3900 | W99: =IF($A99<VARIABLES!$B$60,0,(IF($A99<VARIABLES!$B$60+1,0,X98)+U99)*C99*VARIABLES!$B$66) -> 75467.547 | X99: =IF($A99<VARIABLES!$B$60,0,(IF($A99<VARIABLES!$B$60+1,0,X98)+U99)*(1+C99)-W99) -> 91240265 | Y99: =D99+H99+L99+P99+U99 -> 780000 | Z99: =E99+I99+M99+Q99+V99 -> 5850 | AA99: =F99+J99+N99+R99+W99 -> 211586.97 | AB99: =(IF($A99=1,0,AD98)*VARIABLES!$B$18*VARIABLES!$B$16*VARIABLES!$B$17)+(Y99*VARIABLES!$B$16*VARIABLES!$B$17) -> 46261.183 | AC99: =Z99+AA99+AB99 -> 263698.15 | AD99: =G99+K99+O99+S99+X99 -> 3.7060245e+08 | AE99: =IF($A99=1,VARIABLES!$B$21,0) -> 0 | AF99: =IF($A99<=3,VARIABLES!$B$22,IF($A99<=6,VARIABLES!$B$23,VARIABLES!$B$24))*(1+VARIABLES!$B$25)^INT(($A99-1)/12) -> 69166.992 | AG99: =IF(MOD($A99,12)=0,AD99*VARIABLES!$B$26,0) -> 926506.13 | AH99: =VARIABLES!$B$27 -> 5000 | AI99: =IF(MOD($A99,12)=0,VARIABLES!$B$28,0) -> 3000 | AJ99: =AE99+AF99+AG99+AH99+AI99 -> 1003673.1 | AK99: =IF(OR($A99<VARIABLES!$B$7,AND($A99>=VARIABLES!$B$8,$A99<VARIABLES!$B$10)),VARIABLES!$B$13,0) -> 0 | AL99: =AC99-AJ99-AK99 -> -739974.97 | AM99: =AM98+AL99 -> 16590392 | AN99: =AN98+AK99 -> 0
A100: TOTAL / FINAL (96 months) | Y100: =SUM(Y4:Y99) -> 57225000 | Z100: =SUM(Z4:Z99) -> 429187.5 | AA100: =SUM(AA4:AA99) -> 23569564 | AB100: =SUM(AB4:AB99) -> 1507186.6 | AC100: =SUM(AC4:AC99) -> 25505939 | AD100: =AD99 -> 3.7060245e+08 | AE100: =SUM(AE4:AE99) -> 57500 | AF100: =SUM(AF4:AF99) -> 5359902.3 | AG100: =SUM(AG4:AG99) -> 2994143.9 | AH100: =SUM(AH4:AH99) -> 480000 | AI100: =SUM(AI4:AI99) -> 24000 | AJ100: =SUM(AJ4:AJ99) -> 8915546.2 | AK100: =SUM(AK4:AK99) -> 0 | AL100: =SUM(AL4:AL99) -> 16590392 | AM100: =AM99 -> 16590392 | AN100: =AN99 -> 0
A102: NOTES: ① Expand group D:X (click + above column D) to view per-client detail. ② Performance fee = simplified monthly accrual (AUM × monthly_return × perf_rate). ③ Exchange fee revenue = (prev_AUM × 25% traded × 0.1% fee × 50% share) + (contributions × 0.1% × 50% share). Both rates adjustable in Variables. Covers ZAR/USDT, USDT/BTC, USDT/USDPC conversions. ④ Returns: 4-tier: 60% Y1-3 → 10% Y4 (bear) → 50% Y5-7 → 10% Y8 (bear); all adjustable in Variables. ⑤ Reserve provision accumulates in BULL years only (Y1-3 and Y5-7); no provision in Y4 and Y8 (bear years). no automated drawdown — compare Reserve Fund Bal vs Cumulative Cash to assess Y4 coverage. ⑥ CAEP costs: R57.5k onboarding (M1), tiered hosting R23k/34.5k/46k per month, 0.25% AUM fee annually.

Sheet CHARTS
A1: BitWealth (Pty) Ltd — 96-Month Visual Summary · FSP: CAEP
