Workbook

Sheet VARIABLES
A1: BitWealth (Pty) Ltd — Cashflow Model Variables
A2: v3.0 · 48-Month Forecast · Adjust YELLOW cells · All formulas in 'MONTHLY FORECAST' tab update automatically
A4: RETURN & PERFORMANCE ASSUMPTIONS
A5: Annual portfolio return — Years 1–3 (p.a.) | B5: 0.4 | C5: 40% p.a. BTC bull cycle; divided by 12 for monthly
A6: Annual portfolio return — Year 4 (p.a.) | B6: 0.1 | C6: 10% — BTC bear/consolidation year; set to e.g. 20% for optimistic Y4
A7: Year 4 starts (model month number) | B7: 37 | C7: Month 37 = July 2029 (one month after the 36-month bull period)
A8: Performance fee crystallisation period (months) | B8: 3 | C8: 3 = quarterly (default). Change to 1 for monthly, 12 for annual
A9: Monthly reserve provision into Y4 buffer (R) | B9: =380883/36 -> 10580.083 | C9: Set aside this amount each month in Years 1–3 to fund Year 4 cash deficit
A11: COST ASSUMPTIONS
A12: CAEP onboarding fee (once-off, Month 1) | B12: =50000*1.15 -> 57500 | C12: Juristic Representative appointment fee
A13: CAEP hosting — Months 1–3 | B13: =20000*1.15 -> 23000 | C13: Per month
A14: CAEP hosting — Months 4–6 | B14: =30000*1.15 -> 34500 | C14: Per month
A15: CAEP hosting — Month 7 onwards | B15: =40000*1.15 -> 46000 | C15: Per month steady-state; negotiate cap contractually
A16: CAEP AUM fee (% of AUM, billed once annually) | B16: 0.0025 | C16: 0.25% p.a.; billed in months 12, 24, 36, 48 on AUM at that date
A17: Software & infrastructure (monthly) | B17: 5000 | C17: Cloud, Supabase, On-Chain API, Netlify, Domains, etc.
A18: Company secretarial (annual, charged in month 12/24/36/48) | B18: 3000 | C18: CIPC return + company secretary
A20: CLIENT 1 (Founding — Davin referral / existing)
A21: Start month | B21: 1 | C21: Month 1 = June 2026
A22: Initial lump sum (R) | B22: 300000
A23: Monthly contribution (R) | B23: 200000 | C23: Minimum 5 years
A24: Platform fee rate | B24: 0.0075 | C24: 0.75%
A25: Performance fee rate | B25: 0.025 | C25: 2.5% — negotiated rate for this client
A27: CLIENT 2 (Founding — lined-up)
A28: Start month | B28: 2 | C28: Month 2 = July 2026
A29: Initial lump sum (R) | B29: 0
A30: Monthly contribution (R) | B30: 40000
A31: Platform fee rate | B31: 0.0075
A32: Performance fee rate | B32: 0.1 | C32: Standard 10%
A34: CLIENT 3 (Founding — large lump sum)
A35: Start month | B35: 2 | C35: Month 2 = July 2026
A36: Initial lump sum (R) | B36: 5000000
A37: Monthly contribution (R) | B37: 0 | C37: No monthly contributions
A38: Platform fee rate | B38: 0.0075 | C38: 0.75% on lump sum = R37 500 on day 1
A39: Performance fee rate | B39: 0.1 | C39: Standard 10%
A41: CLIENT 4 (Founding — lined-up)
A42: Start month | B42: 2 | C42: Month 2 = July 2026
A43: Initial lump sum (R) | B43: 0
A44: Monthly contribution (R) | B44: 20000
A45: Platform fee rate | B45: 0.0075
A46: Performance fee rate | B46: 0.025 | C46: 2.5% — preferential rate
...

Sheet MONTHLY FORECAST
A1: BitWealth (Pty) Ltd — 48-Month Operating Cashflow Forecast v3.0 · All formulas auto-update when VARIABLES are changed
A2: PERIOD | D2: CLIENT DETAIL (hidden by default — click + to expand) | T2: NEW CLIENTS | Y2: REVENUE | AC2: TOTAL AUM | AD2: COSTS | AJ2: RESERVE | AK2: CASHFLOW
A3: Month # | B3: Month | C3: Monthly Return % | D3: C1 Contrib | E3: C1 Plat Fee | F3: C1 Perf Fee | G3: C1 AUM | H3: C2 Contrib | I3: C2 Plat Fee | J3: C2 Perf Fee | K3: C2 AUM | L3: C3 Contrib | M3: C3 Plat Fee | N3: C3 Perf Fee | O3: C3 AUM | P3: C4 Contrib | Q3: C4 Plat Fee | R3: C4 Perf Fee | S3: C4 AUM | T3: NC Active# | U3: NC Contrib | V3: NC Plat Fee | W3: NC Perf Fee | X3: NC AUM | Y3: Total Contrib | Z3: Total Plat Fee | AA3: Total Perf Fee | AB3: TOTAL REVENUE | AC3: TOTAL AUM | AD3: CAEP Onboard | AE3: CAEP Hosting | AF3: CAEP AUM Fee | AG3: Software | AH3: Co Sec | AI3: TOTAL COSTS | AJ3: Reserve Provision | AK3: NET CASH (after reserve) | AL3: CUMULATIVE CASH | AM3: Reserve Fund Bal
A4: 1 | B4: =TEXT(DATE(VARIABLES!$B$60+INT((VARIABLES!$B$61+A4-2)/12),MOD(VARIABLES!$B$61+A4-2,12)+1,1),"mmm-yy") -> Jun-26 | C4: =IF($A4<VARIABLES!$B$7,VARIABLES!$B$5/12,VARIABLES!$B$6/12) -> 0.033333333 | D4: =IF($A4<VARIABLES!$B$21,0,IF($A4=VARIABLES!$B$21,VARIABLES!$B$22+VARIABLES!$B$23,VARIABLES!$B$23)) -> 500000 | E4: =D4*VARIABLES!$B$24 -> 3750 | F4: =IF($A4<VARIABLES!$B$21,0,(IF($A4=VARIABLES!$B$21,0,G3)+D4)*C4*VARIABLES!$B$25) -> 416.66667 | G4: =IF($A4<VARIABLES!$B$21,0,(IF($A4=VARIABLES!$B$21,0,G3)+D4)*(1+C4)-F4) -> 516250 | H4: =IF($A4<VARIABLES!$B$28,0,IF($A4=VARIABLES!$B$28,VARIABLES!$B$29+VARIABLES!$B$30,VARIABLES!$B$30)) -> 0 | I4: =H4*VARIABLES!$B$31 -> 0 | J4: =IF($A4<VARIABLES!$B$28,0,(IF($A4=VARIABLES!$B$28,0,K3)+H4)*C4*VARIABLES!$B$32) -> 0 | K4: =IF($A4<VARIABLES!$B$28,0,(IF($A4=VARIABLES!$B$28,0,K3)+H4)*(1+C4)-J4) -> 0 | L4: =IF($A4<VARIABLES!$B$35,0,IF($A4=VARIABLES!$B$35,VARIABLES!$B$36+VARIABLES!$B$37,VARIABLES!$B$37)) -> 0 | M4: =L4*VARIABLES!$B$38 -> 0 | N4: =IF($A4<VARIABLES!$B$35,0,(IF($A4=VARIABLES!$B$35,0,O3)+L4)*C4*VARIABLES!$B$39) -> 0 | O4: =IF($A4<VARIABLES!$B$35,0,(IF($A4=VARIABLES!$B$35,0,O3)+L4)*(1+C4)-N4) -> 0 | P4: =IF($A4<VARIABLES!$B$42,0,IF($A4=VARIABLES!$B$42,VARIABLES!$B$43+VARIABLES!$B$44,VARIABLES!$B$44)) -> 0 | Q4: =P4*VARIABLES!$B$45 -> 0 | R4: =IF($A4<VARIABLES!$B$42,0,(IF($A4=VARIABLES!$B$42,0,S3)+P4)*C4*VARIABLES!$B$46) -> 0 | S4: =IF($A4<VARIABLES!$B$42,0,(IF($A4=VARIABLES!$B$42,0,S3)+P4)*(1+C4)-R4) -> 0 | T4: =IF($A4<VARIABLES!$B$50,0,MIN(VARIABLES!$B$49,INT(($A4-VARIABLES!$B$50)/VARIABLES!$B$51)+1)*VARIABLES!$B$52) -> 0 | U4: =T4*VARIABLES!$B$54+IF(AND($A4>=VARIABLES!$B$50,MOD($A4-VARIABLES!$B$50,VARIABLES!$B$51)=0,INT(($A4-VARIABLES!$B$50)/VARIABLES!$B$51)<VARIABLES!$B$49),VARIABLES!$B$52*VARIABLES!$B$53,0) -> 0 | V4: =U4*VARIABLES!$B$55 -> 0 | W4: =IF($A4<VARIABLES!$B$50,0,(IF($A4<VARIABLES!$B$50+1,0,X3)+U4)*C4*VARIABLES!$B$56) -> 0 | X4: =IF($A4<VARIABLES!$B$50,0,(IF($A4<VARIABLES!$B$50+1,0,X3)+U4)*(1+C4)-W4) -> 0 | Y4: =D4+H4+L4+P4+U4 -> 500000 | Z4: =E4+I4+M4+Q4+V4 -> 3750 | AA4: =F4+J4+N4+R4+W4 -> 416.66667 | AB4: =Z4+AA4 -> 4166.6667 | AC4: =G4+K4+O4+S4+X4 -> 516250 | AD4: =IF($A4=1,VARIABLES!$B$12,0) -> 57500 | AE4: =IF($A4<=3,VARIABLES!$B$13,IF($A4<=6,VARIABLES!$B$14,VARIABLES!$B$15)) -> 23000 | AF4: =IF(MOD($A4,12)=0,AC4*VARIABLES!$B$16,0) -> 0 | AG4: =VARIABLES!$B$17 -> 5000 | AH4: =IF(MOD($A4,12)=0,VARIABLES!$B$18,0) -> 0 | AI4: =AD4+AE4+AF4+AG4+AH4 -> 85500 | AJ4: =IF($A4<VARIABLES!$B$7,VARIABLES!$B$9,0) -> 10580.083 | AK4: =AB4-AI4-AJ4 -> -91913.417 | AL4: =AK4 -> -91913.417 | AM4: =AJ4 -> 10580.083
A5: 2 | B5: =TEXT(DATE(VARIABLES!$B$60+INT((VARIABLES!$B$61+A5-2)/12),MOD(VARIABLES!$B$61+A5-2,12)+1,1),"mmm-yy") -> Jul-26 | C5: =IF($A5<VARIABLES!$B$7,VARIABLES!$B$5/12,VARIABLES!$B$6/12) -> 0.033333333 | D5: =IF($A5<VARIABLES!$B$21,0,IF($A5=VARIABLES!$B$21,VARIABLES!$B$22+VARIABLES!$B$23,VARIABLES!$B$23)) -> 200000 | E5: =D5*VARIABLES!$B$24 -> 1500 | F5: =IF($A5<VARIABLES!$B$21,0,(IF($A5=VARIABLES!$B$21,0,G4)+D5)*C5*VARIABLES!$B$25) -> 596.875 | G5: =IF($A5<VARIABLES!$B$21,0,(IF($A5=VARIABLES!$B$21,0,G4)+D5)*(1+C5)-F5) -> 739528.13 | H5: =IF($A5<VARIABLES!$B$28,0,IF($A5=VARIABLES!$B$28,VARIABLES!$B$29+VARIABLES!$B$30,VARIABLES!$B$30)) -> 40000 | I5: =H5*VARIABLES!$B$31 -> 300 | J5: =IF($A5<VARIABLES!$B$28,0,(IF($A5=VARIABLES!$B$28,0,K4)+H5)*C5*VARIABLES!$B$32) -> 133.33333 | K5: =IF($A5<VARIABLES!$B$28,0,(IF($A5=VARIABLES!$B$28,0,K4)+H5)*(1+C5)-J5) -> 41200 | L5: =IF($A5<VARIABLES!$B$35,0,IF($A5=VARIABLES!$B$35,VARIABLES!$B$36+VARIABLES!$B$37,VARIABLES!$B$37)) -> 5000000 | M5: =L5*VARIABLES!$B$38 -> 37500 | N5: =IF($A5<VARIABLES!$B$35,0,(IF($A5=VARIABLES!$B$35,0,O4)+L5)*C5*VARIABLES!$B$39) -> 16666.667 | O5: =IF($A5<VARIABLES!$B$35,0,(IF($A5=VARIABLES!$B$35,0,O4)+L5)*(1+C5)-N5) -> 5150000 | P5: =IF($A5<VARIABLES!$B$42,0,IF($A5=VARIABLES!$B$42,VARIABLES!$B$43+VARIABLES!$B$44,VARIABLES!$B$44)) -> 20000 | Q5: =P5*VARIABLES!$B$45 -> 150 | R5: =IF($A5<VARIABLES!$B$42,0,(IF($A5=VARIABLES!$B$42,0,S4)+P5)*C5*VARIABLES!$B$46) -> 16.666667 | S5: =IF($A5<VARIABLES!$B$42,0,(IF($A5=VARIABLES!$B$42,0,S4)+P5)*(1+C5)-R5) -> 20650 | T5: =IF($A5<VARIABLES!$B$50,0,MIN(VARIABLES!$B$49,INT(($A5-VARIABLES!$B$50)/VARIABLES!$B$51)+1)*VARIABLES!$B$52) -> 0 | U5: =T5*VARIABLES!$B$54+IF(AND($A5>=VARIABLES!$B$50,MOD($A5-VARIABLES!$B$50,VARIABLES!$B$51)=0,INT(($A5-VARIABLES!$B$50)/VARIABLES!$B$51)<VARIABLES!$B$49),VARIABLES!$B$52*VARIABLES!$B$53,0) -> 0 | V5: =U5*VARIABLES!$B$55 -> 0 | W5: =IF($A5<VARIABLES!$B$50,0,(IF($A5<VARIABLES!$B$50+1,0,X4)+U5)*C5*VARIABLES!$B$56) -> 0 | X5: =IF($A5<VARIABLES!$B$50,0,(IF($A5<VARIABLES!$B$50+1,0,X4)+U5)*(1+C5)-W5) -> 0 | Y5: =D5+H5+L5+P5+U5 -> 5260000 | Z5: =E5+I5+M5+Q5+V5 -> 39450 | AA5: =F5+J5+N5+R5+W5 -> 17413.542 | AB5: =Z5+AA5 -> 56863.542 | AC5: =G5+K5+O5+S5+X5 -> 5951378.1 | AD5: =IF($A5=1,VARIABLES!$B$12,0) -> 0 | AE5: =IF($A5<=3,VARIABLES!$B$13,IF($A5<=6,VARIABLES!$B$14,VARIABLES!$B$15)) -> 23000 | AF5: =IF(MOD($A5,12)=0,AC5*VARIABLES!$B$16,0) -> 0 | AG5: =VARIABLES!$B$17 -> 5000 | AH5: =IF(MOD($A5,12)=0,VARIABLES!$B$18,0) -> 0 | AI5: =AD5+AE5+AF5+AG5+AH5 -> 28000 | AJ5: =IF($A5<VARIABLES!$B$7,VARIABLES!$B$9,0) -> 10580.083 | AK5: =AB5-AI5-AJ5 -> 18283.458 | AL5: =IF(AJ5>0,AL4+AK5,AL4) -> -73629.958 | AM5: =IF(AJ5>0,AM4+AJ5,AM4+AK5) -> 21160.167
A6: 3 | B6: =TEXT(DATE(VARIABLES!$B$60+INT((VARIABLES!$B$61+A6-2)/12),MOD(VARIABLES!$B$61+A6-2,12)+1,1),"mmm-yy") -> Aug-26 | C6: =IF($A6<VARIABLES!$B$7,VARIABLES!$B$5/12,VARIABLES!$B$6/12) -> 0.033333333 | D6: =IF($A6<VARIABLES!$B$21,0,IF($A6=VARIABLES!$B$21,VARIABLES!$B$22+VARIABLES!$B$23,VARIABLES!$B$23)) -> 200000 | E6: =D6*VARIABLES!$B$24 -> 1500 | F6: =IF($A6<VARIABLES!$B$21,0,(IF($A6=VARIABLES!$B$21,0,G5)+D6)*C6*VARIABLES!$B$25) -> 782.9401 | G6: =IF($A6<VARIABLES!$B$21,0,(IF($A6=VARIABLES!$B$21,0,G5)+D6)*(1+C6)-F6) -> 970062.79 | H6: =IF($A6<VARIABLES!$B$28,0,IF($A6=VARIABLES!$B$28,VARIABLES!$B$29+VARIABLES!$B$30,VARIABLES!$B$30)) -> 40000 | I6: =H6*VARIABLES!$B$31 -> 300 | J6: =IF($A6<VARIABLES!$B$28,0,(IF($A6=VARIABLES!$B$28,0,K5)+H6)*C6*VARIABLES!$B$32) -> 270.66667 | K6: =IF($A6<VARIABLES!$B$28,0,(IF($A6=VARIABLES!$B$28,0,K5)+H6)*(1+C6)-J6) -> 83636 | L6: =IF($A6<VARIABLES!$B$35,0,IF($A6=VARIABLES!$B$35,VARIABLES!$B$36+VARIABLES!$B$37,VARIABLES!$B$37)) -> 0 | M6: =L6*VARIABLES!$B$38 -> 0 | N6: =IF($A6<VARIABLES!$B$35,0,(IF($A6=VARIABLES!$B$35,0,O5)+L6)*C6*VARIABLES!$B$39) -> 17166.667 | O6: =IF($A6<VARIABLES!$B$35,0,(IF($A6=VARIABLES!$B$35,0,O5)+L6)*(1+C6)-N6) -> 5304500 | P6: =IF($A6<VARIABLES!$B$42,0,IF($A6=VARIABLES!$B$42,VARIABLES!$B$43+VARIABLES!$B$44,VARIABLES!$B$44)) -> 20000 | Q6: =P6*VARIABLES!$B$45 -> 150 | R6: =IF($A6<VARIABLES!$B$42,0,(IF($A6=VARIABLES!$B$42,0,S5)+P6)*C6*VARIABLES!$B$46) -> 33.875 | S6: =IF($A6<VARIABLES!$B$42,0,(IF($A6=VARIABLES!$B$42,0,S5)+P6)*(1+C6)-R6) -> 41971.125 | T6: =IF($A6<VARIABLES!$B$50,0,MIN(VARIABLES!$B$49,INT(($A6-VARIABLES!$B$50)/VARIABLES!$B$51)+1)*VARIABLES!$B$52) -> 1 | U6: =T6*VARIABLES!$B$54+IF(AND($A6>=VARIABLES!$B$50,MOD($A6-VARIABLES!$B$50,VARIABLES!$B$51)=0,INT(($A6-VARIABLES!$B$50)/VARIABLES!$B$51)<VARIABLES!$B$49),VARIABLES!$B$52*VARIABLES!$B$53,0) -> 55000 | V6: =U6*VARIABLES!$B$55 -> 412.5 | W6: =IF($A6<VARIABLES!$B$50,0,(IF($A6<VARIABLES!$B$50+1,0,X5)+U6)*C6*VARIABLES!$B$56) -> 183.33333 | X6: =IF($A6<VARIABLES!$B$50,0,(IF($A6<VARIABLES!$B$50+1,0,X5)+U6)*(1+C6)-W6) -> 56650 | Y6: =D6+H6+L6+P6+U6 -> 315000 | Z6: =E6+I6+M6+Q6+V6 -> 2362.5 | AA6: =F6+J6+N6+R6+W6 -> 18437.482 | AB6: =Z6+AA6 -> 20799.982 | AC6: =G6+K6+O6+S6+X6 -> 6456819.9 | AD6: =IF($A6=1,VARIABLES!$B$12,0) -> 0 | AE6: =IF($A6<=3,VARIABLES!$B$13,IF($A6<=6,VARIABLES!$B$14,VARIABLES!$B$15)) -> 23000 | AF6: =IF(MOD($A6,12)=0,AC6*VARIABLES!$B$16,0) -> 0 | AG6: =VARIABLES!$B$17 -> 5000 | AH6: =IF(MOD($A6,12)=0,VARIABLES!$B$18,0) -> 0 | AI6: =AD6+AE6+AF6+AG6+AH6 -> 28000 | AJ6: =IF($A6<VARIABLES!$B$7,VARIABLES!$B$9,0) -> 10580.083 | AK6: =AB6-AI6-AJ6 -> -17780.102 | AL6: =IF(AJ6>0,AL5+AK6,AL5) -> -91410.06 | AM6: =IF(AJ6>0,AM5+AJ6,AM5+AK6) -> 31740.25
A7: 4 | B7: =TEXT(DATE(VARIABLES!$B$60+INT((VARIABLES!$B$61+A7-2)/12),MOD(VARIABLES!$B$61+A7-2,12)+1,1),"mmm-yy") -> Sept-26 | C7: =IF($A7<VARIABLES!$B$7,VARIABLES!$B$5/12,VARIABLES!$B$6/12) -> 0.033333333 | D7: =IF($A7<VARIABLES!$B$21,0,IF($A7=VARIABLES!$B$21,VARIABLES!$B$22+VARIABLES!$B$23,VARIABLES!$B$23)) -> 200000 | E7: =D7*VARIABLES!$B$24 -> 1500 | F7: =IF($A7<VARIABLES!$B$21,0,(IF($A7=VARIABLES!$B$21,0,G6)+D7)*C7*VARIABLES!$B$25) -> 975.05232 | G7: =IF($A7<VARIABLES!$B$21,0,(IF($A7=VARIABLES!$B$21,0,G6)+D7)*(1+C7)-F7) -> 1208089.8 | H7: =IF($A7<VARIABLES!$B$28,0,IF($A7=VARIABLES!$B$28,VARIABLES!$B$29+VARIABLES!$B$30,VARIABLES!$B$30)) -> 40000 | I7: =H7*VARIABLES!$B$31 -> 300 | J7: =IF($A7<VARIABLES!$B$28,0,(IF($A7=VARIABLES!$B$28,0,K6)+H7)*C7*VARIABLES!$B$32) -> 412.12 | K7: =IF($A7<VARIABLES!$B$28,0,(IF($A7=VARIABLES!$B$28,0,K6)+H7)*(1+C7)-J7) -> 127345.08 | L7: =IF($A7<VARIABLES!$B$35,0,IF($A7=VARIABLES!$B$35,VARIABLES!$B$36+VARIABLES!$B$37,VARIABLES!$B$37)) -> 0 | M7: =L7*VARIABLES!$B$38 -> 0 | N7: =IF($A7<VARIABLES!$B$35,0,(IF($A7=VARIABLES!$B$35,0,O6)+L7)*C7*VARIABLES!$B$39) -> 17681.667 | O7: =IF($A7<VARIABLES!$B$35,0,(IF($A7=VARIABLES!$B$35,0,O6)+L7)*(1+C7)-N7) -> 5463635 | P7: =IF($A7<VARIABLES!$B$42,0,IF($A7=VARIABLES!$B$42,VARIABLES!$B$43+VARIABLES!$B$44,VARIABLES!$B$44)) -> 20000 | Q7: =P7*VARIABLES!$B$45 -> 150 | R7: =IF($A7<VARIABLES!$B$42,0,(IF($A7=VARIABLES!$B$42,0,S6)+P7)*C7*VARIABLES!$B$46) -> 51.642604 | S7: =IF($A7<VARIABLES!$B$42,0,(IF($A7=VARIABLES!$B$42,0,S6)+P7)*(1+C7)-R7) -> 63985.187 | T7: =IF($A7<VARIABLES!$B$50,0,MIN(VARIABLES!$B$49,INT(($A7-VARIABLES!$B$50)/VARIABLES!$B$51)+1)*VARIABLES!$B$52) -> 2 | U7: =T7*VARIABLES!$B$54+IF(AND($A7>=VARIABLES!$B$50,MOD($A7-VARIABLES!$B$50,VARIABLES!$B$51)=0,INT(($A7-VARIABLES!$B$50)/VARIABLES!$B$51)<VARIABLES!$B$49),VARIABLES!$B$52*VARIABLES!$B$53,0) -> 60000 | V7: =U7*VARIABLES!$B$55 -> 450 | W7: =IF($A7<VARIABLES!$B$50,0,(IF($A7<VARIABLES!$B$50+1,0,X6)+U7)*C7*VARIABLES!$B$56) -> 388.83333 | X7: =IF($A7<VARIABLES!$B$50,0,(IF($A7<VARIABLES!$B$50+1,0,X6)+U7)*(1+C7)-W7) -> 120149.5 | Y7: =D7+H7+L7+P7+U7 -> 320000 | Z7: =E7+I7+M7+Q7+V7 -> 2400 | AA7: =F7+J7+N7+R7+W7 -> 19509.315 | AB7: =Z7+AA7 -> 21909.315 | AC7: =G7+K7+O7+S7+X7 -> 6983204.6 | AD7: =IF($A7=1,VARIABLES!$B$12,0) -> 0 | AE7: =IF($A7<=3,VARIABLES!$B$13,IF($A7<=6,VARIABLES!$B$14,VARIABLES!$B$15)) -> 34500 | AF7: =IF(MOD($A7,12)=0,AC7*VARIABLES!$B$16,0) -> 0 | AG7: =VARIABLES!$B$17 -> 5000 | AH7: =IF(MOD($A7,12)=0,VARIABLES!$B$18,0) -> 0 | AI7: =AD7+AE7+AF7+AG7+AH7 -> 39500 | AJ7: =IF($A7<VARIABLES!$B$7,VARIABLES!$B$9,0) -> 10580.083 | AK7: =AB7-AI7-AJ7 -> -28170.768 | AL7: =IF(AJ7>0,AL6+AK7,AL6) -> -119580.83 | AM7: =IF(AJ7>0,AM6+AJ7,AM6+AK7) -> 42320.333
A8: 5 | B8: =TEXT(DATE(VARIABLES!$B$60+INT((VARIABLES!$B$61+A8-2)/12),MOD(VARIABLES!$B$61+A8-2,12)+1,1),"mmm-yy") -> Oct-26 | C8: =IF($A8<VARIABLES!$B$7,VARIABLES!$B$5/12,VARIABLES!$B$6/12) -> 0.033333333 | D8: =IF($A8<VARIABLES!$B$21,0,IF($A8=VARIABLES!$B$21,VARIABLES!$B$22+VARIABLES!$B$23,VARIABLES!$B$23)) -> 200000 | E8: =D8*VARIABLES!$B$24 -> 1500 | F8: =IF($A8<VARIABLES!$B$21,0,(IF($A8=VARIABLES!$B$21,0,G7)+D8)*C8*VARIABLES!$B$25) -> 1173.4082 | G8: =IF($A8<VARIABLES!$B$21,0,(IF($A8=VARIABLES!$B$21,0,G7)+D8)*(1+C8)-F8) -> 1453852.7 | H8: =IF($A8<VARIABLES!$B$28,0,IF($A8=VARIABLES!$B$28,VARIABLES!$B$29+VARIABLES!$B$30,VARIABLES!$B$30)) -> 40000 | I8: =H8*VARIABLES!$B$31 -> 300 | J8: =IF($A8<VARIABLES!$B$28,0,(IF($A8=VARIABLES!$B$28,0,K7)+H8)*C8*VARIABLES!$B$32) -> 557.81693 | K8: =IF($A8<VARIABLES!$B$28,0,(IF($A8=VARIABLES!$B$28,0,K7)+H8)*(1+C8)-J8) -> 172365.43 | L8: =IF($A8<VARIABLES!$B$35,0,IF($A8=VARIABLES!$B$35,VARIABLES!$B$36+VARIABLES!$B$37,VARIABLES!$B$37)) -> 0 | M8: =L8*VARIABLES!$B$38 -> 0 | N8: =IF($A8<VARIABLES!$B$35,0,(IF($A8=VARIABLES!$B$35,0,O7)+L8)*C8*VARIABLES!$B$39) -> 18212.117 | O8: =IF($A8<VARIABLES!$B$35,0,(IF($A8=VARIABLES!$B$35,0,O7)+L8)*(1+C8)-N8) -> 5627544.1 | P8: =IF($A8<VARIABLES!$B$42,0,IF($A8=VARIABLES!$B$42,VARIABLES!$B$43+VARIABLES!$B$44,VARIABLES!$B$44)) -> 20000 | Q8: =P8*VARIABLES!$B$45 -> 150 | R8: =IF($A8<VARIABLES!$B$42,0,(IF($A8=VARIABLES!$B$42,0,S7)+P8)*C8*VARIABLES!$B$46) -> 69.987655 | S8: =IF($A8<VARIABLES!$B$42,0,(IF($A8=VARIABLES!$B$42,0,S7)+P8)*(1+C8)-R8) -> 86714.705 | T8: =IF($A8<VARIABLES!$B$50,0,MIN(VARIABLES!$B$49,INT(($A8-VARIABLES!$B$50)/VARIABLES!$B$51)+1)*VARIABLES!$B$52) -> 3 | U8: =T8*VARIABLES!$B$54+IF(AND($A8>=VARIABLES!$B$50,MOD($A8-VARIABLES!$B$50,VARIABLES!$B$51)=0,INT(($A8-VARIABLES!$B$50)/VARIABLES!$B$51)<VARIABLES!$B$49),VARIABLES!$B$52*VARIABLES!$B$53,0) -> 65000 | V8: =U8*VARIABLES!$B$55 -> 487.5 | W8: =IF($A8<VARIABLES!$B$50,0,(IF($A8<VARIABLES!$B$50+1,0,X7)+U8)*C8*VARIABLES!$B$56) -> 617.165 | X8: =IF($A8<VARIABLES!$B$50,0,(IF($A8<VARIABLES!$B$50+1,0,X7)+U8)*(1+C8)-W8) -> 190703.99 | Y8: =D8+H8+L8+P8+U8 -> 325000 | Z8: =E8+I8+M8+Q8+V8 -> 2437.5 | AA8: =F8+J8+N8+R8+W8 -> 20630.494 | AB8: =Z8+AA8 -> 23067.994 | AC8: =G8+K8+O8+S8+X8 -> 7531180.9 | AD8: =IF($A8=1,VARIABLES!$B$12,0) -> 0 | AE8: =IF($A8<=3,VARIABLES!$B$13,IF($A8<=6,VARIABLES!$B$14,VARIABLES!$B$15)) -> 34500 | AF8: =IF(MOD($A8,12)=0,AC8*VARIABLES!$B$16,0) -> 0 | AG8: =VARIABLES!$B$17 -> 5000 | AH8: =IF(MOD($A8,12)=0,VARIABLES!$B$18,0) -> 0 | AI8: =AD8+AE8+AF8+AG8+AH8 -> 39500 | AJ8: =IF($A8<VARIABLES!$B$7,VARIABLES!$B$9,0) -> 10580.083 | AK8: =AB8-AI8-AJ8 -> -27012.089 | AL8: =IF(AJ8>0,AL7+AK8,AL7) -> -146592.92 | AM8: =IF(AJ8>0,AM7+AJ8,AM7+AK8) -> 52900.417
A9: 6 | B9: =TEXT(DATE(VARIABLES!$B$60+INT((VARIABLES!$B$61+A9-2)/12),MOD(VARIABLES!$B$61+A9-2,12)+1,1),"mmm-yy") -> Nov-26 | C9: =IF($A9<VARIABLES!$B$7,VARIABLES!$B$5/12,VARIABLES!$B$6/12) -> 0.033333333 | D9: =IF($A9<VARIABLES!$B$21,0,IF($A9=VARIABLES!$B$21,VARIABLES!$B$22+VARIABLES!$B$23,VARIABLES!$B$23)) -> 200000 | E9: =D9*VARIABLES!$B$24 -> 1500 | F9: =IF($A9<VARIABLES!$B$21,0,(IF($A9=VARIABLES!$B$21,0,G8)+D9)*C9*VARIABLES!$B$25) -> 1378.2106 | G9: =IF($A9<VARIABLES!$B$21,0,(IF($A9=VARIABLES!$B$21,0,G8)+D9)*(1+C9)-F9) -> 1707603 | H9: =IF($A9<VARIABLES!$B$28,0,IF($A9=VARIABLES!$B$28,VARIABLES!$B$29+VARIABLES!$B$30,VARIABLES!$B$30)) -> 40000 | I9: =H9*VARIABLES!$B$31 -> 300 | J9: =IF($A9<VARIABLES!$B$28,0,(IF($A9=VARIABLES!$B$28,0,K8)+H9)*C9*VARIABLES!$B$32) -> 707.88477 | K9: =IF($A9<VARIABLES!$B$28,0,(IF($A9=VARIABLES!$B$28,0,K8)+H9)*(1+C9)-J9) -> 218736.4 | L9: =IF($A9<VARIABLES!$B$35,0,IF($A9=VARIABLES!$B$35,VARIABLES!$B$36+VARIABLES!$B$37,VARIABLES!$B$37)) -> 0 | M9: =L9*VARIABLES!$B$38 -> 0 | N9: =IF($A9<VARIABLES!$B$35,0,(IF($A9=VARIABLES!$B$35,0,O8)+L9)*C9*VARIABLES!$B$39) -> 18758.48 | O9: =IF($A9<VARIABLES!$B$35,0,(IF($A9=VARIABLES!$B$35,0,O8)+L9)*(1+C9)-N9) -> 5796370.4 | P9: =IF($A9<VARIABLES!$B$42,0,IF($A9=VARIABLES!$B$42,VARIABLES!$B$43+VARIABLES!$B$44,VARIABLES!$B$44)) -> 20000 | Q9: =P9*VARIABLES!$B$45 -> 150 | R9: =IF($A9<VARIABLES!$B$42,0,(IF($A9=VARIABLES!$B$42,0,S8)+P9)*C9*VARIABLES!$B$46) -> 88.928921 | S9: =IF($A9<VARIABLES!$B$42,0,(IF($A9=VARIABLES!$B$42,0,S8)+P9)*(1+C9)-R9) -> 110182.93 | T9: =IF($A9<VARIABLES!$B$50,0,MIN(VARIABLES!$B$49,INT(($A9-VARIABLES!$B$50)/VARIABLES!$B$51)+1)*VARIABLES!$B$52) -> 4 | U9: =T9*VARIABLES!$B$54+IF(AND($A9>=VARIABLES!$B$50,MOD($A9-VARIABLES!$B$50,VARIABLES!$B$51)=0,INT(($A9-VARIABLES!$B$50)/VARIABLES!$B$51)<VARIABLES!$B$49),VARIABLES!$B$52*VARIABLES!$B$53,0) -> 70000 | V9: =U9*VARIABLES!$B$55 -> 525 | W9: =IF($A9<VARIABLES!$B$50,0,(IF($A9<VARIABLES!$B$50+1,0,X8)+U9)*C9*VARIABLES!$B$56) -> 869.01328 | X9: =IF($A9<VARIABLES!$B$50,0,(IF($A9<VARIABLES!$B$50+1,0,X8)+U9)*(1+C9)-W9) -> 268525.1 | Y9: =D9+H9+L9+P9+U9 -> 330000 | Z9: =E9+I9+M9+Q9+V9 -> 2475 | AA9: =F9+J9+N9+R9+W9 -> 21802.518 | AB9: =Z9+AA9 -> 24277.518 | AC9: =G9+K9+O9+S9+X9 -> 8101417.8 | AD9: =IF($A9=1,VARIABLES!$B$12,0) -> 0 | AE9: =IF($A9<=3,VARIABLES!$B$13,IF($A9<=6,VARIABLES!$B$14,VARIABLES!$B$15)) -> 34500 | AF9: =IF(MOD($A9,12)=0,AC9*VARIABLES!$B$16,0) -> 0 | AG9: =VARIABLES!$B$17 -> 5000 | AH9: =IF(MOD($A9,12)=0,VARIABLES!$B$18,0) -> 0 | AI9: =AD9+AE9+AF9+AG9+AH9 -> 39500 | AJ9: =IF($A9<VARIABLES!$B$7,VARIABLES!$B$9,0) -> 10580.083 | AK9: =AB9-AI9-AJ9 -> -25802.566 | AL9: =IF(AJ9>0,AL8+AK9,AL8) -> -172395.48 | AM9: =IF(AJ9>0,AM8+AJ9,AM8+AK9) -> 63480.5
A10: 7 | B10: =TEXT(DATE(VARIABLES!$B$60+INT((VARIABLES!$B$61+A10-2)/12),MOD(VARIABLES!$B$61+A10-2,12)+1,1),"mmm-yy") -> Dec-26 | C10: =IF($A10<VARIABLES!$B$7,VARIABLES!$B$5/12,VARIABLES!$B$6/12) -> 0.033333333 | D10: =IF($A10<VARIABLES!$B$21,0,IF($A10=VARIABLES!$B$21,VARIABLES!$B$22+VARIABLES!$B$23,VARIABLES!$B$23)) -> 200000 | E10: =D10*VARIABLES!$B$24 -> 1500 | F10: =IF($A10<VARIABLES!$B$21,0,(IF($A10=VARIABLES!$B$21,0,G9)+D10)*C10*VARIABLES!$B$25) -> 1589.6691 | G10: =IF($A10<VARIABLES!$B$21,0,(IF($A10=VARIABLES!$B$21,0,G9)+D10)*(1+C10)-F10) -> 1969600.1 | H10: =IF($A10<VARIABLES!$B$28,0,IF($A10=VARIABLES!$B$28,VARIABLES!$B$29+VARIABLES!$B$30,VARIABLES!$B$30)) -> 40000 | I10: =H10*VARIABLES!$B$31 -> 300 | J10: =IF($A10<VARIABLES!$B$28,0,(IF($A10=VARIABLES!$B$28,0,K9)+H10)*C10*VARIABLES!$B$32) -> 862.45465 | K10: =IF($A10<VARIABLES!$B$28,0,(IF($A10=VARIABLES!$B$28,0,K9)+H10)*(1+C10)-J10) -> 266498.49 | L10: =IF($A10<VARIABLES!$B$35,0,IF($A10=VARIABLES!$B$35,VARIABLES!$B$36+VARIABLES!$B$37,VARIABLES!$B$37)) -> 0 | M10: =L10*VARIABLES!$B$38 -> 0 | N10: =IF($A10<VARIABLES!$B$35,0,(IF($A10=VARIABLES!$B$35,0,O9)+L10)*C10*VARIABLES!$B$39) -> 19321.235 | O10: =IF($A10<VARIABLES!$B$35,0,(IF($A10=VARIABLES!$B$35,0,O9)+L10)*(1+C10)-N10) -> 5970261.5 | P10: =IF($A10<VARIABLES!$B$42,0,IF($A10=VARIABLES!$B$42,VARIABLES!$B$43+VARIABLES!$B$44,VARIABLES!$B$44)) -> 20000 | Q10: =P10*VARIABLES!$B$45 -> 150 | R10: =IF($A10<VARIABLES!$B$42,0,(IF($A10=VARIABLES!$B$42,0,S9)+P10)*C10*VARIABLES!$B$46) -> 108.48578 | S10: =IF($A10<VARIABLES!$B$42,0,(IF($A10=VARIABLES!$B$42,0,S9)+P10)*(1+C10)-R10) -> 134413.88 | T10: =IF($A10<VARIABLES!$B$50,0,MIN(VARIABLES!$B$49,INT(($A10-VARIABLES!$B$50)/VARIABLES!$B$51)+1)*VARIABLES!$B$52) -> 5 | U10: =T10*VARIABLES!$B$54+IF(AND($A10>=VARIABLES!$B$50,MOD($A10-VARIABLES!$B$50,VARIABLES!$B$51)=0,INT(($A10-VARIABLES!$B$50)/VARIABLES!$B$51)<VARIABLES!$B$49),VARIABLES!$B$52*VARIABLES!$B$53,0) -> 75000 | V10: =U10*VARIABLES!$B$55 -> 562.5 | W10: =IF($A10<VARIABLES!$B$50,0,(IF($A10<VARIABLES!$B$50+1,0,X9)+U10)*C10*VARIABLES!$B$56) -> 1145.0837 | X10: =IF($A10<VARIABLES!$B$50,0,(IF($A10<VARIABLES!$B$50+1,0,X9)+U10)*(1+C10)-W10) -> 353830.86 | Y10: =D10+H10+L10+P10+U10 -> 335000 | Z10: =E10+I10+M10+Q10+V10 -> 2512.5 | AA10: =F10+J10+N10+R10+W10 -> 23026.928 | AB10: =Z10+AA10 -> 25539.428 | AC10: =G10+K10+O10+S10+X10 -> 8694604.8 | AD10: =IF($A10=1,VARIABLES!$B$12,0) -> 0 | AE10: =IF($A10<=3,VARIABLES!$B$13,IF($A10<=6,VARIABLES!$B$14,VARIABLES!$B$15)) -> 46000 | AF10: =IF(MOD($A10,12)=0,AC10*VARIABLES!$B$16,0) -> 0 | AG10: =VARIABLES!$B$17 -> 5000 | AH10: =IF(MOD($A10,12)=0,VARIABLES!$B$18,0) -> 0 | AI10: =AD10+AE10+AF10+AG10+AH10 -> 51000 | AJ10: =IF($A10<VARIABLES!$B$7,VARIABLES!$B$9,0) -> 10580.083 | AK10: =AB10-AI10-AJ10 -> -36040.656 | AL10: =IF(AJ10>0,AL9+AK10,AL9) -> -208436.14 | AM10: =IF(AJ10>0,AM9+AJ10,AM9+AK10) -> 74060.583
A11: 8 | B11: =TEXT(DATE(VARIABLES!$B$60+INT((VARIABLES!$B$61+A11-2)/12),MOD(VARIABLES!$B$61+A11-2,12)+1,1),"mmm-yy") -> Jan-27 | C11: =IF($A11<VARIABLES!$B$7,VARIABLES!$B$5/12,VARIABLES!$B$6/12) -> 0.033333333 | D11: =IF($A11<VARIABLES!$B$21,0,IF($A11=VARIABLES!$B$21,VARIABLES!$B$22+VARIABLES!$B$23,VARIABLES!$B$23)) -> 200000 | E11: =D11*VARIABLES!$B$24 -> 1500 | F11: =IF($A11<VARIABLES!$B$21,0,(IF($A11=VARIABLES!$B$21,0,G10)+D11)*C11*VARIABLES!$B$25) -> 1808 | G11: =IF($A11<VARIABLES!$B$21,0,(IF($A11=VARIABLES!$B$21,0,G10)+D11)*(1+C11)-F11) -> 2240112.1 | H11: =IF($A11<VARIABLES!$B$28,0,IF($A11=VARIABLES!$B$28,VARIABLES!$B$29+VARIABLES!$B$30,VARIABLES!$B$30)) -> 40000 | I11: =H11*VARIABLES!$B$31 -> 300 | J11: =IF($A11<VARIABLES!$B$28,0,(IF($A11=VARIABLES!$B$28,0,K10)+H11)*C11*VARIABLES!$B$32) -> 1021.6616 | K11: =IF($A11<VARIABLES!$B$28,0,(IF($A11=VARIABLES!$B$28,0,K10)+H11)*(1+C11)-J11) -> 315693.44 | L11: =IF($A11<VARIABLES!$B$35,0,IF($A11=VARIABLES!$B$35,VARIABLES!$B$36+VARIABLES!$B$37,VARIABLES!$B$37)) -> 0 | M11: =L11*VARIABLES!$B$38 -> 0 | N11: =IF($A11<VARIABLES!$B$35,0,(IF($A11=VARIABLES!$B$35,0,O10)+L11)*C11*VARIABLES!$B$39) -> 19900.872 | O11: =IF($A11<VARIABLES!$B$35,0,(IF($A11=VARIABLES!$B$35,0,O10)+L11)*(1+C11)-N11) -> 6149369.3 | P11: =IF($A11<VARIABLES!$B$42,0,IF($A11=VARIABLES!$B$42,VARIABLES!$B$43+VARIABLES!$B$44,VARIABLES!$B$44)) -> 20000 | Q11: =P11*VARIABLES!$B$45 -> 150 | R11: =IF($A11<VARIABLES!$B$42,0,(IF($A11=VARIABLES!$B$42,0,S10)+P11)*C11*VARIABLES!$B$46) -> 128.67823 | S11: =IF($A11<VARIABLES!$B$42,0,(IF($A11=VARIABLES!$B$42,0,S10)+P11)*(1+C11)-R11) -> 159432.33 | T11: =IF($A11<VARIABLES!$B$50,0,MIN(VARIABLES!$B$49,INT(($A11-VARIABLES!$B$50)/VARIABLES!$B$51)+1)*VARIABLES!$B$52) -> 6 | U11: =T11*VARIABLES!$B$54+IF(AND($A11>=VARIABLES!$B$50,MOD($A11-VARIABLES!$B$50,VARIABLES!$B$51)=0,INT(($A11-VARIABLES!$B$50)/VARIABLES!$B$51)<VARIABLES!$B$49),VARIABLES!$B$52*VARIABLES!$B$53,0) -> 80000 | V11: =U11*VARIABLES!$B$55 -> 600 | W11: =IF($A11<VARIABLES!$B$50,0,(IF($A11<VARIABLES!$B$50+1,0,X10)+U11)*C11*VARIABLES!$B$56) -> 1446.1029 | X11: =IF($A11<VARIABLES!$B$50,0,(IF($A11<VARIABLES!$B$50+1,0,X10)+U11)*(1+C11)-W11) -> 446845.78 | Y11: =D11+H11+L11+P11+U11 -> 340000 | Z11: =E11+I11+M11+Q11+V11 -> 2550 | AA11: =F11+J11+N11+R11+W11 -> 24305.314 | AB11: =Z11+AA11 -> 26855.314 | AC11: =G11+K11+O11+S11+X11 -> 9311452.9 | AD11: =IF($A11=1,VARIABLES!$B$12,0) -> 0 | AE11: =IF($A11<=3,VARIABLES!$B$13,IF($A11<=6,VARIABLES!$B$14,VARIABLES!$B$15)) -> 46000 | AF11: =IF(MOD($A11,12)=0,AC11*VARIABLES!$B$16,0) -> 0 | AG11: =VARIABLES!$B$17 -> 5000 | AH11: =IF(MOD($A11,12)=0,VARIABLES!$B$18,0) -> 0 | AI11: =AD11+AE11+AF11+AG11+AH11 -> 51000 | AJ11: =IF($A11<VARIABLES!$B$7,VARIABLES!$B$9,0) -> 10580.083 | AK11: =AB11-AI11-AJ11 -> -34724.769 | AL11: =IF(AJ11>0,AL10+AK11,AL10) -> -243160.91 | AM11: =IF(AJ11>0,AM10+AJ11,AM10+AK11) -> 84640.667
A12: 9 | B12: =TEXT(DATE(VARIABLES!$B$60+INT((VARIABLES!$B$61+A12-2)/12),MOD(VARIABLES!$B$61+A12-2,12)+1,1),"mmm-yy") -> Feb-27 | C12: =IF($A12<VARIABLES!$B$7,VARIABLES!$B$5/12,VARIABLES!$B$6/12) -> 0.033333333 | D12: =IF($A12<VARIABLES!$B$21,0,IF($A12=VARIABLES!$B$21,VARIABLES!$B$22+VARIABLES!$B$23,VARIABLES!$B$23)) -> 200000 | E12: =D12*VARIABLES!$B$24 -> 1500 | F12: =IF($A12<VARIABLES!$B$21,0,(IF($A12=VARIABLES!$B$21,0,G11)+D12)*C12*VARIABLES!$B$25) -> 2033.4267 | G12: =IF($A12<VARIABLES!$B$21,0,(IF($A12=VARIABLES!$B$21,0,G11)+D12)*(1+C12)-F12) -> 2519415.7 | H12: =IF($A12<VARIABLES!$B$28,0,IF($A12=VARIABLES!$B$28,VARIABLES!$B$29+VARIABLES!$B$30,VARIABLES!$B$30)) -> 40000 | I12: =H12*VARIABLES!$B$31 -> 300 | J12: =IF($A12<VARIABLES!$B$28,0,(IF($A12=VARIABLES!$B$28,0,K11)+H12)*C12*VARIABLES!$B$32) -> 1185.6448 | K12: =IF($A12<VARIABLES!$B$28,0,(IF($A12=VARIABLES!$B$28,0,K11)+H12)*(1+C12)-J12) -> 366364.25 | L12: =IF($A12<VARIABLES!$B$35,0,IF($A12=VARIABLES!$B$35,VARIABLES!$B$36+VARIABLES!$B$37,VARIABLES!$B$37)) -> 0 | M12: =L12*VARIABLES!$B$38 -> 0 | N12: =IF($A12<VARIABLES!$B$35,0,(IF($A12=VARIABLES!$B$35,0,O11)+L12)*C12*VARIABLES!$B$39) -> 20497.898 | O12: =IF($A12<VARIABLES!$B$35,0,(IF($A12=VARIABLES!$B$35,0,O11)+L12)*(1+C12)-N12) -> 6333850.4 | P12: =IF($A12<VARIABLES!$B$42,0,IF($A12=VARIABLES!$B$42,VARIABLES!$B$43+VARIABLES!$B$44,VARIABLES!$B$44)) -> 20000 | Q12: =P12*VARIABLES!$B$45 -> 150 | R12: =IF($A12<VARIABLES!$B$42,0,(IF($A12=VARIABLES!$B$42,0,S11)+P12)*C12*VARIABLES!$B$46) -> 149.52694 | S12: =IF($A12<VARIABLES!$B$42,0,(IF($A12=VARIABLES!$B$42,0,S11)+P12)*(1+C12)-R12) -> 185263.88 | T12: =IF($A12<VARIABLES!$B$50,0,MIN(VARIABLES!$B$49,INT(($A12-VARIABLES!$B$50)/VARIABLES!$B$51)+1)*VARIABLES!$B$52) -> 7 | U12: =T12*VARIABLES!$B$54+IF(AND($A12>=VARIABLES!$B$50,MOD($A12-VARIABLES!$B$50,VARIABLES!$B$51)=0,INT(($A12-VARIABLES!$B$50)/VARIABLES!$B$51)<VARIABLES!$B$49),VARIABLES!$B$52*VARIABLES!$B$53,0) -> 85000 | V12: =U12*VARIABLES!$B$55 -> 637.5 | W12: =IF($A12<VARIABLES!$B$50,0,(IF($A12<VARIABLES!$B$50+1,0,X11)+U12)*C12*VARIABLES!$B$56) -> 1772.8193 | X12: =IF($A12<VARIABLES!$B$50,0,(IF($A12<VARIABLES!$B$50+1,0,X11)+U12)*(1+C12)-W12) -> 547801.16 | Y12: =D12+H12+L12+P12+U12 -> 345000 | Z12: =E12+I12+M12+Q12+V12 -> 2587.5 | AA12: =F12+J12+N12+R12+W12 -> 25639.316 | AB12: =Z12+AA12 -> 28226.816 | AC12: =G12+K12+O12+S12+X12 -> 9952695.4 | AD12: =IF($A12=1,VARIABLES!$B$12,0) -> 0 | AE12: =IF($A12<=3,VARIABLES!$B$13,IF($A12<=6,VARIABLES!$B$14,VARIABLES!$B$15)) -> 46000 | AF12: =IF(MOD($A12,12)=0,AC12*VARIABLES!$B$16,0) -> 0 | AG12: =VARIABLES!$B$17 -> 5000 | AH12: =IF(MOD($A12,12)=0,VARIABLES!$B$18,0) -> 0 | AI12: =AD12+AE12+AF12+AG12+AH12 -> 51000 | AJ12: =IF($A12<VARIABLES!$B$7,VARIABLES!$B$9,0) -> 10580.083 | AK12: =AB12-AI12-AJ12 -> -33353.268 | AL12: =IF(AJ12>0,AL11+AK12,AL11) -> -276514.18 | AM12: =IF(AJ12>0,AM11+AJ12,AM11+AK12) -> 95220.75
A13: 10 | B13: =TEXT(DATE(VARIABLES!$B$60+INT((VARIABLES!$B$61+A13-2)/12),MOD(VARIABLES!$B$61+A13-2,12)+1,1),"mmm-yy") -> Mar-27 | C13: =IF($A13<VARIABLES!$B$7,VARIABLES!$B$5/12,VARIABLES!$B$6/12) -> 0.033333333 | D13: =IF($A13<VARIABLES!$B$21,0,IF($A13=VARIABLES!$B$21,VARIABLES!$B$22+VARIABLES!$B$23,VARIABLES!$B$23)) -> 200000 | E13: =D13*VARIABLES!$B$24 -> 1500 | F13: =IF($A13<VARIABLES!$B$21,0,(IF($A13=VARIABLES!$B$21,0,G12)+D13)*C13*VARIABLES!$B$25) -> 2266.1798 | G13: =IF($A13<VARIABLES!$B$21,0,(IF($A13=VARIABLES!$B$21,0,G12)+D13)*(1+C13)-F13) -> 2807796.7 | H13: =IF($A13<VARIABLES!$B$28,0,IF($A13=VARIABLES!$B$28,VARIABLES!$B$29+VARIABLES!$B$30,VARIABLES!$B$30)) -> 40000 | I13: =H13*VARIABLES!$B$31 -> 300 | J13: =IF($A13<VARIABLES!$B$28,0,(IF($A13=VARIABLES!$B$28,0,K12)+H13)*C13*VARIABLES!$B$32) -> 1354.5475 | K13: =IF($A13<VARIABLES!$B$28,0,(IF($A13=VARIABLES!$B$28,0,K12)+H13)*(1+C13)-J13) -> 418555.17 | L13: =IF($A13<VARIABLES!$B$35,0,IF($A13=VARIABLES!$B$35,VARIABLES!$B$36+VARIABLES!$B$37,VARIABLES!$B$37)) -> 0 | M13: =L13*VARIABLES!$B$38 -> 0 | N13: =IF($A13<VARIABLES!$B$35,0,(IF($A13=VARIABLES!$B$35,0,O12)+L13)*C13*VARIABLES!$B$39) -> 21112.835 | O13: =IF($A13<VARIABLES!$B$35,0,(IF($A13=VARIABLES!$B$35,0,O12)+L13)*(1+C13)-N13) -> 6523865.9 | P13: =IF($A13<VARIABLES!$B$42,0,IF($A13=VARIABLES!$B$42,VARIABLES!$B$43+VARIABLES!$B$44,VARIABLES!$B$44)) -> 20000 | Q13: =P13*VARIABLES!$B$45 -> 150 | R13: =IF($A13<VARIABLES!$B$42,0,(IF($A13=VARIABLES!$B$42,0,S12)+P13)*C13*VARIABLES!$B$46) -> 171.05323 | S13: =IF($A13<VARIABLES!$B$42,0,(IF($A13=VARIABLES!$B$42,0,S12)+P13)*(1+C13)-R13) -> 211934.96 | T13: =IF($A13<VARIABLES!$B$50,0,MIN(VARIABLES!$B$49,INT(($A13-VARIABLES!$B$50)/VARIABLES!$B$51)+1)*VARIABLES!$B$52) -> 8 | U13: =T13*VARIABLES!$B$54+IF(AND($A13>=VARIABLES!$B$50,MOD($A13-VARIABLES!$B$50,VARIABLES!$B$51)=0,INT(($A13-VARIABLES!$B$50)/VARIABLES!$B$51)<VARIABLES!$B$49),VARIABLES!$B$52*VARIABLES!$B$53,0) -> 90000 | V13: =U13*VARIABLES!$B$55 -> 675 | W13: =IF($A13<VARIABLES!$B$50,0,(IF($A13<VARIABLES!$B$50+1,0,X12)+U13)*C13*VARIABLES!$B$56) -> 2126.0039 | X13: =IF($A13<VARIABLES!$B$50,0,(IF($A13<VARIABLES!$B$50+1,0,X12)+U13)*(1+C13)-W13) -> 656935.19 | Y13: =D13+H13+L13+P13+U13 -> 350000 | Z13: =E13+I13+M13+Q13+V13 -> 2625 | AA13: =F13+J13+N13+R13+W13 -> 27030.619 | AB13: =Z13+AA13 -> 29655.619 | AC13: =G13+K13+O13+S13+X13 -> 10619088 | AD13: =IF($A13=1,VARIABLES!$B$12,0) -> 0 | AE13: =IF($A13<=3,VARIABLES!$B$13,IF($A13<=6,VARIABLES!$B$14,VARIABLES!$B$15)) -> 46000 | AF13: =IF(MOD($A13,12)=0,AC13*VARIABLES!$B$16,0) -> 0 | AG13: =VARIABLES!$B$17 -> 5000 | AH13: =IF(MOD($A13,12)=0,VARIABLES!$B$18,0) -> 0 | AI13: =AD13+AE13+AF13+AG13+AH13 -> 51000 | AJ13: =IF($A13<VARIABLES!$B$7,VARIABLES!$B$9,0) -> 10580.083 | AK13: =AB13-AI13-AJ13 -> -31924.464 | AL13: =IF(AJ13>0,AL12+AK13,AL12) -> -308438.64 | AM13: =IF(AJ13>0,AM12+AJ13,AM12+AK13) -> 105800.83
A14: 11 | B14: =TEXT(DATE(VARIABLES!$B$60+INT((VARIABLES!$B$61+A14-2)/12),MOD(VARIABLES!$B$61+A14-2,12)+1,1),"mmm-yy") -> Apr-27 | C14: =IF($A14<VARIABLES!$B$7,VARIABLES!$B$5/12,VARIABLES!$B$6/12) -> 0.033333333 | D14: =IF($A14<VARIABLES!$B$21,0,IF($A14=VARIABLES!$B$21,VARIABLES!$B$22+VARIABLES!$B$23,VARIABLES!$B$23)) -> 200000 | E14: =D14*VARIABLES!$B$24 -> 1500 | F14: =IF($A14<VARIABLES!$B$21,0,(IF($A14=VARIABLES!$B$21,0,G13)+D14)*C14*VARIABLES!$B$25) -> 2506.4973 | G14: =IF($A14<VARIABLES!$B$21,0,(IF($A14=VARIABLES!$B$21,0,G13)+D14)*(1+C14)-F14) -> 3105550.1 | H14: =IF($A14<VARIABLES!$B$28,0,IF($A14=VARIABLES!$B$28,VARIABLES!$B$29+VARIABLES!$B$30,VARIABLES!$B$30)) -> 40000 | I14: =H14*VARIABLES!$B$31 -> 300 | J14: =IF($A14<VARIABLES!$B$28,0,(IF($A14=VARIABLES!$B$28,0,K13)+H14)*C14*VARIABLES!$B$32) -> 1528.5172 | K14: =IF($A14<VARIABLES!$B$28,0,(IF($A14=VARIABLES!$B$28,0,K13)+H14)*(1+C14)-J14) -> 472311.83 | L14: =IF($A14<VARIABLES!$B$35,0,IF($A14=VARIABLES!$B$35,VARIABLES!$B$36+VARIABLES!$B$37,VARIABLES!$B$37)) -> 0 | M14: =L14*VARIABLES!$B$38 -> 0 | N14: =IF($A14<VARIABLES!$B$35,0,(IF($A14=VARIABLES!$B$35,0,O13)+L14)*C14*VARIABLES!$B$39) -> 21746.22 | O14: =IF($A14<VARIABLES!$B$35,0,(IF($A14=VARIABLES!$B$35,0,O13)+L14)*(1+C14)-N14) -> 6719581.9 | P14: =IF($A14<VARIABLES!$B$42,0,IF($A14=VARIABLES!$B$42,VARIABLES!$B$43+VARIABLES!$B$44,VARIABLES!$B$44)) -> 20000 | Q14: =P14*VARIABLES!$B$45 -> 150 | R14: =IF($A14<VARIABLES!$B$42,0,(IF($A14=VARIABLES!$B$42,0,S13)+P14)*C14*VARIABLES!$B$46) -> 193.27913 | S14: =IF($A14<VARIABLES!$B$42,0,(IF($A14=VARIABLES!$B$42,0,S13)+P14)*(1+C14)-R14) -> 239472.84 | T14: =IF($A14<VARIABLES!$B$50,0,MIN(VARIABLES!$B$49,INT(($A14-VARIABLES!$B$50)/VARIABLES!$B$51)+1)*VARIABLES!$B$52) -> 9 | U14: =T14*VARIABLES!$B$54+IF(AND($A14>=VARIABLES!$B$50,MOD($A14-VARIABLES!$B$50,VARIABLES!$B$51)=0,INT(($A14-VARIABLES!$B$50)/VARIABLES!$B$51)<VARIABLES!$B$49),VARIABLES!$B$52*VARIABLES!$B$53,0) -> 95000 | V14: =U14*VARIABLES!$B$55 -> 712.5 | W14: =IF($A14<VARIABLES!$B$50,0,(IF($A14<VARIABLES!$B$50+1,0,X13)+U14)*C14*VARIABLES!$B$56) -> 2506.4506 | X14: =IF($A14<VARIABLES!$B$50,0,(IF($A14<VARIABLES!$B$50+1,0,X13)+U14)*(1+C14)-W14) -> 774493.25 | Y14: =D14+H14+L14+P14+U14 -> 355000 | Z14: =E14+I14+M14+Q14+V14 -> 2662.5 | AA14: =F14+J14+N14+R14+W14 -> 28480.964 | AB14: =Z14+AA14 -> 31143.464 | AC14: =G14+K14+O14+S14+X14 -> 11311410 | AD14: =IF($A14=1,VARIABLES!$B$12,0) -> 0 | AE14: =IF($A14<=3,VARIABLES!$B$13,IF($A14<=6,VARIABLES!$B$14,VARIABLES!$B$15)) -> 46000 | AF14: =IF(MOD($A14,12)=0,AC14*VARIABLES!$B$16,0) -> 0 | AG14: =VARIABLES!$B$17 -> 5000 | AH14: =IF(MOD($A14,12)=0,VARIABLES!$B$18,0) -> 0 | AI14: =AD14+AE14+AF14+AG14+AH14 -> 51000 | AJ14: =IF($A14<VARIABLES!$B$7,VARIABLES!$B$9,0) -> 10580.083 | AK14: =AB14-AI14-AJ14 -> -30436.619 | AL14: =IF(AJ14>0,AL13+AK14,AL13) -> -338875.26 | AM14: =IF(AJ14>0,AM13+AJ14,AM13+AK14) -> 116380.92
A15: 12 | B15: =TEXT(DATE(VARIABLES!$B$60+INT((VARIABLES!$B$61+A15-2)/12),MOD(VARIABLES!$B$61+A15-2,12)+1,1),"mmm-yy") -> May-27 | C15: =IF($A15<VARIABLES!$B$7,VARIABLES!$B$5/12,VARIABLES!$B$6/12) -> 0.033333333 | D15: =IF($A15<VARIABLES!$B$21,0,IF($A15=VARIABLES!$B$21,VARIABLES!$B$22+VARIABLES!$B$23,VARIABLES!$B$23)) -> 200000 | E15: =D15*VARIABLES!$B$24 -> 1500 | F15: =IF($A15<VARIABLES!$B$21,0,(IF($A15=VARIABLES!$B$21,0,G14)+D15)*C15*VARIABLES!$B$25) -> 2754.6251 | G15: =IF($A15<VARIABLES!$B$21,0,(IF($A15=VARIABLES!$B$21,0,G14)+D15)*(1+C15)-F15) -> 3412980.5 | H15: =IF($A15<VARIABLES!$B$28,0,IF($A15=VARIABLES!$B$28,VARIABLES!$B$29+VARIABLES!$B$30,VARIABLES!$B$30)) -> 40000 | I15: =H15*VARIABLES!$B$31 -> 300 | J15: =IF($A15<VARIABLES!$B$28,0,(IF($A15=VARIABLES!$B$28,0,K14)+H15)*C15*VARIABLES!$B$32) -> 1707.7061 | K15: =IF($A15<VARIABLES!$B$28,0,(IF($A15=VARIABLES!$B$28,0,K14)+H15)*(1+C15)-J15) -> 527681.18 | L15: =IF($A15<VARIABLES!$B$35,0,IF($A15=VARIABLES!$B$35,VARIABLES!$B$36+VARIABLES!$B$37,VARIABLES!$B$37)) -> 0 | M15: =L15*VARIABLES!$B$38 -> 0 | N15: =IF($A15<VARIABLES!$B$35,0,(IF($A15=VARIABLES!$B$35,0,O14)+L15)*C15*VARIABLES!$B$39) -> 22398.606 | O15: =IF($A15<VARIABLES!$B$35,0,(IF($A15=VARIABLES!$B$35,0,O14)+L15)*(1+C15)-N15) -> 6921169.4 | P15: =IF($A15<VARIABLES!$B$42,0,IF($A15=VARIABLES!$B$42,VARIABLES!$B$43+VARIABLES!$B$44,VARIABLES!$B$44)) -> 20000 | Q15: =P15*VARIABLES!$B$45 -> 150 | R15: =IF($A15<VARIABLES!$B$42,0,(IF($A15=VARIABLES!$B$42,0,S14)+P15)*C15*VARIABLES!$B$46) -> 216.22737 | S15: =IF($A15<VARIABLES!$B$42,0,(IF($A15=VARIABLES!$B$42,0,S14)+P15)*(1+C15)-R15) -> 267905.71 | T15: =IF($A15<VARIABLES!$B$50,0,MIN(VARIABLES!$B$49,INT(($A15-VARIABLES!$B$50)/VARIABLES!$B$51)+1)*VARIABLES!$B$52) -> 10 | U15: =T15*VARIABLES!$B$54+IF(AND($A15>=VARIABLES!$B$50,MOD($A15-VARIABLES!$B$50,VARIABLES!$B$51)=0,INT(($A15-VARIABLES!$B$50)/VARIABLES!$B$51)<VARIABLES!$B$49),VARIABLES!$B$52*VARIABLES!$B$53,0) -> 100000 | V15: =U15*VARIABLES!$B$55 -> 750 | W15: =IF($A15<VARIABLES!$B$50,0,(IF($A15<VARIABLES!$B$50+1,0,X14)+U15)*C15*VARIABLES!$B$56) -> 2914.9775 | X15: =IF($A15<VARIABLES!$B$50,0,(IF($A15<VARIABLES!$B$50+1,0,X14)+U15)*(1+C15)-W15) -> 900728.04 | Y15: =D15+H15+L15+P15+U15 -> 360000 | Z15: =E15+I15+M15+Q15+V15 -> 2700 | AA15: =F15+J15+N15+R15+W15 -> 29992.142 | AB15: =Z15+AA15 -> 32692.142 | AC15: =G15+K15+O15+S15+X15 -> 12030465 | AD15: =IF($A15=1,VARIABLES!$B$12,0) -> 0 | AE15: =IF($A15<=3,VARIABLES!$B$13,IF($A15<=6,VARIABLES!$B$14,VARIABLES!$B$15)) -> 46000 | AF15: =IF(MOD($A15,12)=0,AC15*VARIABLES!$B$16,0) -> 30076.162 | AG15: =VARIABLES!$B$17 -> 5000 | AH15: =IF(MOD($A15,12)=0,VARIABLES!$B$18,0) -> 3000 | AI15: =AD15+AE15+AF15+AG15+AH15 -> 84076.162 | AJ15: =IF($A15<VARIABLES!$B$7,VARIABLES!$B$9,0) -> 10580.083 | AK15: =AB15-AI15-AJ15 -> -61964.103 | AL15: =IF(AJ15>0,AL14+AK15,AL14) -> -400839.36 | AM15: =IF(AJ15>0,AM14+AJ15,AM14+AK15) -> 126961
A16: 13 | B16: =TEXT(DATE(VARIABLES!$B$60+INT((VARIABLES!$B$61+A16-2)/12),MOD(VARIABLES!$B$61+A16-2,12)+1,1),"mmm-yy") -> Jun-27 | C16: =IF($A16<VARIABLES!$B$7,VARIABLES!$B$5/12,VARIABLES!$B$6/12) -> 0.033333333 | D16: =IF($A16<VARIABLES!$B$21,0,IF($A16=VARIABLES!$B$21,VARIABLES!$B$22+VARIABLES!$B$23,VARIABLES!$B$23)) -> 200000 | E16: =D16*VARIABLES!$B$24 -> 1500 | F16: =IF($A16<VARIABLES!$B$21,0,(IF($A16=VARIABLES!$B$21,0,G15)+D16)*C16*VARIABLES!$B$25) -> 3010.8171 | G16: =IF($A16<VARIABLES!$B$21,0,(IF($A16=VARIABLES!$B$21,0,G15)+D16)*(1+C16)-F16) -> 3730402.4 | H16: =IF($A16<VARIABLES!$B$28,0,IF($A16=VARIABLES!$B$28,VARIABLES!$B$29+VARIABLES!$B$30,VARIABLES!$B$30)) -> 40000 | I16: =H16*VARIABLES!$B$31 -> 300 | J16: =IF($A16<VARIABLES!$B$28,0,(IF($A16=VARIABLES!$B$28,0,K15)+H16)*C16*VARIABLES!$B$32) -> 1892.2706 | K16: =IF($A16<VARIABLES!$B$28,0,(IF($A16=VARIABLES!$B$28,0,K15)+H16)*(1+C16)-J16) -> 584711.62 | L16: =IF($A16<VARIABLES!$B$35,0,IF($A16=VARIABLES!$B$35,VARIABLES!$B$36+VARIABLES!$B$37,VARIABLES!$B$37)) -> 0 | M16: =L16*VARIABLES!$B$38 -> 0 | N16: =IF($A16<VARIABLES!$B$35,0,(IF($A16=VARIABLES!$B$35,0,O15)+L16)*C16*VARIABLES!$B$39) -> 23070.565 | O16: =IF($A16<VARIABLES!$B$35,0,(IF($A16=VARIABLES!$B$35,0,O15)+L16)*(1+C16)-N16) -> 7128804.4 | P16: =IF($A16<VARIABLES!$B$42,0,IF($A16=VARIABLES!$B$42,VARIABLES!$B$43+VARIABLES!$B$44,VARIABLES!$B$44)) -> 20000 | Q16: =P16*VARIABLES!$B$45 -> 150 | R16: =IF($A16<VARIABLES!$B$42,0,(IF($A16=VARIABLES!$B$42,0,S15)+P16)*C16*VARIABLES!$B$46) -> 239.92142 | S16: =IF($A16<VARIABLES!$B$42,0,(IF($A16=VARIABLES!$B$42,0,S15)+P16)*(1+C16)-R16) -> 297262.65 | T16: =IF($A16<VARIABLES!$B$50,0,MIN(VARIABLES!$B$49,INT(($A16-VARIABLES!$B$50)/VARIABLES!$B$51)+1)*VARIABLES!$B$52) -> 11 | U16: =T16*VARIABLES!$B$54+IF(AND($A16>=VARIABLES!$B$50,MOD($A16-VARIABLES!$B$50,VARIABLES!$B$51)=0,INT(($A16-VARIABLES!$B$50)/VARIABLES!$B$51)<VARIABLES!$B$49),VARIABLES!$B$52*VARIABLES!$B$53,0) -> 105000 | V16: =U16*VARIABLES!$B$55 -> 787.5 | W16: =IF($A16<VARIABLES!$B$50,0,(IF($A16<VARIABLES!$B$50+1,0,X15)+U16)*C16*VARIABLES!$B$56) -> 3352.4268 | X16: =IF($A16<VARIABLES!$B$50,0,(IF($A16<VARIABLES!$B$50+1,0,X15)+U16)*(1+C16)-W16) -> 1035899.9 | Y16: =D16+H16+L16+P16+U16 -> 365000 | Z16: =E16+I16+M16+Q16+V16 -> 2737.5 | AA16: =F16+J16+N16+R16+W16 -> 31566 | AB16: =Z16+AA16 -> 34303.5 | AC16: =G16+K16+O16+S16+X16 -> 12777081 | AD16: =IF($A16=1,VARIABLES!$B$12,0) -> 0 | AE16: =IF($A16<=3,VARIABLES!$B$13,IF($A16<=6,VARIABLES!$B$14,VARIABLES!$B$15)) -> 46000 | AF16: =IF(MOD($A16,12)=0,AC16*VARIABLES!$B$16,0) -> 0 | AG16: =VARIABLES!$B$17 -> 5000 | AH16: =IF(MOD($A16,12)=0,VARIABLES!$B$18,0) -> 0 | AI16: =AD16+AE16+AF16+AG16+AH16 -> 51000 | AJ16: =IF($A16<VARIABLES!$B$7,VARIABLES!$B$9,0) -> 10580.083 | AK16: =AB16-AI16-AJ16 -> -27276.583 | AL16: =IF(AJ16>0,AL15+AK16,AL15) -> -428115.94 | AM16: =IF(AJ16>0,AM15+AJ16,AM15+AK16) -> 137541.08
... A51: 48 | B51: =TEXT(DATE(VARIABLES!$B$60+INT((VARIABLES!$B$61+A51-2)/12),MOD(VARIABLES!$B$61+A51-2,12)+1,1),"mmm-yy") -> May-30 | C51: =IF($A51<VARIABLES!$B$7,VARIABLES!$B$5/12,VARIABLES!$B$6/12) -> 0.0083333333 | D51: =IF($A51<VARIABLES!$B$21,0,IF($A51=VARIABLES!$B$21,VARIABLES!$B$22+VARIABLES!$B$23,VARIABLES!$B$23)) -> 200000 | E51: =D51*VARIABLES!$B$24 -> 1500 | F51: =IF($A51<VARIABLES!$B$21,0,(IF($A51=VARIABLES!$B$21,0,G50)+D51)*C51*VARIABLES!$B$25) -> 3868.1763 | G51: =IF($A51<VARIABLES!$B$21,0,(IF($A51=VARIABLES!$B$21,0,G50)+D51)*(1+C51)-F51) -> 18718105 | H51: =IF($A51<VARIABLES!$B$28,0,IF($A51=VARIABLES!$B$28,VARIABLES!$B$29+VARIABLES!$B$30,VARIABLES!$B$30)) -> 40000 | I51: =H51*VARIABLES!$B$31 -> 300 | J51: =IF($A51<VARIABLES!$B$28,0,(IF($A51=VARIABLES!$B$28,0,K50)+H51)*C51*VARIABLES!$B$32) -> 2670.6121 | K51: =IF($A51<VARIABLES!$B$28,0,(IF($A51=VARIABLES!$B$28,0,K50)+H51)*(1+C51)-J51) -> 3228770 | L51: =IF($A51<VARIABLES!$B$35,0,IF($A51=VARIABLES!$B$35,VARIABLES!$B$36+VARIABLES!$B$37,VARIABLES!$B$37)) -> 0 | M51: =L51*VARIABLES!$B$38 -> 0 | N51: =IF($A51<VARIABLES!$B$35,0,(IF($A51=VARIABLES!$B$35,0,O50)+L51)*C51*VARIABLES!$B$39) -> 12728.793 | O51: =IF($A51<VARIABLES!$B$35,0,(IF($A51=VARIABLES!$B$35,0,O50)+L51)*(1+C51)-N51) -> 15389111 | P51: =IF($A51<VARIABLES!$B$42,0,IF($A51=VARIABLES!$B$42,VARIABLES!$B$43+VARIABLES!$B$44,VARIABLES!$B$44)) -> 20000 | Q51: =P51*VARIABLES!$B$45 -> 150 | R51: =IF($A51<VARIABLES!$B$42,0,(IF($A51=VARIABLES!$B$42,0,S50)+P51)*C51*VARIABLES!$B$46) -> 350.80713 | S51: =IF($A51<VARIABLES!$B$42,0,(IF($A51=VARIABLES!$B$42,0,S50)+P51)*(1+C51)-R51) -> 1697555.7 | T51: =IF($A51<VARIABLES!$B$50,0,MIN(VARIABLES!$B$49,INT(($A51-VARIABLES!$B$50)/VARIABLES!$B$51)+1)*VARIABLES!$B$52) -> 46 | U51: =T51*VARIABLES!$B$54+IF(AND($A51>=VARIABLES!$B$50,MOD($A51-VARIABLES!$B$50,VARIABLES!$B$51)=0,INT(($A51-VARIABLES!$B$50)/VARIABLES!$B$51)<VARIABLES!$B$49),VARIABLES!$B$52*VARIABLES!$B$53,0) -> 280000 | V51: =U51*VARIABLES!$B$55 -> 2100 | W51: =IF($A51<VARIABLES!$B$50,0,(IF($A51<VARIABLES!$B$50+1,0,X50)+U51)*C51*VARIABLES!$B$56) -> 9271.5168 | X51: =IF($A51<VARIABLES!$B$50,0,(IF($A51<VARIABLES!$B$50+1,0,X50)+U51)*(1+C51)-W51) -> 11209264 | Y51: =D51+H51+L51+P51+U51 -> 540000 | Z51: =E51+I51+M51+Q51+V51 -> 4050 | AA51: =F51+J51+N51+R51+W51 -> 28889.905 | AB51: =Z51+AA51 -> 32939.905 | AC51: =G51+K51+O51+S51+X51 -> 50242806 | AD51: =IF($A51=1,VARIABLES!$B$12,0) -> 0 | AE51: =IF($A51<=3,VARIABLES!$B$13,IF($A51<=6,VARIABLES!$B$14,VARIABLES!$B$15)) -> 46000 | AF51: =IF(MOD($A51,12)=0,AC51*VARIABLES!$B$16,0) -> 125607.01 | AG51: =VARIABLES!$B$17 -> 5000 | AH51: =IF(MOD($A51,12)=0,VARIABLES!$B$18,0) -> 3000 | AI51: =AD51+AE51+AF51+AG51+AH51 -> 179607.01 | AJ51: =IF($A51<VARIABLES!$B$7,VARIABLES!$B$9,0) -> 0 | AK51: =AB51-AI51-AJ51 -> -146667.11 | AL51: =IF(AJ51>0,AL50+AK51,AL50) -> -597339.44 | AM51: =IF(AJ51>0,AM50+AJ51,AM50+AK51) -> 0.11358176
A52: TOTAL / FINAL | Y52: =SUM(Y4:Y51) -> 25425000 | Z52: =SUM(Z4:Z51) -> 190687.5 | AA52: =SUM(AA4:AA51) -> 1939101.4 | AB52: =SUM(AB4:AB51) -> 2129788.9 | AC52: =AC51 -> 50242806 | AD52: =SUM(AD4:AD51) -> 57500 | AE52: =SUM(AE4:AE51) -> 2104500 | AF52: =SUM(AF4:AF51) -> 313128.22 | AG52: =SUM(AG4:AG51) -> 240000 | AH52: =SUM(AH4:AH51) -> 12000 | AI52: =SUM(AI4:AI51) -> 2727128.2 | AJ52: =SUM(AJ4:AJ51) -> 380883 | AK52: =SUM(AK4:AK51) -> -978222.33 | AL52: =AL51 -> -597339.44 | AM52: =AM51 -> 0.11358176
A54: NOTES: ① Detail columns (Clients 1-4 + New Clients) are hidden — click the [+] group toggle above column D to expand. ② Performance fee uses simplified monthly accrual (AUM × monthly_return × perf_rate) — closely approximates quarterly HWM crystallisation. ③ CAEP AUM fee (0.25%) billed annually in months 12, 24, 36, 48 on end-of-month AUM. ④ Reserve provision set aside monthly (Years 1–3) to fund Year 4 cash deficit; tracked in Reserve Fund Balance column. ⑤ Year 4 (months 37–48) assumes 10% portfolio return — staking to USDPC. ⑥ NEW v3.0: nc_per_cohort variable = clients per cohort batch. NC Active# column shows total active clients. Example: nc_per_cohort=2 + nc_monthly=R50k → R50k total contribution per active batch.

Sheet CHARTS
A1: BitWealth (Pty) Ltd — Cashflow Visual Summary
