Workbook

Sheet VARIABLES
A1: BitWealth (Pty) Ltd — Cashflow Model Variables
A2: 48-Month Forecast · Adjust YELLOW cells · All formulas in 'MONTHLY FORECAST' tab update automatically
A4: RETURN & PERFORMANCE ASSUMPTIONS
A5: Annual portfolio return — Years 1–3 (p.a.) | B5: 0.5 | C5: 50% p.a. BTC bull cycle; divided by 12 for monthly
A6: Annual portfolio return — Year 4 (p.a.) | B6: 0.1 | C6: 10% — BTC bear/consolidation year; set to e.g. 20% for optimistic Y4
A7: Year 4 starts (model month number) | B7: 37 | C7: Month 37 = July 2029 (one month after the 36-month bull period)
A8: Performance fee crystallisation period (months) | B8: 3 | C8: 3 = quarterly (default). Change to 1 for monthly, 12 for annual
A9: Monthly reserve provision into Y4 buffer (R) | B9: =319000/12 -> 26583.333 | C9: Set aside this amount each month in Years 1–3 to fund Year 4 cash deficit
A11: COST ASSUMPTIONS
A12: CAEP onboarding fee (once-off, Month 1) | B12: 50000 | C12: Juristic Representative appointment fee
A13: CAEP hosting — Months 1–3 | B13: 20000 | C13: Per month
A14: CAEP hosting — Months 4–6 | B14: 30000 | C14: Per month
A15: CAEP hosting — Month 7 onwards | B15: 40000 | C15: Per month steady-state; negotiate cap contractually
A16: CAEP AUM fee (% of AUM, billed once annually) | B16: 0.0025 | C16: 0.25% p.a.; billed in months 12, 24, 36, 48 on AUM at that date
A17: Software & infrastructure (monthly) | B17: 5000 | C17: Cloud, Supabase, On-Chain API, Netlify, Domains, etc.
A18: Company secretarial (annual, charged in month 12/24/36/48) | B18: 3000 | C18: CIPC return + company secretary
A20: CLIENT 1 (Founding — Davin referral / existing)
A21: Start month | B21: 1 | C21: Month 1 = June 2026
A22: Initial lump sum (R) | B22: 300000
A23: Monthly contribution (R) | B23: 200000 | C23: Minimum 5 years
A24: Platform fee rate | B24: 0.0075 | C24: 0.75%
A25: Performance fee rate | B25: 0.025 | C25: 2.5% — negotiated rate for this client
A27: CLIENT 2 (Founding — lined-up)
A28: Start month | B28: 2 | C28: Month 2 = July 2026
A29: Initial lump sum (R) | B29: 0
A30: Monthly contribution (R) | B30: 40000
A31: Platform fee rate | B31: 0.0075
A32: Performance fee rate | B32: 0.1 | C32: Standard 10%
A34: CLIENT 3 (Founding — large lump sum)
A35: Start month | B35: 2 | C35: Month 2 = July 2026
A36: Initial lump sum (R) | B36: 5000000
A37: Monthly contribution (R) | B37: 0 | C37: No monthly contributions
A38: Platform fee rate | B38: 0.0075 | C38: 0.75% on lump sum = R37 500 on day 1
A39: Performance fee rate | B39: 0.1 | C39: Standard 10%
A41: CLIENT 4 (Founding — lined-up)
A42: Start month | B42: 2 | C42: Month 2 = July 2026
A43: Initial lump sum (R) | B43: 0
A44: Monthly contribution (R) | B44: 20000
A45: Platform fee rate | B45: 0.0075
A46: Performance fee rate | B46: 0.025 | C46: 2.5% — preferential rate
...

Sheet MONTHLY FORECAST
A1: BitWealth (Pty) Ltd — 48-Month Operating Cashflow Forecast · All formulas auto-update when VARIABLES are changed
A2: PERIOD | D2: CLIENT DETAIL (hidden by default — click + to expand) | T2: NEW CLIENTS | Y2: REVENUE | AC2: TOTAL AUM | AD2: COSTS | AJ2: RESERVE | AK2: CASHFLOW
A3: Month # | B3: Month | C3: Monthly Return % | D3: C1 Contrib | E3: C1 Plat Fee | F3: C1 Perf Fee | G3: C1 AUM | H3: C2 Contrib | I3: C2 Plat Fee | J3: C2 Perf Fee | K3: C2 AUM | L3: C3 Contrib | M3: C3 Plat Fee | N3: C3 Perf Fee | O3: C3 AUM | P3: C4 Contrib | Q3: C4 Plat Fee | R3: C4 Perf Fee | S3: C4 AUM | T3: NC Active# | U3: NC Contrib | V3: NC Plat Fee | W3: NC Perf Fee | X3: NC AUM | Y3: Total Contrib | Z3: Total Plat Fee | AA3: Total Perf Fee | AB3: TOTAL REVENUE | AC3: TOTAL AUM | AD3: CAEP Onboard | AE3: CAEP Hosting | AF3: CAEP AUM Fee | AG3: Software | AH3: Co Sec | AI3: TOTAL COSTS | AJ3: Reserve Provision | AK3: NET CASH (after reserve) | AL3: CUMULATIVE CASH | AM3: Reserve Fund Bal
A4: 1 | B4: =TEXT(DATE(VARIABLES!$B$59+INT((VARIABLES!$B$60+A4-2)/12),MOD(VARIABLES!$B$60+A4-2,12)+1,1),"mmm-yy") -> Jun-26 | C4: =IF($A4<VARIABLES!$B$7,VARIABLES!$B$5/12,VARIABLES!$B$6/12) -> 0.041666667 | D4: =IF($A4<VARIABLES!$B$21,0,IF($A4=VARIABLES!$B$21,VARIABLES!$B$22+VARIABLES!$B$23,VARIABLES!$B$23)) -> 500000 | E4: =D4*VARIABLES!$B$24 -> 3750 | F4: =IF($A4<VARIABLES!$B$21,0,(IF($A4=VARIABLES!$B$21,0,G3)+D4)*C4*VARIABLES!$B$25) -> 520.83333 | G4: =IF($A4<VARIABLES!$B$21,0,(IF($A4=VARIABLES!$B$21,0,G3)+D4)*(1+C4)-F4) -> 520312.5 | H4: =IF($A4<VARIABLES!$B$28,0,IF($A4=VARIABLES!$B$28,VARIABLES!$B$29+VARIABLES!$B$30,VARIABLES!$B$30)) -> 0 | I4: =H4*VARIABLES!$B$31 -> 0 | J4: =IF($A4<VARIABLES!$B$28,0,(IF($A4=VARIABLES!$B$28,0,K3)+H4)*C4*VARIABLES!$B$32) -> 0 | K4: =IF($A4<VARIABLES!$B$28,0,(IF($A4=VARIABLES!$B$28,0,K3)+H4)*(1+C4)-J4) -> 0 | L4: =IF($A4<VARIABLES!$B$35,0,IF($A4=VARIABLES!$B$35,VARIABLES!$B$36+VARIABLES!$B$37,VARIABLES!$B$37)) -> 0 | M4: =L4*VARIABLES!$B$38 -> 0 | N4: =IF($A4<VARIABLES!$B$35,0,(IF($A4=VARIABLES!$B$35,0,O3)+L4)*C4*VARIABLES!$B$39) -> 0 | O4: =IF($A4<VARIABLES!$B$35,0,(IF($A4=VARIABLES!$B$35,0,O3)+L4)*(1+C4)-N4) -> 0 | P4: =IF($A4<VARIABLES!$B$42,0,IF($A4=VARIABLES!$B$42,VARIABLES!$B$43+VARIABLES!$B$44,VARIABLES!$B$44)) -> 0 | Q4: =P4*VARIABLES!$B$45 -> 0 | R4: =IF($A4<VARIABLES!$B$42,0,(IF($A4=VARIABLES!$B$42,0,S3)+P4)*C4*VARIABLES!$B$46) -> 0 | S4: =IF($A4<VARIABLES!$B$42,0,(IF($A4=VARIABLES!$B$42,0,S3)+P4)*(1+C4)-R4) -> 0 | T4: =IF($A4<VARIABLES!$B$50,0,MIN(VARIABLES!$B$49,INT(($A4-VARIABLES!$B$50)/VARIABLES!$B$51)+1)) -> 0 | U4: =T4*VARIABLES!$B$53+IF(AND($A4>=VARIABLES!$B$50,MOD($A4-VARIABLES!$B$50,VARIABLES!$B$51)=0,($A4-VARIABLES!$B$50)/VARIABLES!$B$51<VARIABLES!$B$49),VARIABLES!$B$52,0) -> 0 | V4: =U4*VARIABLES!$B$54 -> 0 | W4: =IF($A4<VARIABLES!$B$50,0,(IF($A4<VARIABLES!$B$50+1,0,X3)+U4)*C4*VARIABLES!$B$55) -> 0 | X4: =IF($A4<VARIABLES!$B$50,0,(IF($A4<VARIABLES!$B$50+1,0,X3)+U4)*(1+C4)-W4) -> 0 | Y4: =D4+H4+L4+P4+U4 -> 500000 | Z4: =E4+I4+M4+Q4+V4 -> 3750 | AA4: =F4+J4+N4+R4+W4 -> 520.83333 | AB4: =Z4+AA4 -> 4270.8333 | AC4: =G4+K4+O4+S4+X4 -> 520312.5 | AD4: =IF($A4=1,VARIABLES!$B$12,0) -> 50000 | AE4: =IF($A4<=3,VARIABLES!$B$13,IF($A4<=6,VARIABLES!$B$14,VARIABLES!$B$15)) -> 20000 | AF4: =IF(MOD($A4,12)=0,AC4*VARIABLES!$B$16,0) -> 0 | AG4: =VARIABLES!$B$17 -> 5000 | AH4: =IF(MOD($A4,12)=0,VARIABLES!$B$18,0) -> 0 | AI4: =AD4+AE4+AF4+AG4+AH4 -> 75000 | AJ4: =IF($A4<VARIABLES!$B$7,VARIABLES!$B$9,0) -> 26583.333 | AK4: =AB4-AI4-AJ4 -> -97312.5 | AL4: =AK4 -> -97312.5 | AM4: =AJ4 -> 26583.333
A5: 2 | B5: =TEXT(DATE(VARIABLES!$B$59+INT((VARIABLES!$B$60+A5-2)/12),MOD(VARIABLES!$B$60+A5-2,12)+1,1),"mmm-yy") -> Jul-26 | C5: =IF($A5<VARIABLES!$B$7,VARIABLES!$B$5/12,VARIABLES!$B$6/12) -> 0.041666667 | D5: =IF($A5<VARIABLES!$B$21,0,IF($A5=VARIABLES!$B$21,VARIABLES!$B$22+VARIABLES!$B$23,VARIABLES!$B$23)) -> 200000 | E5: =D5*VARIABLES!$B$24 -> 1500 | F5: =IF($A5<VARIABLES!$B$21,0,(IF($A5=VARIABLES!$B$21,0,G4)+D5)*C5*VARIABLES!$B$25) -> 750.32552 | G5: =IF($A5<VARIABLES!$B$21,0,(IF($A5=VARIABLES!$B$21,0,G4)+D5)*(1+C5)-F5) -> 749575.2 | H5: =IF($A5<VARIABLES!$B$28,0,IF($A5=VARIABLES!$B$28,VARIABLES!$B$29+VARIABLES!$B$30,VARIABLES!$B$30)) -> 40000 | I5: =H5*VARIABLES!$B$31 -> 300 | J5: =IF($A5<VARIABLES!$B$28,0,(IF($A5=VARIABLES!$B$28,0,K4)+H5)*C5*VARIABLES!$B$32) -> 166.66667 | K5: =IF($A5<VARIABLES!$B$28,0,(IF($A5=VARIABLES!$B$28,0,K4)+H5)*(1+C5)-J5) -> 41500 | L5: =IF($A5<VARIABLES!$B$35,0,IF($A5=VARIABLES!$B$35,VARIABLES!$B$36+VARIABLES!$B$37,VARIABLES!$B$37)) -> 5000000 | M5: =L5*VARIABLES!$B$38 -> 37500 | N5: =IF($A5<VARIABLES!$B$35,0,(IF($A5=VARIABLES!$B$35,0,O4)+L5)*C5*VARIABLES!$B$39) -> 20833.333 | O5: =IF($A5<VARIABLES!$B$35,0,(IF($A5=VARIABLES!$B$35,0,O4)+L5)*(1+C5)-N5) -> 5187500 | P5: =IF($A5<VARIABLES!$B$42,0,IF($A5=VARIABLES!$B$42,VARIABLES!$B$43+VARIABLES!$B$44,VARIABLES!$B$44)) -> 20000 | Q5: =P5*VARIABLES!$B$45 -> 150 | R5: =IF($A5<VARIABLES!$B$42,0,(IF($A5=VARIABLES!$B$42,0,S4)+P5)*C5*VARIABLES!$B$46) -> 20.833333 | S5: =IF($A5<VARIABLES!$B$42,0,(IF($A5=VARIABLES!$B$42,0,S4)+P5)*(1+C5)-R5) -> 20812.5 | T5: =IF($A5<VARIABLES!$B$50,0,MIN(VARIABLES!$B$49,INT(($A5-VARIABLES!$B$50)/VARIABLES!$B$51)+1)) -> 0 | U5: =T5*VARIABLES!$B$53+IF(AND($A5>=VARIABLES!$B$50,MOD($A5-VARIABLES!$B$50,VARIABLES!$B$51)=0,($A5-VARIABLES!$B$50)/VARIABLES!$B$51<VARIABLES!$B$49),VARIABLES!$B$52,0) -> 0 | V5: =U5*VARIABLES!$B$54 -> 0 | W5: =IF($A5<VARIABLES!$B$50,0,(IF($A5<VARIABLES!$B$50+1,0,X4)+U5)*C5*VARIABLES!$B$55) -> 0 | X5: =IF($A5<VARIABLES!$B$50,0,(IF($A5<VARIABLES!$B$50+1,0,X4)+U5)*(1+C5)-W5) -> 0 | Y5: =D5+H5+L5+P5+U5 -> 5260000 | Z5: =E5+I5+M5+Q5+V5 -> 39450 | AA5: =F5+J5+N5+R5+W5 -> 21771.159 | AB5: =Z5+AA5 -> 61221.159 | AC5: =G5+K5+O5+S5+X5 -> 5999387.7 | AD5: =IF($A5=1,VARIABLES!$B$12,0) -> 0 | AE5: =IF($A5<=3,VARIABLES!$B$13,IF($A5<=6,VARIABLES!$B$14,VARIABLES!$B$15)) -> 20000 | AF5: =IF(MOD($A5,12)=0,AC5*VARIABLES!$B$16,0) -> 0 | AG5: =VARIABLES!$B$17 -> 5000 | AH5: =IF(MOD($A5,12)=0,VARIABLES!$B$18,0) -> 0 | AI5: =AD5+AE5+AF5+AG5+AH5 -> 25000 | AJ5: =IF($A5<VARIABLES!$B$7,VARIABLES!$B$9,0) -> 26583.333 | AK5: =AB5-AI5-AJ5 -> 9637.8255 | AL5: =AL4+AK5 -> -87674.674 | AM5: =AM4+AJ5 -> 53166.667
A6: 3 | B6: =TEXT(DATE(VARIABLES!$B$59+INT((VARIABLES!$B$60+A6-2)/12),MOD(VARIABLES!$B$60+A6-2,12)+1,1),"mmm-yy") -> Aug-26 | C6: =IF($A6<VARIABLES!$B$7,VARIABLES!$B$5/12,VARIABLES!$B$6/12) -> 0.041666667 | D6: =IF($A6<VARIABLES!$B$21,0,IF($A6=VARIABLES!$B$21,VARIABLES!$B$22+VARIABLES!$B$23,VARIABLES!$B$23)) -> 200000 | E6: =D6*VARIABLES!$B$24 -> 1500 | F6: =IF($A6<VARIABLES!$B$21,0,(IF($A6=VARIABLES!$B$21,0,G5)+D6)*C6*VARIABLES!$B$25) -> 989.14083 | G6: =IF($A6<VARIABLES!$B$21,0,(IF($A6=VARIABLES!$B$21,0,G5)+D6)*(1+C6)-F6) -> 988151.69 | H6: =IF($A6<VARIABLES!$B$28,0,IF($A6=VARIABLES!$B$28,VARIABLES!$B$29+VARIABLES!$B$30,VARIABLES!$B$30)) -> 40000 | I6: =H6*VARIABLES!$B$31 -> 300 | J6: =IF($A6<VARIABLES!$B$28,0,(IF($A6=VARIABLES!$B$28,0,K5)+H6)*C6*VARIABLES!$B$32) -> 339.58333 | K6: =IF($A6<VARIABLES!$B$28,0,(IF($A6=VARIABLES!$B$28,0,K5)+H6)*(1+C6)-J6) -> 84556.25 | L6: =IF($A6<VARIABLES!$B$35,0,IF($A6=VARIABLES!$B$35,VARIABLES!$B$36+VARIABLES!$B$37,VARIABLES!$B$37)) -> 0 | M6: =L6*VARIABLES!$B$38 -> 0 | N6: =IF($A6<VARIABLES!$B$35,0,(IF($A6=VARIABLES!$B$35,0,O5)+L6)*C6*VARIABLES!$B$39) -> 21614.583 | O6: =IF($A6<VARIABLES!$B$35,0,(IF($A6=VARIABLES!$B$35,0,O5)+L6)*(1+C6)-N6) -> 5382031.3 | P6: =IF($A6<VARIABLES!$B$42,0,IF($A6=VARIABLES!$B$42,VARIABLES!$B$43+VARIABLES!$B$44,VARIABLES!$B$44)) -> 20000 | Q6: =P6*VARIABLES!$B$45 -> 150 | R6: =IF($A6<VARIABLES!$B$42,0,(IF($A6=VARIABLES!$B$42,0,S5)+P6)*C6*VARIABLES!$B$46) -> 42.513021 | S6: =IF($A6<VARIABLES!$B$42,0,(IF($A6=VARIABLES!$B$42,0,S5)+P6)*(1+C6)-R6) -> 42470.508 | T6: =IF($A6<VARIABLES!$B$50,0,MIN(VARIABLES!$B$49,INT(($A6-VARIABLES!$B$50)/VARIABLES!$B$51)+1)) -> 0 | U6: =T6*VARIABLES!$B$53+IF(AND($A6>=VARIABLES!$B$50,MOD($A6-VARIABLES!$B$50,VARIABLES!$B$51)=0,($A6-VARIABLES!$B$50)/VARIABLES!$B$51<VARIABLES!$B$49),VARIABLES!$B$52,0) -> 0 | V6: =U6*VARIABLES!$B$54 -> 0 | W6: =IF($A6<VARIABLES!$B$50,0,(IF($A6<VARIABLES!$B$50+1,0,X5)+U6)*C6*VARIABLES!$B$55) -> 0 | X6: =IF($A6<VARIABLES!$B$50,0,(IF($A6<VARIABLES!$B$50+1,0,X5)+U6)*(1+C6)-W6) -> 0 | Y6: =D6+H6+L6+P6+U6 -> 260000 | Z6: =E6+I6+M6+Q6+V6 -> 1950 | AA6: =F6+J6+N6+R6+W6 -> 22985.821 | AB6: =Z6+AA6 -> 24935.821 | AC6: =G6+K6+O6+S6+X6 -> 6497209.7 | AD6: =IF($A6=1,VARIABLES!$B$12,0) -> 0 | AE6: =IF($A6<=3,VARIABLES!$B$13,IF($A6<=6,VARIABLES!$B$14,VARIABLES!$B$15)) -> 20000 | AF6: =IF(MOD($A6,12)=0,AC6*VARIABLES!$B$16,0) -> 0 | AG6: =VARIABLES!$B$17 -> 5000 | AH6: =IF(MOD($A6,12)=0,VARIABLES!$B$18,0) -> 0 | AI6: =AD6+AE6+AF6+AG6+AH6 -> 25000 | AJ6: =IF($A6<VARIABLES!$B$7,VARIABLES!$B$9,0) -> 26583.333 | AK6: =AB6-AI6-AJ6 -> -26647.513 | AL6: =AL5+AK6 -> -114322.19 | AM6: =AM5+AJ6 -> 79750
A7: 4 | B7: =TEXT(DATE(VARIABLES!$B$59+INT((VARIABLES!$B$60+A7-2)/12),MOD(VARIABLES!$B$60+A7-2,12)+1,1),"mmm-yy") -> Sept-26 | C7: =IF($A7<VARIABLES!$B$7,VARIABLES!$B$5/12,VARIABLES!$B$6/12) -> 0.041666667 | D7: =IF($A7<VARIABLES!$B$21,0,IF($A7=VARIABLES!$B$21,VARIABLES!$B$22+VARIABLES!$B$23,VARIABLES!$B$23)) -> 200000 | E7: =D7*VARIABLES!$B$24 -> 1500 | F7: =IF($A7<VARIABLES!$B$21,0,(IF($A7=VARIABLES!$B$21,0,G6)+D7)*C7*VARIABLES!$B$25) -> 1237.658 | G7: =IF($A7<VARIABLES!$B$21,0,(IF($A7=VARIABLES!$B$21,0,G6)+D7)*(1+C7)-F7) -> 1236420.3 | H7: =IF($A7<VARIABLES!$B$28,0,IF($A7=VARIABLES!$B$28,VARIABLES!$B$29+VARIABLES!$B$30,VARIABLES!$B$30)) -> 40000 | I7: =H7*VARIABLES!$B$31 -> 300 | J7: =IF($A7<VARIABLES!$B$28,0,(IF($A7=VARIABLES!$B$28,0,K6)+H7)*C7*VARIABLES!$B$32) -> 518.98438 | K7: =IF($A7<VARIABLES!$B$28,0,(IF($A7=VARIABLES!$B$28,0,K6)+H7)*(1+C7)-J7) -> 129227.11 | L7: =IF($A7<VARIABLES!$B$35,0,IF($A7=VARIABLES!$B$35,VARIABLES!$B$36+VARIABLES!$B$37,VARIABLES!$B$37)) -> 0 | M7: =L7*VARIABLES!$B$38 -> 0 | N7: =IF($A7<VARIABLES!$B$35,0,(IF($A7=VARIABLES!$B$35,0,O6)+L7)*C7*VARIABLES!$B$39) -> 22425.13 | O7: =IF($A7<VARIABLES!$B$35,0,(IF($A7=VARIABLES!$B$35,0,O6)+L7)*(1+C7)-N7) -> 5583857.4 | P7: =IF($A7<VARIABLES!$B$42,0,IF($A7=VARIABLES!$B$42,VARIABLES!$B$43+VARIABLES!$B$44,VARIABLES!$B$44)) -> 20000 | Q7: =P7*VARIABLES!$B$45 -> 150 | R7: =IF($A7<VARIABLES!$B$42,0,(IF($A7=VARIABLES!$B$42,0,S6)+P7)*C7*VARIABLES!$B$46) -> 65.073446 | S7: =IF($A7<VARIABLES!$B$42,0,(IF($A7=VARIABLES!$B$42,0,S6)+P7)*(1+C7)-R7) -> 65008.372 | T7: =IF($A7<VARIABLES!$B$50,0,MIN(VARIABLES!$B$49,INT(($A7-VARIABLES!$B$50)/VARIABLES!$B$51)+1)) -> 1 | U7: =T7*VARIABLES!$B$53+IF(AND($A7>=VARIABLES!$B$50,MOD($A7-VARIABLES!$B$50,VARIABLES!$B$51)=0,($A7-VARIABLES!$B$50)/VARIABLES!$B$51<VARIABLES!$B$49),VARIABLES!$B$52,0) -> 55000 | V7: =U7*VARIABLES!$B$54 -> 412.5 | W7: =IF($A7<VARIABLES!$B$50,0,(IF($A7<VARIABLES!$B$50+1,0,X6)+U7)*C7*VARIABLES!$B$55) -> 229.16667 | X7: =IF($A7<VARIABLES!$B$50,0,(IF($A7<VARIABLES!$B$50+1,0,X6)+U7)*(1+C7)-W7) -> 57062.5 | Y7: =D7+H7+L7+P7+U7 -> 315000 | Z7: =E7+I7+M7+Q7+V7 -> 2362.5 | AA7: =F7+J7+N7+R7+W7 -> 24476.013 | AB7: =Z7+AA7 -> 26838.513 | AC7: =G7+K7+O7+S7+X7 -> 7071575.8 | AD7: =IF($A7=1,VARIABLES!$B$12,0) -> 0 | AE7: =IF($A7<=3,VARIABLES!$B$13,IF($A7<=6,VARIABLES!$B$14,VARIABLES!$B$15)) -> 30000 | AF7: =IF(MOD($A7,12)=0,AC7*VARIABLES!$B$16,0) -> 0 | AG7: =VARIABLES!$B$17 -> 5000 | AH7: =IF(MOD($A7,12)=0,VARIABLES!$B$18,0) -> 0 | AI7: =AD7+AE7+AF7+AG7+AH7 -> 35000 | AJ7: =IF($A7<VARIABLES!$B$7,VARIABLES!$B$9,0) -> 26583.333 | AK7: =AB7-AI7-AJ7 -> -34744.821 | AL7: =AL6+AK7 -> -149067.01 | AM7: =AM6+AJ7 -> 106333.33
A8: 5 | B8: =TEXT(DATE(VARIABLES!$B$59+INT((VARIABLES!$B$60+A8-2)/12),MOD(VARIABLES!$B$60+A8-2,12)+1,1),"mmm-yy") -> Oct-26 | C8: =IF($A8<VARIABLES!$B$7,VARIABLES!$B$5/12,VARIABLES!$B$6/12) -> 0.041666667 | D8: =IF($A8<VARIABLES!$B$21,0,IF($A8=VARIABLES!$B$21,VARIABLES!$B$22+VARIABLES!$B$23,VARIABLES!$B$23)) -> 200000 | E8: =D8*VARIABLES!$B$24 -> 1500 | F8: =IF($A8<VARIABLES!$B$21,0,(IF($A8=VARIABLES!$B$21,0,G7)+D8)*C8*VARIABLES!$B$25) -> 1496.2712 | G8: =IF($A8<VARIABLES!$B$21,0,(IF($A8=VARIABLES!$B$21,0,G7)+D8)*(1+C8)-F8) -> 1494774.9 | H8: =IF($A8<VARIABLES!$B$28,0,IF($A8=VARIABLES!$B$28,VARIABLES!$B$29+VARIABLES!$B$30,VARIABLES!$B$30)) -> 40000 | I8: =H8*VARIABLES!$B$31 -> 300 | J8: =IF($A8<VARIABLES!$B$28,0,(IF($A8=VARIABLES!$B$28,0,K7)+H8)*C8*VARIABLES!$B$32) -> 705.11296 | K8: =IF($A8<VARIABLES!$B$28,0,(IF($A8=VARIABLES!$B$28,0,K7)+H8)*(1+C8)-J8) -> 175573.13 | L8: =IF($A8<VARIABLES!$B$35,0,IF($A8=VARIABLES!$B$35,VARIABLES!$B$36+VARIABLES!$B$37,VARIABLES!$B$37)) -> 0 | M8: =L8*VARIABLES!$B$38 -> 0 | N8: =IF($A8<VARIABLES!$B$35,0,(IF($A8=VARIABLES!$B$35,0,O7)+L8)*C8*VARIABLES!$B$39) -> 23266.073 | O8: =IF($A8<VARIABLES!$B$35,0,(IF($A8=VARIABLES!$B$35,0,O7)+L8)*(1+C8)-N8) -> 5793252.1 | P8: =IF($A8<VARIABLES!$B$42,0,IF($A8=VARIABLES!$B$42,VARIABLES!$B$43+VARIABLES!$B$44,VARIABLES!$B$44)) -> 20000 | Q8: =P8*VARIABLES!$B$45 -> 150 | R8: =IF($A8<VARIABLES!$B$42,0,(IF($A8=VARIABLES!$B$42,0,S7)+P8)*C8*VARIABLES!$B$46) -> 88.550388 | S8: =IF($A8<VARIABLES!$B$42,0,(IF($A8=VARIABLES!$B$42,0,S7)+P8)*(1+C8)-R8) -> 88461.837 | T8: =IF($A8<VARIABLES!$B$50,0,MIN(VARIABLES!$B$49,INT(($A8-VARIABLES!$B$50)/VARIABLES!$B$51)+1)) -> 2 | U8: =T8*VARIABLES!$B$53+IF(AND($A8>=VARIABLES!$B$50,MOD($A8-VARIABLES!$B$50,VARIABLES!$B$51)=0,($A8-VARIABLES!$B$50)/VARIABLES!$B$51<VARIABLES!$B$49),VARIABLES!$B$52,0) -> 60000 | V8: =U8*VARIABLES!$B$54 -> 450 | W8: =IF($A8<VARIABLES!$B$50,0,(IF($A8<VARIABLES!$B$50+1,0,X7)+U8)*C8*VARIABLES!$B$55) -> 487.76042 | X8: =IF($A8<VARIABLES!$B$50,0,(IF($A8<VARIABLES!$B$50+1,0,X7)+U8)*(1+C8)-W8) -> 121452.34 | Y8: =D8+H8+L8+P8+U8 -> 320000 | Z8: =E8+I8+M8+Q8+V8 -> 2400 | AA8: =F8+J8+N8+R8+W8 -> 26043.768 | AB8: =Z8+AA8 -> 28443.768 | AC8: =G8+K8+O8+S8+X8 -> 7673514.3 | AD8: =IF($A8=1,VARIABLES!$B$12,0) -> 0 | AE8: =IF($A8<=3,VARIABLES!$B$13,IF($A8<=6,VARIABLES!$B$14,VARIABLES!$B$15)) -> 30000 | AF8: =IF(MOD($A8,12)=0,AC8*VARIABLES!$B$16,0) -> 0 | AG8: =VARIABLES!$B$17 -> 5000 | AH8: =IF(MOD($A8,12)=0,VARIABLES!$B$18,0) -> 0 | AI8: =AD8+AE8+AF8+AG8+AH8 -> 35000 | AJ8: =IF($A8<VARIABLES!$B$7,VARIABLES!$B$9,0) -> 26583.333 | AK8: =AB8-AI8-AJ8 -> -33139.566 | AL8: =AL7+AK8 -> -182206.57 | AM8: =AM7+AJ8 -> 132916.67
A9: 6 | B9: =TEXT(DATE(VARIABLES!$B$59+INT((VARIABLES!$B$60+A9-2)/12),MOD(VARIABLES!$B$60+A9-2,12)+1,1),"mmm-yy") -> Nov-26 | C9: =IF($A9<VARIABLES!$B$7,VARIABLES!$B$5/12,VARIABLES!$B$6/12) -> 0.041666667 | D9: =IF($A9<VARIABLES!$B$21,0,IF($A9=VARIABLES!$B$21,VARIABLES!$B$22+VARIABLES!$B$23,VARIABLES!$B$23)) -> 200000 | E9: =D9*VARIABLES!$B$24 -> 1500 | F9: =IF($A9<VARIABLES!$B$21,0,(IF($A9=VARIABLES!$B$21,0,G8)+D9)*C9*VARIABLES!$B$25) -> 1765.3905 | G9: =IF($A9<VARIABLES!$B$21,0,(IF($A9=VARIABLES!$B$21,0,G8)+D9)*(1+C9)-F9) -> 1763625.2 | H9: =IF($A9<VARIABLES!$B$28,0,IF($A9=VARIABLES!$B$28,VARIABLES!$B$29+VARIABLES!$B$30,VARIABLES!$B$30)) -> 40000 | I9: =H9*VARIABLES!$B$31 -> 300 | J9: =IF($A9<VARIABLES!$B$28,0,(IF($A9=VARIABLES!$B$28,0,K8)+H9)*C9*VARIABLES!$B$32) -> 898.22136 | K9: =IF($A9<VARIABLES!$B$28,0,(IF($A9=VARIABLES!$B$28,0,K8)+H9)*(1+C9)-J9) -> 223657.12 | L9: =IF($A9<VARIABLES!$B$35,0,IF($A9=VARIABLES!$B$35,VARIABLES!$B$36+VARIABLES!$B$37,VARIABLES!$B$37)) -> 0 | M9: =L9*VARIABLES!$B$38 -> 0 | N9: =IF($A9<VARIABLES!$B$35,0,(IF($A9=VARIABLES!$B$35,0,O8)+L9)*C9*VARIABLES!$B$39) -> 24138.55 | O9: =IF($A9<VARIABLES!$B$35,0,(IF($A9=VARIABLES!$B$35,0,O8)+L9)*(1+C9)-N9) -> 6010499 | P9: =IF($A9<VARIABLES!$B$42,0,IF($A9=VARIABLES!$B$42,VARIABLES!$B$43+VARIABLES!$B$44,VARIABLES!$B$44)) -> 20000 | Q9: =P9*VARIABLES!$B$45 -> 150 | R9: =IF($A9<VARIABLES!$B$42,0,(IF($A9=VARIABLES!$B$42,0,S8)+P9)*C9*VARIABLES!$B$46) -> 112.98108 | S9: =IF($A9<VARIABLES!$B$42,0,(IF($A9=VARIABLES!$B$42,0,S8)+P9)*(1+C9)-R9) -> 112868.1 | T9: =IF($A9<VARIABLES!$B$50,0,MIN(VARIABLES!$B$49,INT(($A9-VARIABLES!$B$50)/VARIABLES!$B$51)+1)) -> 3 | U9: =T9*VARIABLES!$B$53+IF(AND($A9>=VARIABLES!$B$50,MOD($A9-VARIABLES!$B$50,VARIABLES!$B$51)=0,($A9-VARIABLES!$B$50)/VARIABLES!$B$51<VARIABLES!$B$49),VARIABLES!$B$52,0) -> 65000 | V9: =U9*VARIABLES!$B$54 -> 487.5 | W9: =IF($A9<VARIABLES!$B$50,0,(IF($A9<VARIABLES!$B$50+1,0,X8)+U9)*C9*VARIABLES!$B$55) -> 776.88477 | X9: =IF($A9<VARIABLES!$B$50,0,(IF($A9<VARIABLES!$B$50+1,0,X8)+U9)*(1+C9)-W9) -> 193444.31 | Y9: =D9+H9+L9+P9+U9 -> 325000 | Z9: =E9+I9+M9+Q9+V9 -> 2437.5 | AA9: =F9+J9+N9+R9+W9 -> 27692.028 | AB9: =Z9+AA9 -> 30129.528 | AC9: =G9+K9+O9+S9+X9 -> 8304093.7 | AD9: =IF($A9=1,VARIABLES!$B$12,0) -> 0 | AE9: =IF($A9<=3,VARIABLES!$B$13,IF($A9<=6,VARIABLES!$B$14,VARIABLES!$B$15)) -> 30000 | AF9: =IF(MOD($A9,12)=0,AC9*VARIABLES!$B$16,0) -> 0 | AG9: =VARIABLES!$B$17 -> 5000 | AH9: =IF(MOD($A9,12)=0,VARIABLES!$B$18,0) -> 0 | AI9: =AD9+AE9+AF9+AG9+AH9 -> 35000 | AJ9: =IF($A9<VARIABLES!$B$7,VARIABLES!$B$9,0) -> 26583.333 | AK9: =AB9-AI9-AJ9 -> -31453.805 | AL9: =AL8+AK9 -> -213660.38 | AM9: =AM8+AJ9 -> 159500
A10: 7 | B10: =TEXT(DATE(VARIABLES!$B$59+INT((VARIABLES!$B$60+A10-2)/12),MOD(VARIABLES!$B$60+A10-2,12)+1,1),"mmm-yy") -> Dec-26 | C10: =IF($A10<VARIABLES!$B$7,VARIABLES!$B$5/12,VARIABLES!$B$6/12) -> 0.041666667 | D10: =IF($A10<VARIABLES!$B$21,0,IF($A10=VARIABLES!$B$21,VARIABLES!$B$22+VARIABLES!$B$23,VARIABLES!$B$23)) -> 200000 | E10: =D10*VARIABLES!$B$24 -> 1500 | F10: =IF($A10<VARIABLES!$B$21,0,(IF($A10=VARIABLES!$B$21,0,G9)+D10)*C10*VARIABLES!$B$25) -> 2045.4429 | G10: =IF($A10<VARIABLES!$B$21,0,(IF($A10=VARIABLES!$B$21,0,G9)+D10)*(1+C10)-F10) -> 2043397.4 | H10: =IF($A10<VARIABLES!$B$28,0,IF($A10=VARIABLES!$B$28,VARIABLES!$B$29+VARIABLES!$B$30,VARIABLES!$B$30)) -> 40000 | I10: =H10*VARIABLES!$B$31 -> 300 | J10: =IF($A10<VARIABLES!$B$28,0,(IF($A10=VARIABLES!$B$28,0,K9)+H10)*C10*VARIABLES!$B$32) -> 1098.5713 | K10: =IF($A10<VARIABLES!$B$28,0,(IF($A10=VARIABLES!$B$28,0,K9)+H10)*(1+C10)-J10) -> 273544.26 | L10: =IF($A10<VARIABLES!$B$35,0,IF($A10=VARIABLES!$B$35,VARIABLES!$B$36+VARIABLES!$B$37,VARIABLES!$B$37)) -> 0 | M10: =L10*VARIABLES!$B$38 -> 0 | N10: =IF($A10<VARIABLES!$B$35,0,(IF($A10=VARIABLES!$B$35,0,O9)+L10)*C10*VARIABLES!$B$39) -> 25043.746 | O10: =IF($A10<VARIABLES!$B$35,0,(IF($A10=VARIABLES!$B$35,0,O9)+L10)*(1+C10)-N10) -> 6235892.7 | P10: =IF($A10<VARIABLES!$B$42,0,IF($A10=VARIABLES!$B$42,VARIABLES!$B$43+VARIABLES!$B$44,VARIABLES!$B$44)) -> 20000 | Q10: =P10*VARIABLES!$B$45 -> 150 | R10: =IF($A10<VARIABLES!$B$42,0,(IF($A10=VARIABLES!$B$42,0,S9)+P10)*C10*VARIABLES!$B$46) -> 138.40427 | S10: =IF($A10<VARIABLES!$B$42,0,(IF($A10=VARIABLES!$B$42,0,S9)+P10)*(1+C10)-R10) -> 138265.87 | T10: =IF($A10<VARIABLES!$B$50,0,MIN(VARIABLES!$B$49,INT(($A10-VARIABLES!$B$50)/VARIABLES!$B$51)+1)) -> 4 | U10: =T10*VARIABLES!$B$53+IF(AND($A10>=VARIABLES!$B$50,MOD($A10-VARIABLES!$B$50,VARIABLES!$B$51)=0,($A10-VARIABLES!$B$50)/VARIABLES!$B$51<VARIABLES!$B$49),VARIABLES!$B$52,0) -> 70000 | V10: =U10*VARIABLES!$B$54 -> 525 | W10: =IF($A10<VARIABLES!$B$50,0,(IF($A10<VARIABLES!$B$50+1,0,X9)+U10)*C10*VARIABLES!$B$55) -> 1097.6846 | X10: =IF($A10<VARIABLES!$B$50,0,(IF($A10<VARIABLES!$B$50+1,0,X9)+U10)*(1+C10)-W10) -> 273323.47 | Y10: =D10+H10+L10+P10+U10 -> 330000 | Z10: =E10+I10+M10+Q10+V10 -> 2475 | AA10: =F10+J10+N10+R10+W10 -> 29423.849 | AB10: =Z10+AA10 -> 31898.849 | AC10: =G10+K10+O10+S10+X10 -> 8964423.8 | AD10: =IF($A10=1,VARIABLES!$B$12,0) -> 0 | AE10: =IF($A10<=3,VARIABLES!$B$13,IF($A10<=6,VARIABLES!$B$14,VARIABLES!$B$15)) -> 40000 | AF10: =IF(MOD($A10,12)=0,AC10*VARIABLES!$B$16,0) -> 0 | AG10: =VARIABLES!$B$17 -> 5000 | AH10: =IF(MOD($A10,12)=0,VARIABLES!$B$18,0) -> 0 | AI10: =AD10+AE10+AF10+AG10+AH10 -> 45000 | AJ10: =IF($A10<VARIABLES!$B$7,VARIABLES!$B$9,0) -> 26583.333 | AK10: =AB10-AI10-AJ10 -> -39684.484 | AL10: =AL9+AK10 -> -253344.86 | AM10: =AM9+AJ10 -> 186083.33
A11: 8 | B11: =TEXT(DATE(VARIABLES!$B$59+INT((VARIABLES!$B$60+A11-2)/12),MOD(VARIABLES!$B$60+A11-2,12)+1,1),"mmm-yy") -> Jan-27 | C11: =IF($A11<VARIABLES!$B$7,VARIABLES!$B$5/12,VARIABLES!$B$6/12) -> 0.041666667 | D11: =IF($A11<VARIABLES!$B$21,0,IF($A11=VARIABLES!$B$21,VARIABLES!$B$22+VARIABLES!$B$23,VARIABLES!$B$23)) -> 200000 | E11: =D11*VARIABLES!$B$24 -> 1500 | F11: =IF($A11<VARIABLES!$B$21,0,(IF($A11=VARIABLES!$B$21,0,G10)+D11)*C11*VARIABLES!$B$25) -> 2336.8723 | G11: =IF($A11<VARIABLES!$B$21,0,(IF($A11=VARIABLES!$B$21,0,G10)+D11)*(1+C11)-F11) -> 2334535.5 | H11: =IF($A11<VARIABLES!$B$28,0,IF($A11=VARIABLES!$B$28,VARIABLES!$B$29+VARIABLES!$B$30,VARIABLES!$B$30)) -> 40000 | I11: =H11*VARIABLES!$B$31 -> 300 | J11: =IF($A11<VARIABLES!$B$28,0,(IF($A11=VARIABLES!$B$28,0,K10)+H11)*C11*VARIABLES!$B$32) -> 1306.4344 | K11: =IF($A11<VARIABLES!$B$28,0,(IF($A11=VARIABLES!$B$28,0,K10)+H11)*(1+C11)-J11) -> 325302.17 | L11: =IF($A11<VARIABLES!$B$35,0,IF($A11=VARIABLES!$B$35,VARIABLES!$B$36+VARIABLES!$B$37,VARIABLES!$B$37)) -> 0 | M11: =L11*VARIABLES!$B$38 -> 0 | N11: =IF($A11<VARIABLES!$B$35,0,(IF($A11=VARIABLES!$B$35,0,O10)+L11)*C11*VARIABLES!$B$39) -> 25982.886 | O11: =IF($A11<VARIABLES!$B$35,0,(IF($A11=VARIABLES!$B$35,0,O10)+L11)*(1+C11)-N11) -> 6469738.7 | P11: =IF($A11<VARIABLES!$B$42,0,IF($A11=VARIABLES!$B$42,VARIABLES!$B$43+VARIABLES!$B$44,VARIABLES!$B$44)) -> 20000 | Q11: =P11*VARIABLES!$B$45 -> 150 | R11: =IF($A11<VARIABLES!$B$42,0,(IF($A11=VARIABLES!$B$42,0,S10)+P11)*C11*VARIABLES!$B$46) -> 164.86028 | S11: =IF($A11<VARIABLES!$B$42,0,(IF($A11=VARIABLES!$B$42,0,S10)+P11)*(1+C11)-R11) -> 164695.42 | T11: =IF($A11<VARIABLES!$B$50,0,MIN(VARIABLES!$B$49,INT(($A11-VARIABLES!$B$50)/VARIABLES!$B$51)+1)) -> 5 | U11: =T11*VARIABLES!$B$53+IF(AND($A11>=VARIABLES!$B$50,MOD($A11-VARIABLES!$B$50,VARIABLES!$B$51)=0,($A11-VARIABLES!$B$50)/VARIABLES!$B$51<VARIABLES!$B$49),VARIABLES!$B$52,0) -> 75000 | V11: =U11*VARIABLES!$B$54 -> 562.5 | W11: =IF($A11<VARIABLES!$B$50,0,(IF($A11<VARIABLES!$B$50+1,0,X10)+U11)*C11*VARIABLES!$B$55) -> 1451.3478 | X11: =IF($A11<VARIABLES!$B$50,0,(IF($A11<VARIABLES!$B$50+1,0,X10)+U11)*(1+C11)-W11) -> 361385.6 | Y11: =D11+H11+L11+P11+U11 -> 335000 | Z11: =E11+I11+M11+Q11+V11 -> 2512.5 | AA11: =F11+J11+N11+R11+W11 -> 31242.401 | AB11: =Z11+AA11 -> 33754.901 | AC11: =G11+K11+O11+S11+X11 -> 9655657.4 | AD11: =IF($A11=1,VARIABLES!$B$12,0) -> 0 | AE11: =IF($A11<=3,VARIABLES!$B$13,IF($A11<=6,VARIABLES!$B$14,VARIABLES!$B$15)) -> 40000 | AF11: =IF(MOD($A11,12)=0,AC11*VARIABLES!$B$16,0) -> 0 | AG11: =VARIABLES!$B$17 -> 5000 | AH11: =IF(MOD($A11,12)=0,VARIABLES!$B$18,0) -> 0 | AI11: =AD11+AE11+AF11+AG11+AH11 -> 45000 | AJ11: =IF($A11<VARIABLES!$B$7,VARIABLES!$B$9,0) -> 26583.333 | AK11: =AB11-AI11-AJ11 -> -37828.432 | AL11: =AL10+AK11 -> -291173.3 | AM11: =AM10+AJ11 -> 212666.67
A12: 9 | B12: =TEXT(DATE(VARIABLES!$B$59+INT((VARIABLES!$B$60+A12-2)/12),MOD(VARIABLES!$B$60+A12-2,12)+1,1),"mmm-yy") -> Feb-27 | C12: =IF($A12<VARIABLES!$B$7,VARIABLES!$B$5/12,VARIABLES!$B$6/12) -> 0.041666667 | D12: =IF($A12<VARIABLES!$B$21,0,IF($A12=VARIABLES!$B$21,VARIABLES!$B$22+VARIABLES!$B$23,VARIABLES!$B$23)) -> 200000 | E12: =D12*VARIABLES!$B$24 -> 1500 | F12: =IF($A12<VARIABLES!$B$21,0,(IF($A12=VARIABLES!$B$21,0,G11)+D12)*C12*VARIABLES!$B$25) -> 2640.1411 | G12: =IF($A12<VARIABLES!$B$21,0,(IF($A12=VARIABLES!$B$21,0,G11)+D12)*(1+C12)-F12) -> 2637501 | H12: =IF($A12<VARIABLES!$B$28,0,IF($A12=VARIABLES!$B$28,VARIABLES!$B$29+VARIABLES!$B$30,VARIABLES!$B$30)) -> 40000 | I12: =H12*VARIABLES!$B$31 -> 300 | J12: =IF($A12<VARIABLES!$B$28,0,(IF($A12=VARIABLES!$B$28,0,K11)+H12)*C12*VARIABLES!$B$32) -> 1522.0924 | K12: =IF($A12<VARIABLES!$B$28,0,(IF($A12=VARIABLES!$B$28,0,K11)+H12)*(1+C12)-J12) -> 379001 | L12: =IF($A12<VARIABLES!$B$35,0,IF($A12=VARIABLES!$B$35,VARIABLES!$B$36+VARIABLES!$B$37,VARIABLES!$B$37)) -> 0 | M12: =L12*VARIABLES!$B$38 -> 0 | N12: =IF($A12<VARIABLES!$B$35,0,(IF($A12=VARIABLES!$B$35,0,O11)+L12)*C12*VARIABLES!$B$39) -> 26957.245 | O12: =IF($A12<VARIABLES!$B$35,0,(IF($A12=VARIABLES!$B$35,0,O11)+L12)*(1+C12)-N12) -> 6712353.9 | P12: =IF($A12<VARIABLES!$B$42,0,IF($A12=VARIABLES!$B$42,VARIABLES!$B$43+VARIABLES!$B$44,VARIABLES!$B$44)) -> 20000 | Q12: =P12*VARIABLES!$B$45 -> 150 | R12: =IF($A12<VARIABLES!$B$42,0,(IF($A12=VARIABLES!$B$42,0,S11)+P12)*C12*VARIABLES!$B$46) -> 192.39106 | S12: =IF($A12<VARIABLES!$B$42,0,(IF($A12=VARIABLES!$B$42,0,S11)+P12)*(1+C12)-R12) -> 192198.67 | T12: =IF($A12<VARIABLES!$B$50,0,MIN(VARIABLES!$B$49,INT(($A12-VARIABLES!$B$50)/VARIABLES!$B$51)+1)) -> 6 | U12: =T12*VARIABLES!$B$53+IF(AND($A12>=VARIABLES!$B$50,MOD($A12-VARIABLES!$B$50,VARIABLES!$B$51)=0,($A12-VARIABLES!$B$50)/VARIABLES!$B$51<VARIABLES!$B$49),VARIABLES!$B$52,0) -> 80000 | V12: =U12*VARIABLES!$B$54 -> 600 | W12: =IF($A12<VARIABLES!$B$50,0,(IF($A12<VARIABLES!$B$50+1,0,X11)+U12)*C12*VARIABLES!$B$55) -> 1839.1067 | X12: =IF($A12<VARIABLES!$B$50,0,(IF($A12<VARIABLES!$B$50+1,0,X11)+U12)*(1+C12)-W12) -> 457937.56 | Y12: =D12+H12+L12+P12+U12 -> 340000 | Z12: =E12+I12+M12+Q12+V12 -> 2550 | AA12: =F12+J12+N12+R12+W12 -> 33150.976 | AB12: =Z12+AA12 -> 35700.976 | AC12: =G12+K12+O12+S12+X12 -> 10378992 | AD12: =IF($A12=1,VARIABLES!$B$12,0) -> 0 | AE12: =IF($A12<=3,VARIABLES!$B$13,IF($A12<=6,VARIABLES!$B$14,VARIABLES!$B$15)) -> 40000 | AF12: =IF(MOD($A12,12)=0,AC12*VARIABLES!$B$16,0) -> 0 | AG12: =VARIABLES!$B$17 -> 5000 | AH12: =IF(MOD($A12,12)=0,VARIABLES!$B$18,0) -> 0 | AI12: =AD12+AE12+AF12+AG12+AH12 -> 45000 | AJ12: =IF($A12<VARIABLES!$B$7,VARIABLES!$B$9,0) -> 26583.333 | AK12: =AB12-AI12-AJ12 -> -35882.357 | AL12: =AL11+AK12 -> -327055.65 | AM12: =AM11+AJ12 -> 239250
A13: 10 | B13: =TEXT(DATE(VARIABLES!$B$59+INT((VARIABLES!$B$60+A13-2)/12),MOD(VARIABLES!$B$60+A13-2,12)+1,1),"mmm-yy") -> Mar-27 | C13: =IF($A13<VARIABLES!$B$7,VARIABLES!$B$5/12,VARIABLES!$B$6/12) -> 0.041666667 | D13: =IF($A13<VARIABLES!$B$21,0,IF($A13=VARIABLES!$B$21,VARIABLES!$B$22+VARIABLES!$B$23,VARIABLES!$B$23)) -> 200000 | E13: =D13*VARIABLES!$B$24 -> 1500 | F13: =IF($A13<VARIABLES!$B$21,0,(IF($A13=VARIABLES!$B$21,0,G12)+D13)*C13*VARIABLES!$B$25) -> 2955.7302 | G13: =IF($A13<VARIABLES!$B$21,0,(IF($A13=VARIABLES!$B$21,0,G12)+D13)*(1+C13)-F13) -> 2952774.4 | H13: =IF($A13<VARIABLES!$B$28,0,IF($A13=VARIABLES!$B$28,VARIABLES!$B$29+VARIABLES!$B$30,VARIABLES!$B$30)) -> 40000 | I13: =H13*VARIABLES!$B$31 -> 300 | J13: =IF($A13<VARIABLES!$B$28,0,(IF($A13=VARIABLES!$B$28,0,K12)+H13)*C13*VARIABLES!$B$32) -> 1745.8375 | K13: =IF($A13<VARIABLES!$B$28,0,(IF($A13=VARIABLES!$B$28,0,K12)+H13)*(1+C13)-J13) -> 434713.54 | L13: =IF($A13<VARIABLES!$B$35,0,IF($A13=VARIABLES!$B$35,VARIABLES!$B$36+VARIABLES!$B$37,VARIABLES!$B$37)) -> 0 | M13: =L13*VARIABLES!$B$38 -> 0 | N13: =IF($A13<VARIABLES!$B$35,0,(IF($A13=VARIABLES!$B$35,0,O12)+L13)*C13*VARIABLES!$B$39) -> 27968.141 | O13: =IF($A13<VARIABLES!$B$35,0,(IF($A13=VARIABLES!$B$35,0,O12)+L13)*(1+C13)-N13) -> 6964067.2 | P13: =IF($A13<VARIABLES!$B$42,0,IF($A13=VARIABLES!$B$42,VARIABLES!$B$43+VARIABLES!$B$44,VARIABLES!$B$44)) -> 20000 | Q13: =P13*VARIABLES!$B$45 -> 150 | R13: =IF($A13<VARIABLES!$B$42,0,(IF($A13=VARIABLES!$B$42,0,S12)+P13)*C13*VARIABLES!$B$46) -> 221.04028 | S13: =IF($A13<VARIABLES!$B$42,0,(IF($A13=VARIABLES!$B$42,0,S12)+P13)*(1+C13)-R13) -> 220819.24 | T13: =IF($A13<VARIABLES!$B$50,0,MIN(VARIABLES!$B$49,INT(($A13-VARIABLES!$B$50)/VARIABLES!$B$51)+1)) -> 7 | U13: =T13*VARIABLES!$B$53+IF(AND($A13>=VARIABLES!$B$50,MOD($A13-VARIABLES!$B$50,VARIABLES!$B$51)=0,($A13-VARIABLES!$B$50)/VARIABLES!$B$51<VARIABLES!$B$49),VARIABLES!$B$52,0) -> 85000 | V13: =U13*VARIABLES!$B$54 -> 637.5 | W13: =IF($A13<VARIABLES!$B$50,0,(IF($A13<VARIABLES!$B$50+1,0,X12)+U13)*C13*VARIABLES!$B$55) -> 2262.2398 | X13: =IF($A13<VARIABLES!$B$50,0,(IF($A13<VARIABLES!$B$50+1,0,X12)+U13)*(1+C13)-W13) -> 563297.72 | Y13: =D13+H13+L13+P13+U13 -> 345000 | Z13: =E13+I13+M13+Q13+V13 -> 2587.5 | AA13: =F13+J13+N13+R13+W13 -> 35152.989 | AB13: =Z13+AA13 -> 37740.489 | AC13: =G13+K13+O13+S13+X13 -> 11135672 | AD13: =IF($A13=1,VARIABLES!$B$12,0) -> 0 | AE13: =IF($A13<=3,VARIABLES!$B$13,IF($A13<=6,VARIABLES!$B$14,VARIABLES!$B$15)) -> 40000 | AF13: =IF(MOD($A13,12)=0,AC13*VARIABLES!$B$16,0) -> 0 | AG13: =VARIABLES!$B$17 -> 5000 | AH13: =IF(MOD($A13,12)=0,VARIABLES!$B$18,0) -> 0 | AI13: =AD13+AE13+AF13+AG13+AH13 -> 45000 | AJ13: =IF($A13<VARIABLES!$B$7,VARIABLES!$B$9,0) -> 26583.333 | AK13: =AB13-AI13-AJ13 -> -33842.844 | AL13: =AL12+AK13 -> -360898.5 | AM13: =AM12+AJ13 -> 265833.33
A14: 11 | B14: =TEXT(DATE(VARIABLES!$B$59+INT((VARIABLES!$B$60+A14-2)/12),MOD(VARIABLES!$B$60+A14-2,12)+1,1),"mmm-yy") -> Apr-27 | C14: =IF($A14<VARIABLES!$B$7,VARIABLES!$B$5/12,VARIABLES!$B$6/12) -> 0.041666667 | D14: =IF($A14<VARIABLES!$B$21,0,IF($A14=VARIABLES!$B$21,VARIABLES!$B$22+VARIABLES!$B$23,VARIABLES!$B$23)) -> 200000 | E14: =D14*VARIABLES!$B$24 -> 1500 | F14: =IF($A14<VARIABLES!$B$21,0,(IF($A14=VARIABLES!$B$21,0,G13)+D14)*C14*VARIABLES!$B$25) -> 3284.14 | G14: =IF($A14<VARIABLES!$B$21,0,(IF($A14=VARIABLES!$B$21,0,G13)+D14)*(1+C14)-F14) -> 3280855.9 | H14: =IF($A14<VARIABLES!$B$28,0,IF($A14=VARIABLES!$B$28,VARIABLES!$B$29+VARIABLES!$B$30,VARIABLES!$B$30)) -> 40000 | I14: =H14*VARIABLES!$B$31 -> 300 | J14: =IF($A14<VARIABLES!$B$28,0,(IF($A14=VARIABLES!$B$28,0,K13)+H14)*C14*VARIABLES!$B$32) -> 1977.9731 | K14: =IF($A14<VARIABLES!$B$28,0,(IF($A14=VARIABLES!$B$28,0,K13)+H14)*(1+C14)-J14) -> 492515.3 | L14: =IF($A14<VARIABLES!$B$35,0,IF($A14=VARIABLES!$B$35,VARIABLES!$B$36+VARIABLES!$B$37,VARIABLES!$B$37)) -> 0 | M14: =L14*VARIABLES!$B$38 -> 0 | N14: =IF($A14<VARIABLES!$B$35,0,(IF($A14=VARIABLES!$B$35,0,O13)+L14)*C14*VARIABLES!$B$39) -> 29016.947 | O14: =IF($A14<VARIABLES!$B$35,0,(IF($A14=VARIABLES!$B$35,0,O13)+L14)*(1+C14)-N14) -> 7225219.7 | P14: =IF($A14<VARIABLES!$B$42,0,IF($A14=VARIABLES!$B$42,VARIABLES!$B$43+VARIABLES!$B$44,VARIABLES!$B$44)) -> 20000 | Q14: =P14*VARIABLES!$B$45 -> 150 | R14: =IF($A14<VARIABLES!$B$42,0,(IF($A14=VARIABLES!$B$42,0,S13)+P14)*C14*VARIABLES!$B$46) -> 250.85337 | S14: =IF($A14<VARIABLES!$B$42,0,(IF($A14=VARIABLES!$B$42,0,S13)+P14)*(1+C14)-R14) -> 250602.52 | T14: =IF($A14<VARIABLES!$B$50,0,MIN(VARIABLES!$B$49,INT(($A14-VARIABLES!$B$50)/VARIABLES!$B$51)+1)) -> 8 | U14: =T14*VARIABLES!$B$53+IF(AND($A14>=VARIABLES!$B$50,MOD($A14-VARIABLES!$B$50,VARIABLES!$B$51)=0,($A14-VARIABLES!$B$50)/VARIABLES!$B$51<VARIABLES!$B$49),VARIABLES!$B$52,0) -> 90000 | V14: =U14*VARIABLES!$B$54 -> 675 | W14: =IF($A14<VARIABLES!$B$50,0,(IF($A14<VARIABLES!$B$50+1,0,X13)+U14)*C14*VARIABLES!$B$55) -> 2722.0738 | X14: =IF($A14<VARIABLES!$B$50,0,(IF($A14<VARIABLES!$B$50+1,0,X13)+U14)*(1+C14)-W14) -> 677796.38 | Y14: =D14+H14+L14+P14+U14 -> 350000 | Z14: =E14+I14+M14+Q14+V14 -> 2625 | AA14: =F14+J14+N14+R14+W14 -> 37251.987 | AB14: =Z14+AA14 -> 39876.987 | AC14: =G14+K14+O14+S14+X14 -> 11926990 | AD14: =IF($A14=1,VARIABLES!$B$12,0) -> 0 | AE14: =IF($A14<=3,VARIABLES!$B$13,IF($A14<=6,VARIABLES!$B$14,VARIABLES!$B$15)) -> 40000 | AF14: =IF(MOD($A14,12)=0,AC14*VARIABLES!$B$16,0) -> 0 | AG14: =VARIABLES!$B$17 -> 5000 | AH14: =IF(MOD($A14,12)=0,VARIABLES!$B$18,0) -> 0 | AI14: =AD14+AE14+AF14+AG14+AH14 -> 45000 | AJ14: =IF($A14<VARIABLES!$B$7,VARIABLES!$B$9,0) -> 26583.333 | AK14: =AB14-AI14-AJ14 -> -31706.346 | AL14: =AL13+AK14 -> -392604.84 | AM14: =AM13+AJ14 -> 292416.67
A15: 12 | B15: =TEXT(DATE(VARIABLES!$B$59+INT((VARIABLES!$B$60+A15-2)/12),MOD(VARIABLES!$B$60+A15-2,12)+1,1),"mmm-yy") -> May-27 | C15: =IF($A15<VARIABLES!$B$7,VARIABLES!$B$5/12,VARIABLES!$B$6/12) -> 0.041666667 | D15: =IF($A15<VARIABLES!$B$21,0,IF($A15=VARIABLES!$B$21,VARIABLES!$B$22+VARIABLES!$B$23,VARIABLES!$B$23)) -> 200000 | E15: =D15*VARIABLES!$B$24 -> 1500 | F15: =IF($A15<VARIABLES!$B$21,0,(IF($A15=VARIABLES!$B$21,0,G14)+D15)*C15*VARIABLES!$B$25) -> 3625.8916 | G15: =IF($A15<VARIABLES!$B$21,0,(IF($A15=VARIABLES!$B$21,0,G14)+D15)*(1+C15)-F15) -> 3622265.7 | H15: =IF($A15<VARIABLES!$B$28,0,IF($A15=VARIABLES!$B$28,VARIABLES!$B$29+VARIABLES!$B$30,VARIABLES!$B$30)) -> 40000 | I15: =H15*VARIABLES!$B$31 -> 300 | J15: =IF($A15<VARIABLES!$B$28,0,(IF($A15=VARIABLES!$B$28,0,K14)+H15)*C15*VARIABLES!$B$32) -> 2218.8137 | K15: =IF($A15<VARIABLES!$B$28,0,(IF($A15=VARIABLES!$B$28,0,K14)+H15)*(1+C15)-J15) -> 552484.62 | L15: =IF($A15<VARIABLES!$B$35,0,IF($A15=VARIABLES!$B$35,VARIABLES!$B$36+VARIABLES!$B$37,VARIABLES!$B$37)) -> 0 | M15: =L15*VARIABLES!$B$38 -> 0 | N15: =IF($A15<VARIABLES!$B$35,0,(IF($A15=VARIABLES!$B$35,0,O14)+L15)*C15*VARIABLES!$B$39) -> 30105.082 | O15: =IF($A15<VARIABLES!$B$35,0,(IF($A15=VARIABLES!$B$35,0,O14)+L15)*(1+C15)-N15) -> 7496165.5 | P15: =IF($A15<VARIABLES!$B$42,0,IF($A15=VARIABLES!$B$42,VARIABLES!$B$43+VARIABLES!$B$44,VARIABLES!$B$44)) -> 20000 | Q15: =P15*VARIABLES!$B$45 -> 150 | R15: =IF($A15<VARIABLES!$B$42,0,(IF($A15=VARIABLES!$B$42,0,S14)+P15)*C15*VARIABLES!$B$46) -> 281.87763 | S15: =IF($A15<VARIABLES!$B$42,0,(IF($A15=VARIABLES!$B$42,0,S14)+P15)*(1+C15)-R15) -> 281595.75 | T15: =IF($A15<VARIABLES!$B$50,0,MIN(VARIABLES!$B$49,INT(($A15-VARIABLES!$B$50)/VARIABLES!$B$51)+1)) -> 9 | U15: =T15*VARIABLES!$B$53+IF(AND($A15>=VARIABLES!$B$50,MOD($A15-VARIABLES!$B$50,VARIABLES!$B$51)=0,($A15-VARIABLES!$B$50)/VARIABLES!$B$51<VARIABLES!$B$49),VARIABLES!$B$52,0) -> 95000 | V15: =U15*VARIABLES!$B$54 -> 712.5 | W15: =IF($A15<VARIABLES!$B$50,0,(IF($A15<VARIABLES!$B$50+1,0,X14)+U15)*C15*VARIABLES!$B$55) -> 3219.9849 | X15: =IF($A15<VARIABLES!$B$50,0,(IF($A15<VARIABLES!$B$50+1,0,X14)+U15)*(1+C15)-W15) -> 801776.25 | Y15: =D15+H15+L15+P15+U15 -> 355000 | Z15: =E15+I15+M15+Q15+V15 -> 2662.5 | AA15: =F15+J15+N15+R15+W15 -> 39451.65 | AB15: =Z15+AA15 -> 42114.15 | AC15: =G15+K15+O15+S15+X15 -> 12754288 | AD15: =IF($A15=1,VARIABLES!$B$12,0) -> 0 | AE15: =IF($A15<=3,VARIABLES!$B$13,IF($A15<=6,VARIABLES!$B$14,VARIABLES!$B$15)) -> 40000 | AF15: =IF(MOD($A15,12)=0,AC15*VARIABLES!$B$16,0) -> 31885.719 | AG15: =VARIABLES!$B$17 -> 5000 | AH15: =IF(MOD($A15,12)=0,VARIABLES!$B$18,0) -> 3000 | AI15: =AD15+AE15+AF15+AG15+AH15 -> 79885.719 | AJ15: =IF($A15<VARIABLES!$B$7,VARIABLES!$B$9,0) -> 26583.333 | AK15: =AB15-AI15-AJ15 -> -64354.903 | AL15: =AL14+AK15 -> -456959.75 | AM15: =AM14+AJ15 -> 319000
A16: 13 | B16: =TEXT(DATE(VARIABLES!$B$59+INT((VARIABLES!$B$60+A16-2)/12),MOD(VARIABLES!$B$60+A16-2,12)+1,1),"mmm-yy") -> Jun-27 | C16: =IF($A16<VARIABLES!$B$7,VARIABLES!$B$5/12,VARIABLES!$B$6/12) -> 0.041666667 | D16: =IF($A16<VARIABLES!$B$21,0,IF($A16=VARIABLES!$B$21,VARIABLES!$B$22+VARIABLES!$B$23,VARIABLES!$B$23)) -> 200000 | E16: =D16*VARIABLES!$B$24 -> 1500 | F16: =IF($A16<VARIABLES!$B$21,0,(IF($A16=VARIABLES!$B$21,0,G15)+D16)*C16*VARIABLES!$B$25) -> 3981.5267 | G16: =IF($A16<VARIABLES!$B$21,0,(IF($A16=VARIABLES!$B$21,0,G15)+D16)*(1+C16)-F16) -> 3977545.2 | H16: =IF($A16<VARIABLES!$B$28,0,IF($A16=VARIABLES!$B$28,VARIABLES!$B$29+VARIABLES!$B$30,VARIABLES!$B$30)) -> 40000 | I16: =H16*VARIABLES!$B$31 -> 300 | J16: =IF($A16<VARIABLES!$B$28,0,(IF($A16=VARIABLES!$B$28,0,K15)+H16)*C16*VARIABLES!$B$32) -> 2468.6859 | K16: =IF($A16<VARIABLES!$B$28,0,(IF($A16=VARIABLES!$B$28,0,K15)+H16)*(1+C16)-J16) -> 614702.79 | L16: =IF($A16<VARIABLES!$B$35,0,IF($A16=VARIABLES!$B$35,VARIABLES!$B$36+VARIABLES!$B$37,VARIABLES!$B$37)) -> 0 | M16: =L16*VARIABLES!$B$38 -> 0 | N16: =IF($A16<VARIABLES!$B$35,0,(IF($A16=VARIABLES!$B$35,0,O15)+L16)*C16*VARIABLES!$B$39) -> 31234.023 | O16: =IF($A16<VARIABLES!$B$35,0,(IF($A16=VARIABLES!$B$35,0,O15)+L16)*(1+C16)-N16) -> 7777271.7 | P16: =IF($A16<VARIABLES!$B$42,0,IF($A16=VARIABLES!$B$42,VARIABLES!$B$43+VARIABLES!$B$44,VARIABLES!$B$44)) -> 20000 | Q16: =P16*VARIABLES!$B$45 -> 150 | R16: =IF($A16<VARIABLES!$B$42,0,(IF($A16=VARIABLES!$B$42,0,S15)+P16)*C16*VARIABLES!$B$46) -> 314.16224 | S16: =IF($A16<VARIABLES!$B$42,0,(IF($A16=VARIABLES!$B$42,0,S15)+P16)*(1+C16)-R16) -> 313848.08 | T16: =IF($A16<VARIABLES!$B$50,0,MIN(VARIABLES!$B$49,INT(($A16-VARIABLES!$B$50)/VARIABLES!$B$51)+1)) -> 10 | U16: =T16*VARIABLES!$B$53+IF(AND($A16>=VARIABLES!$B$50,MOD($A16-VARIABLES!$B$50,VARIABLES!$B$51)=0,($A16-VARIABLES!$B$50)/VARIABLES!$B$51<VARIABLES!$B$49),VARIABLES!$B$52,0) -> 100000 | V16: =U16*VARIABLES!$B$54 -> 750 | W16: =IF($A16<VARIABLES!$B$50,0,(IF($A16<VARIABLES!$B$50+1,0,X15)+U16)*C16*VARIABLES!$B$55) -> 3757.401 | X16: =IF($A16<VARIABLES!$B$50,0,(IF($A16<VARIABLES!$B$50+1,0,X15)+U16)*(1+C16)-W16) -> 935592.85 | Y16: =D16+H16+L16+P16+U16 -> 360000 | Z16: =E16+I16+M16+Q16+V16 -> 2700 | AA16: =F16+J16+N16+R16+W16 -> 41755.799 | AB16: =Z16+AA16 -> 44455.799 | AC16: =G16+K16+O16+S16+X16 -> 13618961 | AD16: =IF($A16=1,VARIABLES!$B$12,0) -> 0 | AE16: =IF($A16<=3,VARIABLES!$B$13,IF($A16<=6,VARIABLES!$B$14,VARIABLES!$B$15)) -> 40000 | AF16: =IF(MOD($A16,12)=0,AC16*VARIABLES!$B$16,0) -> 0 | AG16: =VARIABLES!$B$17 -> 5000 | AH16: =IF(MOD($A16,12)=0,VARIABLES!$B$18,0) -> 0 | AI16: =AD16+AE16+AF16+AG16+AH16 -> 45000 | AJ16: =IF($A16<VARIABLES!$B$7,VARIABLES!$B$9,0) -> 26583.333 | AK16: =AB16-AI16-AJ16 -> -27127.535 | AL16: =AL15+AK16 -> -484087.28 | AM16: =AM15+AJ16 -> 345583.33
... A51: 48 | B51: =TEXT(DATE(VARIABLES!$B$59+INT((VARIABLES!$B$60+A51-2)/12),MOD(VARIABLES!$B$60+A51-2,12)+1,1),"mmm-yy") -> May-30 | C51: =IF($A51<VARIABLES!$B$7,VARIABLES!$B$5/12,VARIABLES!$B$6/12) -> 0.0083333333 | D51: =IF($A51<VARIABLES!$B$21,0,IF($A51=VARIABLES!$B$21,VARIABLES!$B$22+VARIABLES!$B$23,VARIABLES!$B$23)) -> 200000 | E51: =D51*VARIABLES!$B$24 -> 1500 | F51: =IF($A51<VARIABLES!$B$21,0,(IF($A51=VARIABLES!$B$21,0,G50)+D51)*C51*VARIABLES!$B$25) -> 4535.4102 | G51: =IF($A51<VARIABLES!$B$21,0,(IF($A51=VARIABLES!$B$21,0,G50)+D51)*(1+C51)-F51) -> 21946850 | H51: =IF($A51<VARIABLES!$B$28,0,IF($A51=VARIABLES!$B$28,VARIABLES!$B$29+VARIABLES!$B$30,VARIABLES!$B$30)) -> 40000 | I51: =H51*VARIABLES!$B$31 -> 300 | J51: =IF($A51<VARIABLES!$B$28,0,(IF($A51=VARIABLES!$B$28,0,K50)+H51)*C51*VARIABLES!$B$32) -> 3047.4367 | K51: =IF($A51<VARIABLES!$B$28,0,(IF($A51=VARIABLES!$B$28,0,K50)+H51)*(1+C51)-J51) -> 3684351 | L51: =IF($A51<VARIABLES!$B$35,0,IF($A51=VARIABLES!$B$35,VARIABLES!$B$36+VARIABLES!$B$37,VARIABLES!$B$37)) -> 0 | M51: =L51*VARIABLES!$B$38 -> 0 | N51: =IF($A51<VARIABLES!$B$35,0,(IF($A51=VARIABLES!$B$35,0,O50)+L51)*C51*VARIABLES!$B$39) -> 16408.469 | O51: =IF($A51<VARIABLES!$B$35,0,(IF($A51=VARIABLES!$B$35,0,O50)+L51)*(1+C51)-N51) -> 19837839 | P51: =IF($A51<VARIABLES!$B$42,0,IF($A51=VARIABLES!$B$42,VARIABLES!$B$43+VARIABLES!$B$44,VARIABLES!$B$44)) -> 20000 | Q51: =P51*VARIABLES!$B$45 -> 150 | R51: =IF($A51<VARIABLES!$B$42,0,(IF($A51=VARIABLES!$B$42,0,S50)+P51)*C51*VARIABLES!$B$46) -> 405.79027 | S51: =IF($A51<VARIABLES!$B$42,0,(IF($A51=VARIABLES!$B$42,0,S50)+P51)*(1+C51)-R51) -> 1963619.1 | T51: =IF($A51<VARIABLES!$B$50,0,MIN(VARIABLES!$B$49,INT(($A51-VARIABLES!$B$50)/VARIABLES!$B$51)+1)) -> 12 | U51: =T51*VARIABLES!$B$53+IF(AND($A51>=VARIABLES!$B$50,MOD($A51-VARIABLES!$B$50,VARIABLES!$B$51)=0,($A51-VARIABLES!$B$50)/VARIABLES!$B$51<VARIABLES!$B$49),VARIABLES!$B$52,0) -> 60000 | V51: =U51*VARIABLES!$B$54 -> 450 | W51: =IF($A51<VARIABLES!$B$50,0,(IF($A51<VARIABLES!$B$50+1,0,X50)+U51)*C51*VARIABLES!$B$55) -> 4796.3368 | X51: =IF($A51<VARIABLES!$B$50,0,(IF($A51<VARIABLES!$B$50+1,0,X50)+U51)*(1+C51)-W51) -> 5798771.2 | Y51: =D51+H51+L51+P51+U51 -> 320000 | Z51: =E51+I51+M51+Q51+V51 -> 2400 | AA51: =F51+J51+N51+R51+W51 -> 29193.443 | AB51: =Z51+AA51 -> 31593.443 | AC51: =G51+K51+O51+S51+X51 -> 53231430 | AD51: =IF($A51=1,VARIABLES!$B$12,0) -> 0 | AE51: =IF($A51<=3,VARIABLES!$B$13,IF($A51<=6,VARIABLES!$B$14,VARIABLES!$B$15)) -> 40000 | AF51: =IF(MOD($A51,12)=0,AC51*VARIABLES!$B$16,0) -> 133078.57 | AG51: =VARIABLES!$B$17 -> 5000 | AH51: =IF(MOD($A51,12)=0,VARIABLES!$B$18,0) -> 3000 | AI51: =AD51+AE51+AF51+AG51+AH51 -> 181078.57 | AJ51: =IF($A51<VARIABLES!$B$7,VARIABLES!$B$9,0) -> 0 | AK51: =AB51-AI51-AJ51 -> -149485.13 | AL51: =AL50+AK51 -> -775406.19 | AM51: =AM50+AJ51 -> 957000
A52: TOTAL / FINAL | Y52: =SUM(Y4:Y51) -> 20690000 | Z52: =SUM(Z4:Z51) -> 155175 | AA52: =SUM(AA4:AA51) -> 2498580.3 | AB52: =SUM(AB4:AB51) -> 2653755.3 | AC52: =AC51 -> 53231430 | AD52: =SUM(AD4:AD51) -> 50000 | AE52: =SUM(AE4:AE51) -> 1830000 | AF52: =SUM(AF4:AF51) -> 340161.51 | AG52: =SUM(AG4:AG51) -> 240000 | AH52: =SUM(AH4:AH51) -> 12000 | AI52: =SUM(AI4:AI51) -> 2472161.5 | AJ52: =SUM(AJ4:AJ51) -> 957000 | AK52: =SUM(AK4:AK51) -> -775406.19 | AL52: =AL51 -> -775406.19 | AM52: =AM51 -> 957000
A54: NOTES: ① Detail columns (Clients 1-4 + New Clients) are hidden — click the [+] group toggle above column D to expand. ② Performance fee uses simplified monthly accrual (AUM × monthly_return × perf_rate) — closely approximates quarterly HWM crystallisation. ③ CAEP AUM fee (0.25%) billed annually in months 12, 24, 36, 48 on end-of-month AUM. ④ Reserve provision set aside monthly (Years 1–3) to fund Year 4 cash deficit; tracked in Reserve Fund Balance column. ⑤ Year 4 (months 37–48) assumes 0% portfolio return — no performance fees; reserve drawdown not automated (see Reserve Fund Bal vs cumulative deficit).

Sheet CHARTS
A1: BitWealth (Pty) Ltd — Cashflow Visual Summary
