Workbook

Sheet VARIABLES
A1: BitWealth (Pty) Ltd — Cashflow Model Variables [FINOVA CAPITAL VARIANT]
A2: v4.0 · 96-Month Forecast (8 Years) · Adjust YELLOW cells · Forecast tab auto-recalculates · FSP: FINOVA CAPITAL (rev-share)
A4: RETURN & PERFORMANCE ASSUMPTIONS
A5: Annual portfolio return — Years 1–3 (p.a.) | B5: 0.6 | C5: 60% p.a. BTC bull cycle (months 1 → y4_start-1); divided by 12 for monthly
A6: Annual portfolio return — Year 4 (p.a.) | B6: 0.1 | C6: 10% moderate/consolidation (months y4_start → y5_start-1)
A7: Year 4 starts (model month #) | B7: 37 | C7: Month 37 = July 2029
A8: Year 5 starts (model month #) | B8: 49 | C8: Month 49 = July 2030 — start of next BTC halving cycle
A9: Annual portfolio return — Years 5–8 (p.a.) | B9: 0.5 | C9: Next BTC bull cycle. Set to 0% for conservative Y5-8 assumption
A10: Performance fee crystallisation period (months) | B10: 12 | C10: 12 = annual crystallisation (simplified to monthly accrual in formulas)
A11: Monthly liquidity buffer provision (R) | B11: 10580 | C11: Set aside each month in Y1-3 to fund cash deficit in Y4; tracked in Reserve Fund Bal
A13: EXCHANGE FEE SHARE REVENUE (VALR revenue-share deal)
A14: VALR exchange fee rate per trade | B14: 0.001 | C14: 0.1% default. Covers ZAR/USDT, USDT/BTC, and USDT/USDPC conversions. Adjust if VALR rate changes
A15: BitWealth share of exchange fees | B15: 0.5 | C15: 50% — as negotiated with VALR. Revenue = total monthly contributions × fee_rate × this share
A17: FSP ARRANGEMENT — FINOVA CAPITAL (rev-share model)
A18: Performance fee share paid to Finova Capital | B18: 0.2 | C18: 20% of all performance fees earned by BitWealth. BitWealth retains 80%
A19: Platform fee share paid to Finova Capital | B19: 0.5 | C19: 50% of all platform fees earned by BitWealth. BitWealth retains 50%
A20: Software & infrastructure (monthly) | B20: 5000 | C20: Cloud, Supabase, VALR API, domain etc.
A21: Company secretarial (annual, months 12/24/36 …) | B21: 3000 | C21: CIPC annual return + company secretary
A23: CLIENT 1 (Founding — preferential 2.5% perf fee)
A24: Start month | B24: 1 | C24: Month 1 = June 2026
A25: Initial lump sum (R) | B25: 300000
A26: Monthly contribution (R) | B26: 200000
A27: Platform fee rate | B27: 0.0075 | C27: 0.75%
A28: Performance fee rate | B28: 0.025 | C28: 2.5% preferential
A30: CLIENT 2 (Founding)
A31: Start month | B31: 2 | C31: Month 2 = July 2026
A32: Initial lump sum (R) | B32: 0
A33: Monthly contribution (R) | B33: 40000
A34: Platform fee rate | B34: 0.0075
A35: Performance fee rate | B35: 0.1 | C35: Standard 10%
A37: CLIENT 3 (Founding — large lump sum, no monthly contributions)
A38: Start month | B38: 2 | C38: Month 2 = July 2026
A39: Initial lump sum (R) | B39: 5000000 | C39: 0.75% platform fee = R37 500 on day 1
A40: Monthly contribution (R) | B40: 0 | C40: No monthly contributions
A41: Platform fee rate | B41: 0.0075
A42: Performance fee rate | B42: 0.1
A44: CLIENT 4 (Founding — preferential 2.5% perf fee)
A45: Start month | B45: 2 | C45: Month 2 = July 2026
A46: Initial lump sum (R) | B46: 0
A47: Monthly contribution (R) | B47: 20000
...

Sheet MONTHLY FORECAST
A1: BitWealth (Pty) Ltd — 96-Month Cashflow Forecast v4.0 · FSP: FINOVA CAPITAL · All formulas auto-update when VARIABLES sheet changes
A2: PERIOD | D2: CLIENT DETAIL (hidden — click + to expand) | Y2: REVENUE | AD2: TOTAL AUM | AE2: COSTS | AK2: RESERVE | AL2: CASHFLOW
A3: Month # | B3: Month | C3: Monthly Return % | D3: C1 Contrib | E3: C1 Plat | F3: C1 Perf | G3: C1 AUM | H3: C2 Contrib | I3: C2 Plat | J3: C2 Perf | K3: C2 AUM | L3: C3 Contrib | M3: C3 Plat | N3: C3 Perf | O3: C3 AUM | P3: C4 Contrib | Q3: C4 Plat | R3: C4 Perf | S3: C4 AUM | T3: NC Clients | U3: NC Contrib | V3: NC Plat | W3: NC Perf | X3: NC AUM | Y3: Total Contrib | Z3: Total Plat Fee | AA3: Total Perf Fee | AB3: Exchange Fee Rev | AC3: TOTAL REVENUE | AD3: TOTAL AUM | AE3: Finova Setup (R0) | AF3: Finova Plat Share | AG3: Finova Perf Share | AH3: Software | AI3: Co Sec | AJ3: TOTAL COSTS | AK3: Reserve Provision | AL3: NET CASH (after reserve) | AM3: CUMULATIVE CASH | AN3: Reserve Fund Bal
A4: 1 | B4: =TEXT(DATE(VARIABLES!$B$63+INT((VARIABLES!$B$64+$A4-2)/12),MOD(VARIABLES!$B$64+$A4-2,12)+1,1),"mmm-yy") | C4: =IF($A4<VARIABLES!$B$7,VARIABLES!$B$5/12,IF($A4<VARIABLES!$B$8,VARIABLES!$B$6/12,VARIABLES!$B$9/12)) | D4: =IF($A4<VARIABLES!$B$24,0,IF($A4=VARIABLES!$B$24,VARIABLES!$B$25+VARIABLES!$B$26,VARIABLES!$B$26)) | E4: =D4*VARIABLES!$B$27 | F4: =IF($A4<VARIABLES!$B$24,0,(IF($A4=VARIABLES!$B$24,0,G3)+D4)*C4*VARIABLES!$B$28) | G4: =IF($A4<VARIABLES!$B$24,0,(IF($A4=VARIABLES!$B$24,0,G3)+D4)*(1+C4)-F4) | H4: =IF($A4<VARIABLES!$B$31,0,IF($A4=VARIABLES!$B$31,VARIABLES!$B$32+VARIABLES!$B$33,VARIABLES!$B$33)) | I4: =H4*VARIABLES!$B$34 | J4: =IF($A4<VARIABLES!$B$31,0,(IF($A4=VARIABLES!$B$31,0,K3)+H4)*C4*VARIABLES!$B$35) | K4: =IF($A4<VARIABLES!$B$31,0,(IF($A4=VARIABLES!$B$31,0,K3)+H4)*(1+C4)-J4) | L4: =IF($A4<VARIABLES!$B$38,0,IF($A4=VARIABLES!$B$38,VARIABLES!$B$39+VARIABLES!$B$40,VARIABLES!$B$40)) | M4: =L4*VARIABLES!$B$41 | N4: =IF($A4<VARIABLES!$B$38,0,(IF($A4=VARIABLES!$B$38,0,O3)+L4)*C4*VARIABLES!$B$42) | O4: =IF($A4<VARIABLES!$B$38,0,(IF($A4=VARIABLES!$B$38,0,O3)+L4)*(1+C4)-N4) | P4: =IF($A4<VARIABLES!$B$45,0,IF($A4=VARIABLES!$B$45,VARIABLES!$B$46+VARIABLES!$B$47,VARIABLES!$B$47)) | Q4: =P4*VARIABLES!$B$48 | R4: =IF($A4<VARIABLES!$B$45,0,(IF($A4=VARIABLES!$B$45,0,S3)+P4)*C4*VARIABLES!$B$49) | S4: =IF($A4<VARIABLES!$B$45,0,(IF($A4=VARIABLES!$B$45,0,S3)+P4)*(1+C4)-R4) | T4: =IF($A4<VARIABLES!$B$53,0,MIN(VARIABLES!$B$52,INT(($A4-VARIABLES!$B$53)/VARIABLES!$B$54)+1)*VARIABLES!$B$55) | U4: =T4*VARIABLES!$B$57+IF(AND($A4>=VARIABLES!$B$53,MOD($A4-VARIABLES!$B$53,VARIABLES!$B$54)=0,INT(($A4-VARIABLES!$B$53)/VARIABLES!$B$54)<VARIABLES!$B$52),VARIABLES!$B$55*VARIABLES!$B$56,0) | V4: =U4*VARIABLES!$B$58 | W4: =IF($A4<VARIABLES!$B$53,0,(IF($A4<VARIABLES!$B$53+1,0,X3)+U4)*C4*VARIABLES!$B$59) | X4: =IF($A4<VARIABLES!$B$53,0,(IF($A4<VARIABLES!$B$53+1,0,X3)+U4)*(1+C4)-W4) | Y4: =D4+H4+L4+P4+U4 | Z4: =E4+I4+M4+Q4+V4 | AA4: =F4+J4+N4+R4+W4 | AB4: =Y4*VARIABLES!$B$14*VARIABLES!$B$15 | AC4: =Z4+AA4+AB4 | AD4: =G4+K4+O4+S4+X4 | AE4: =0 | AF4: =Z4*VARIABLES!$B$19 | AG4: =AA4*VARIABLES!$B$18 | AH4: =VARIABLES!$B$20 | AI4: =IF(MOD($A4,12)=0,VARIABLES!$B$21,0) | AJ4: =AE4+AF4+AG4+AH4+AI4 | AK4: =IF($A4<VARIABLES!$B$7,VARIABLES!$B$11,0) | AL4: =AC4-AJ4-AK4 | AM4: =AL4 | AN4: =AK4
A5: 2 | B5: =TEXT(DATE(VARIABLES!$B$63+INT((VARIABLES!$B$64+$A5-2)/12),MOD(VARIABLES!$B$64+$A5-2,12)+1,1),"mmm-yy") | C5: =IF($A5<VARIABLES!$B$7,VARIABLES!$B$5/12,IF($A5<VARIABLES!$B$8,VARIABLES!$B$6/12,VARIABLES!$B$9/12)) | D5: =IF($A5<VARIABLES!$B$24,0,IF($A5=VARIABLES!$B$24,VARIABLES!$B$25+VARIABLES!$B$26,VARIABLES!$B$26)) | E5: =D5*VARIABLES!$B$27 | F5: =IF($A5<VARIABLES!$B$24,0,(IF($A5=VARIABLES!$B$24,0,G4)+D5)*C5*VARIABLES!$B$28) | G5: =IF($A5<VARIABLES!$B$24,0,(IF($A5=VARIABLES!$B$24,0,G4)+D5)*(1+C5)-F5) | H5: =IF($A5<VARIABLES!$B$31,0,IF($A5=VARIABLES!$B$31,VARIABLES!$B$32+VARIABLES!$B$33,VARIABLES!$B$33)) | I5: =H5*VARIABLES!$B$34 | J5: =IF($A5<VARIABLES!$B$31,0,(IF($A5=VARIABLES!$B$31,0,K4)+H5)*C5*VARIABLES!$B$35) | K5: =IF($A5<VARIABLES!$B$31,0,(IF($A5=VARIABLES!$B$31,0,K4)+H5)*(1+C5)-J5) | L5: =IF($A5<VARIABLES!$B$38,0,IF($A5=VARIABLES!$B$38,VARIABLES!$B$39+VARIABLES!$B$40,VARIABLES!$B$40)) | M5: =L5*VARIABLES!$B$41 | N5: =IF($A5<VARIABLES!$B$38,0,(IF($A5=VARIABLES!$B$38,0,O4)+L5)*C5*VARIABLES!$B$42) | O5: =IF($A5<VARIABLES!$B$38,0,(IF($A5=VARIABLES!$B$38,0,O4)+L5)*(1+C5)-N5) | P5: =IF($A5<VARIABLES!$B$45,0,IF($A5=VARIABLES!$B$45,VARIABLES!$B$46+VARIABLES!$B$47,VARIABLES!$B$47)) | Q5: =P5*VARIABLES!$B$48 | R5: =IF($A5<VARIABLES!$B$45,0,(IF($A5=VARIABLES!$B$45,0,S4)+P5)*C5*VARIABLES!$B$49) | S5: =IF($A5<VARIABLES!$B$45,0,(IF($A5=VARIABLES!$B$45,0,S4)+P5)*(1+C5)-R5) | T5: =IF($A5<VARIABLES!$B$53,0,MIN(VARIABLES!$B$52,INT(($A5-VARIABLES!$B$53)/VARIABLES!$B$54)+1)*VARIABLES!$B$55) | U5: =T5*VARIABLES!$B$57+IF(AND($A5>=VARIABLES!$B$53,MOD($A5-VARIABLES!$B$53,VARIABLES!$B$54)=0,INT(($A5-VARIABLES!$B$53)/VARIABLES!$B$54)<VARIABLES!$B$52),VARIABLES!$B$55*VARIABLES!$B$56,0) | V5: =U5*VARIABLES!$B$58 | W5: =IF($A5<VARIABLES!$B$53,0,(IF($A5<VARIABLES!$B$53+1,0,X4)+U5)*C5*VARIABLES!$B$59) | X5: =IF($A5<VARIABLES!$B$53,0,(IF($A5<VARIABLES!$B$53+1,0,X4)+U5)*(1+C5)-W5) | Y5: =D5+H5+L5+P5+U5 | Z5: =E5+I5+M5+Q5+V5 | AA5: =F5+J5+N5+R5+W5 | AB5: =Y5*VARIABLES!$B$14*VARIABLES!$B$15 | AC5: =Z5+AA5+AB5 | AD5: =G5+K5+O5+S5+X5 | AE5: =0 | AF5: =Z5*VARIABLES!$B$19 | AG5: =AA5*VARIABLES!$B$18 | AH5: =VARIABLES!$B$20 | AI5: =IF(MOD($A5,12)=0,VARIABLES!$B$21,0) | AJ5: =AE5+AF5+AG5+AH5+AI5 | AK5: =IF($A5<VARIABLES!$B$7,VARIABLES!$B$11,0) | AL5: =AC5-AJ5-AK5 | AM5: =AM4+AL5 | AN5: =AN4+AK5
A6: 3 | B6: =TEXT(DATE(VARIABLES!$B$63+INT((VARIABLES!$B$64+$A6-2)/12),MOD(VARIABLES!$B$64+$A6-2,12)+1,1),"mmm-yy") | C6: =IF($A6<VARIABLES!$B$7,VARIABLES!$B$5/12,IF($A6<VARIABLES!$B$8,VARIABLES!$B$6/12,VARIABLES!$B$9/12)) | D6: =IF($A6<VARIABLES!$B$24,0,IF($A6=VARIABLES!$B$24,VARIABLES!$B$25+VARIABLES!$B$26,VARIABLES!$B$26)) | E6: =D6*VARIABLES!$B$27 | F6: =IF($A6<VARIABLES!$B$24,0,(IF($A6=VARIABLES!$B$24,0,G5)+D6)*C6*VARIABLES!$B$28) | G6: =IF($A6<VARIABLES!$B$24,0,(IF($A6=VARIABLES!$B$24,0,G5)+D6)*(1+C6)-F6) | H6: =IF($A6<VARIABLES!$B$31,0,IF($A6=VARIABLES!$B$31,VARIABLES!$B$32+VARIABLES!$B$33,VARIABLES!$B$33)) | I6: =H6*VARIABLES!$B$34 | J6: =IF($A6<VARIABLES!$B$31,0,(IF($A6=VARIABLES!$B$31,0,K5)+H6)*C6*VARIABLES!$B$35) | K6: =IF($A6<VARIABLES!$B$31,0,(IF($A6=VARIABLES!$B$31,0,K5)+H6)*(1+C6)-J6) | L6: =IF($A6<VARIABLES!$B$38,0,IF($A6=VARIABLES!$B$38,VARIABLES!$B$39+VARIABLES!$B$40,VARIABLES!$B$40)) | M6: =L6*VARIABLES!$B$41 | N6: =IF($A6<VARIABLES!$B$38,0,(IF($A6=VARIABLES!$B$38,0,O5)+L6)*C6*VARIABLES!$B$42) | O6: =IF($A6<VARIABLES!$B$38,0,(IF($A6=VARIABLES!$B$38,0,O5)+L6)*(1+C6)-N6) | P6: =IF($A6<VARIABLES!$B$45,0,IF($A6=VARIABLES!$B$45,VARIABLES!$B$46+VARIABLES!$B$47,VARIABLES!$B$47)) | Q6: =P6*VARIABLES!$B$48 | R6: =IF($A6<VARIABLES!$B$45,0,(IF($A6=VARIABLES!$B$45,0,S5)+P6)*C6*VARIABLES!$B$49) | S6: =IF($A6<VARIABLES!$B$45,0,(IF($A6=VARIABLES!$B$45,0,S5)+P6)*(1+C6)-R6) | T6: =IF($A6<VARIABLES!$B$53,0,MIN(VARIABLES!$B$52,INT(($A6-VARIABLES!$B$53)/VARIABLES!$B$54)+1)*VARIABLES!$B$55) | U6: =T6*VARIABLES!$B$57+IF(AND($A6>=VARIABLES!$B$53,MOD($A6-VARIABLES!$B$53,VARIABLES!$B$54)=0,INT(($A6-VARIABLES!$B$53)/VARIABLES!$B$54)<VARIABLES!$B$52),VARIABLES!$B$55*VARIABLES!$B$56,0) | V6: =U6*VARIABLES!$B$58 | W6: =IF($A6<VARIABLES!$B$53,0,(IF($A6<VARIABLES!$B$53+1,0,X5)+U6)*C6*VARIABLES!$B$59) | X6: =IF($A6<VARIABLES!$B$53,0,(IF($A6<VARIABLES!$B$53+1,0,X5)+U6)*(1+C6)-W6) | Y6: =D6+H6+L6+P6+U6 | Z6: =E6+I6+M6+Q6+V6 | AA6: =F6+J6+N6+R6+W6 | AB6: =Y6*VARIABLES!$B$14*VARIABLES!$B$15 | AC6: =Z6+AA6+AB6 | AD6: =G6+K6+O6+S6+X6 | AE6: =0 | AF6: =Z6*VARIABLES!$B$19 | AG6: =AA6*VARIABLES!$B$18 | AH6: =VARIABLES!$B$20 | AI6: =IF(MOD($A6,12)=0,VARIABLES!$B$21,0) | AJ6: =AE6+AF6+AG6+AH6+AI6 | AK6: =IF($A6<VARIABLES!$B$7,VARIABLES!$B$11,0) | AL6: =AC6-AJ6-AK6 | AM6: =AM5+AL6 | AN6: =AN5+AK6
A7: 4 | B7: =TEXT(DATE(VARIABLES!$B$63+INT((VARIABLES!$B$64+$A7-2)/12),MOD(VARIABLES!$B$64+$A7-2,12)+1,1),"mmm-yy") | C7: =IF($A7<VARIABLES!$B$7,VARIABLES!$B$5/12,IF($A7<VARIABLES!$B$8,VARIABLES!$B$6/12,VARIABLES!$B$9/12)) | D7: =IF($A7<VARIABLES!$B$24,0,IF($A7=VARIABLES!$B$24,VARIABLES!$B$25+VARIABLES!$B$26,VARIABLES!$B$26)) | E7: =D7*VARIABLES!$B$27 | F7: =IF($A7<VARIABLES!$B$24,0,(IF($A7=VARIABLES!$B$24,0,G6)+D7)*C7*VARIABLES!$B$28) | G7: =IF($A7<VARIABLES!$B$24,0,(IF($A7=VARIABLES!$B$24,0,G6)+D7)*(1+C7)-F7) | H7: =IF($A7<VARIABLES!$B$31,0,IF($A7=VARIABLES!$B$31,VARIABLES!$B$32+VARIABLES!$B$33,VARIABLES!$B$33)) | I7: =H7*VARIABLES!$B$34 | J7: =IF($A7<VARIABLES!$B$31,0,(IF($A7=VARIABLES!$B$31,0,K6)+H7)*C7*VARIABLES!$B$35) | K7: =IF($A7<VARIABLES!$B$31,0,(IF($A7=VARIABLES!$B$31,0,K6)+H7)*(1+C7)-J7) | L7: =IF($A7<VARIABLES!$B$38,0,IF($A7=VARIABLES!$B$38,VARIABLES!$B$39+VARIABLES!$B$40,VARIABLES!$B$40)) | M7: =L7*VARIABLES!$B$41 | N7: =IF($A7<VARIABLES!$B$38,0,(IF($A7=VARIABLES!$B$38,0,O6)+L7)*C7*VARIABLES!$B$42) | O7: =IF($A7<VARIABLES!$B$38,0,(IF($A7=VARIABLES!$B$38,0,O6)+L7)*(1+C7)-N7) | P7: =IF($A7<VARIABLES!$B$45,0,IF($A7=VARIABLES!$B$45,VARIABLES!$B$46+VARIABLES!$B$47,VARIABLES!$B$47)) | Q7: =P7*VARIABLES!$B$48 | R7: =IF($A7<VARIABLES!$B$45,0,(IF($A7=VARIABLES!$B$45,0,S6)+P7)*C7*VARIABLES!$B$49) | S7: =IF($A7<VARIABLES!$B$45,0,(IF($A7=VARIABLES!$B$45,0,S6)+P7)*(1+C7)-R7) | T7: =IF($A7<VARIABLES!$B$53,0,MIN(VARIABLES!$B$52,INT(($A7-VARIABLES!$B$53)/VARIABLES!$B$54)+1)*VARIABLES!$B$55) | U7: =T7*VARIABLES!$B$57+IF(AND($A7>=VARIABLES!$B$53,MOD($A7-VARIABLES!$B$53,VARIABLES!$B$54)=0,INT(($A7-VARIABLES!$B$53)/VARIABLES!$B$54)<VARIABLES!$B$52),VARIABLES!$B$55*VARIABLES!$B$56,0) | V7: =U7*VARIABLES!$B$58 | W7: =IF($A7<VARIABLES!$B$53,0,(IF($A7<VARIABLES!$B$53+1,0,X6)+U7)*C7*VARIABLES!$B$59) | X7: =IF($A7<VARIABLES!$B$53,0,(IF($A7<VARIABLES!$B$53+1,0,X6)+U7)*(1+C7)-W7) | Y7: =D7+H7+L7+P7+U7 | Z7: =E7+I7+M7+Q7+V7 | AA7: =F7+J7+N7+R7+W7 | AB7: =Y7*VARIABLES!$B$14*VARIABLES!$B$15 | AC7: =Z7+AA7+AB7 | AD7: =G7+K7+O7+S7+X7 | AE7: =0 | AF7: =Z7*VARIABLES!$B$19 | AG7: =AA7*VARIABLES!$B$18 | AH7: =VARIABLES!$B$20 | AI7: =IF(MOD($A7,12)=0,VARIABLES!$B$21,0) | AJ7: =AE7+AF7+AG7+AH7+AI7 | AK7: =IF($A7<VARIABLES!$B$7,VARIABLES!$B$11,0) | AL7: =AC7-AJ7-AK7 | AM7: =AM6+AL7 | AN7: =AN6+AK7
A8: 5 | B8: =TEXT(DATE(VARIABLES!$B$63+INT((VARIABLES!$B$64+$A8-2)/12),MOD(VARIABLES!$B$64+$A8-2,12)+1,1),"mmm-yy") | C8: =IF($A8<VARIABLES!$B$7,VARIABLES!$B$5/12,IF($A8<VARIABLES!$B$8,VARIABLES!$B$6/12,VARIABLES!$B$9/12)) | D8: =IF($A8<VARIABLES!$B$24,0,IF($A8=VARIABLES!$B$24,VARIABLES!$B$25+VARIABLES!$B$26,VARIABLES!$B$26)) | E8: =D8*VARIABLES!$B$27 | F8: =IF($A8<VARIABLES!$B$24,0,(IF($A8=VARIABLES!$B$24,0,G7)+D8)*C8*VARIABLES!$B$28) | G8: =IF($A8<VARIABLES!$B$24,0,(IF($A8=VARIABLES!$B$24,0,G7)+D8)*(1+C8)-F8) | H8: =IF($A8<VARIABLES!$B$31,0,IF($A8=VARIABLES!$B$31,VARIABLES!$B$32+VARIABLES!$B$33,VARIABLES!$B$33)) | I8: =H8*VARIABLES!$B$34 | J8: =IF($A8<VARIABLES!$B$31,0,(IF($A8=VARIABLES!$B$31,0,K7)+H8)*C8*VARIABLES!$B$35) | K8: =IF($A8<VARIABLES!$B$31,0,(IF($A8=VARIABLES!$B$31,0,K7)+H8)*(1+C8)-J8) | L8: =IF($A8<VARIABLES!$B$38,0,IF($A8=VARIABLES!$B$38,VARIABLES!$B$39+VARIABLES!$B$40,VARIABLES!$B$40)) | M8: =L8*VARIABLES!$B$41 | N8: =IF($A8<VARIABLES!$B$38,0,(IF($A8=VARIABLES!$B$38,0,O7)+L8)*C8*VARIABLES!$B$42) | O8: =IF($A8<VARIABLES!$B$38,0,(IF($A8=VARIABLES!$B$38,0,O7)+L8)*(1+C8)-N8) | P8: =IF($A8<VARIABLES!$B$45,0,IF($A8=VARIABLES!$B$45,VARIABLES!$B$46+VARIABLES!$B$47,VARIABLES!$B$47)) | Q8: =P8*VARIABLES!$B$48 | R8: =IF($A8<VARIABLES!$B$45,0,(IF($A8=VARIABLES!$B$45,0,S7)+P8)*C8*VARIABLES!$B$49) | S8: =IF($A8<VARIABLES!$B$45,0,(IF($A8=VARIABLES!$B$45,0,S7)+P8)*(1+C8)-R8) | T8: =IF($A8<VARIABLES!$B$53,0,MIN(VARIABLES!$B$52,INT(($A8-VARIABLES!$B$53)/VARIABLES!$B$54)+1)*VARIABLES!$B$55) | U8: =T8*VARIABLES!$B$57+IF(AND($A8>=VARIABLES!$B$53,MOD($A8-VARIABLES!$B$53,VARIABLES!$B$54)=0,INT(($A8-VARIABLES!$B$53)/VARIABLES!$B$54)<VARIABLES!$B$52),VARIABLES!$B$55*VARIABLES!$B$56,0) | V8: =U8*VARIABLES!$B$58 | W8: =IF($A8<VARIABLES!$B$53,0,(IF($A8<VARIABLES!$B$53+1,0,X7)+U8)*C8*VARIABLES!$B$59) | X8: =IF($A8<VARIABLES!$B$53,0,(IF($A8<VARIABLES!$B$53+1,0,X7)+U8)*(1+C8)-W8) | Y8: =D8+H8+L8+P8+U8 | Z8: =E8+I8+M8+Q8+V8 | AA8: =F8+J8+N8+R8+W8 | AB8: =Y8*VARIABLES!$B$14*VARIABLES!$B$15 | AC8: =Z8+AA8+AB8 | AD8: =G8+K8+O8+S8+X8 | AE8: =0 | AF8: =Z8*VARIABLES!$B$19 | AG8: =AA8*VARIABLES!$B$18 | AH8: =VARIABLES!$B$20 | AI8: =IF(MOD($A8,12)=0,VARIABLES!$B$21,0) | AJ8: =AE8+AF8+AG8+AH8+AI8 | AK8: =IF($A8<VARIABLES!$B$7,VARIABLES!$B$11,0) | AL8: =AC8-AJ8-AK8 | AM8: =AM7+AL8 | AN8: =AN7+AK8
A9: 6 | B9: =TEXT(DATE(VARIABLES!$B$63+INT((VARIABLES!$B$64+$A9-2)/12),MOD(VARIABLES!$B$64+$A9-2,12)+1,1),"mmm-yy") | C9: =IF($A9<VARIABLES!$B$7,VARIABLES!$B$5/12,IF($A9<VARIABLES!$B$8,VARIABLES!$B$6/12,VARIABLES!$B$9/12)) | D9: =IF($A9<VARIABLES!$B$24,0,IF($A9=VARIABLES!$B$24,VARIABLES!$B$25+VARIABLES!$B$26,VARIABLES!$B$26)) | E9: =D9*VARIABLES!$B$27 | F9: =IF($A9<VARIABLES!$B$24,0,(IF($A9=VARIABLES!$B$24,0,G8)+D9)*C9*VARIABLES!$B$28) | G9: =IF($A9<VARIABLES!$B$24,0,(IF($A9=VARIABLES!$B$24,0,G8)+D9)*(1+C9)-F9) | H9: =IF($A9<VARIABLES!$B$31,0,IF($A9=VARIABLES!$B$31,VARIABLES!$B$32+VARIABLES!$B$33,VARIABLES!$B$33)) | I9: =H9*VARIABLES!$B$34 | J9: =IF($A9<VARIABLES!$B$31,0,(IF($A9=VARIABLES!$B$31,0,K8)+H9)*C9*VARIABLES!$B$35) | K9: =IF($A9<VARIABLES!$B$31,0,(IF($A9=VARIABLES!$B$31,0,K8)+H9)*(1+C9)-J9) | L9: =IF($A9<VARIABLES!$B$38,0,IF($A9=VARIABLES!$B$38,VARIABLES!$B$39+VARIABLES!$B$40,VARIABLES!$B$40)) | M9: =L9*VARIABLES!$B$41 | N9: =IF($A9<VARIABLES!$B$38,0,(IF($A9=VARIABLES!$B$38,0,O8)+L9)*C9*VARIABLES!$B$42) | O9: =IF($A9<VARIABLES!$B$38,0,(IF($A9=VARIABLES!$B$38,0,O8)+L9)*(1+C9)-N9) | P9: =IF($A9<VARIABLES!$B$45,0,IF($A9=VARIABLES!$B$45,VARIABLES!$B$46+VARIABLES!$B$47,VARIABLES!$B$47)) | Q9: =P9*VARIABLES!$B$48 | R9: =IF($A9<VARIABLES!$B$45,0,(IF($A9=VARIABLES!$B$45,0,S8)+P9)*C9*VARIABLES!$B$49) | S9: =IF($A9<VARIABLES!$B$45,0,(IF($A9=VARIABLES!$B$45,0,S8)+P9)*(1+C9)-R9) | T9: =IF($A9<VARIABLES!$B$53,0,MIN(VARIABLES!$B$52,INT(($A9-VARIABLES!$B$53)/VARIABLES!$B$54)+1)*VARIABLES!$B$55) | U9: =T9*VARIABLES!$B$57+IF(AND($A9>=VARIABLES!$B$53,MOD($A9-VARIABLES!$B$53,VARIABLES!$B$54)=0,INT(($A9-VARIABLES!$B$53)/VARIABLES!$B$54)<VARIABLES!$B$52),VARIABLES!$B$55*VARIABLES!$B$56,0) | V9: =U9*VARIABLES!$B$58 | W9: =IF($A9<VARIABLES!$B$53,0,(IF($A9<VARIABLES!$B$53+1,0,X8)+U9)*C9*VARIABLES!$B$59) | X9: =IF($A9<VARIABLES!$B$53,0,(IF($A9<VARIABLES!$B$53+1,0,X8)+U9)*(1+C9)-W9) | Y9: =D9+H9+L9+P9+U9 | Z9: =E9+I9+M9+Q9+V9 | AA9: =F9+J9+N9+R9+W9 | AB9: =Y9*VARIABLES!$B$14*VARIABLES!$B$15 | AC9: =Z9+AA9+AB9 | AD9: =G9+K9+O9+S9+X9 | AE9: =0 | AF9: =Z9*VARIABLES!$B$19 | AG9: =AA9*VARIABLES!$B$18 | AH9: =VARIABLES!$B$20 | AI9: =IF(MOD($A9,12)=0,VARIABLES!$B$21,0) | AJ9: =AE9+AF9+AG9+AH9+AI9 | AK9: =IF($A9<VARIABLES!$B$7,VARIABLES!$B$11,0) | AL9: =AC9-AJ9-AK9 | AM9: =AM8+AL9 | AN9: =AN8+AK9
A10: 7 | B10: =TEXT(DATE(VARIABLES!$B$63+INT((VARIABLES!$B$64+$A10-2)/12),MOD(VARIABLES!$B$64+$A10-2,12)+1,1),"mmm-yy") | C10: =IF($A10<VARIABLES!$B$7,VARIABLES!$B$5/12,IF($A10<VARIABLES!$B$8,VARIABLES!$B$6/12,VARIABLES!$B$9/12)) | D10: =IF($A10<VARIABLES!$B$24,0,IF($A10=VARIABLES!$B$24,VARIABLES!$B$25+VARIABLES!$B$26,VARIABLES!$B$26)) | E10: =D10*VARIABLES!$B$27 | F10: =IF($A10<VARIABLES!$B$24,0,(IF($A10=VARIABLES!$B$24,0,G9)+D10)*C10*VARIABLES!$B$28) | G10: =IF($A10<VARIABLES!$B$24,0,(IF($A10=VARIABLES!$B$24,0,G9)+D10)*(1+C10)-F10) | H10: =IF($A10<VARIABLES!$B$31,0,IF($A10=VARIABLES!$B$31,VARIABLES!$B$32+VARIABLES!$B$33,VARIABLES!$B$33)) | I10: =H10*VARIABLES!$B$34 | J10: =IF($A10<VARIABLES!$B$31,0,(IF($A10=VARIABLES!$B$31,0,K9)+H10)*C10*VARIABLES!$B$35) | K10: =IF($A10<VARIABLES!$B$31,0,(IF($A10=VARIABLES!$B$31,0,K9)+H10)*(1+C10)-J10) | L10: =IF($A10<VARIABLES!$B$38,0,IF($A10=VARIABLES!$B$38,VARIABLES!$B$39+VARIABLES!$B$40,VARIABLES!$B$40)) | M10: =L10*VARIABLES!$B$41 | N10: =IF($A10<VARIABLES!$B$38,0,(IF($A10=VARIABLES!$B$38,0,O9)+L10)*C10*VARIABLES!$B$42) | O10: =IF($A10<VARIABLES!$B$38,0,(IF($A10=VARIABLES!$B$38,0,O9)+L10)*(1+C10)-N10) | P10: =IF($A10<VARIABLES!$B$45,0,IF($A10=VARIABLES!$B$45,VARIABLES!$B$46+VARIABLES!$B$47,VARIABLES!$B$47)) | Q10: =P10*VARIABLES!$B$48 | R10: =IF($A10<VARIABLES!$B$45,0,(IF($A10=VARIABLES!$B$45,0,S9)+P10)*C10*VARIABLES!$B$49) | S10: =IF($A10<VARIABLES!$B$45,0,(IF($A10=VARIABLES!$B$45,0,S9)+P10)*(1+C10)-R10) | T10: =IF($A10<VARIABLES!$B$53,0,MIN(VARIABLES!$B$52,INT(($A10-VARIABLES!$B$53)/VARIABLES!$B$54)+1)*VARIABLES!$B$55) | U10: =T10*VARIABLES!$B$57+IF(AND($A10>=VARIABLES!$B$53,MOD($A10-VARIABLES!$B$53,VARIABLES!$B$54)=0,INT(($A10-VARIABLES!$B$53)/VARIABLES!$B$54)<VARIABLES!$B$52),VARIABLES!$B$55*VARIABLES!$B$56,0) | V10: =U10*VARIABLES!$B$58 | W10: =IF($A10<VARIABLES!$B$53,0,(IF($A10<VARIABLES!$B$53+1,0,X9)+U10)*C10*VARIABLES!$B$59) | X10: =IF($A10<VARIABLES!$B$53,0,(IF($A10<VARIABLES!$B$53+1,0,X9)+U10)*(1+C10)-W10) | Y10: =D10+H10+L10+P10+U10 | Z10: =E10+I10+M10+Q10+V10 | AA10: =F10+J10+N10+R10+W10 | AB10: =Y10*VARIABLES!$B$14*VARIABLES!$B$15 | AC10: =Z10+AA10+AB10 | AD10: =G10+K10+O10+S10+X10 | AE10: =0 | AF10: =Z10*VARIABLES!$B$19 | AG10: =AA10*VARIABLES!$B$18 | AH10: =VARIABLES!$B$20 | AI10: =IF(MOD($A10,12)=0,VARIABLES!$B$21,0) | AJ10: =AE10+AF10+AG10+AH10+AI10 | AK10: =IF($A10<VARIABLES!$B$7,VARIABLES!$B$11,0) | AL10: =AC10-AJ10-AK10 | AM10: =AM9+AL10 | AN10: =AN9+AK10
A11: 8 | B11: =TEXT(DATE(VARIABLES!$B$63+INT((VARIABLES!$B$64+$A11-2)/12),MOD(VARIABLES!$B$64+$A11-2,12)+1,1),"mmm-yy") | C11: =IF($A11<VARIABLES!$B$7,VARIABLES!$B$5/12,IF($A11<VARIABLES!$B$8,VARIABLES!$B$6/12,VARIABLES!$B$9/12)) | D11: =IF($A11<VARIABLES!$B$24,0,IF($A11=VARIABLES!$B$24,VARIABLES!$B$25+VARIABLES!$B$26,VARIABLES!$B$26)) | E11: =D11*VARIABLES!$B$27 | F11: =IF($A11<VARIABLES!$B$24,0,(IF($A11=VARIABLES!$B$24,0,G10)+D11)*C11*VARIABLES!$B$28) | G11: =IF($A11<VARIABLES!$B$24,0,(IF($A11=VARIABLES!$B$24,0,G10)+D11)*(1+C11)-F11) | H11: =IF($A11<VARIABLES!$B$31,0,IF($A11=VARIABLES!$B$31,VARIABLES!$B$32+VARIABLES!$B$33,VARIABLES!$B$33)) | I11: =H11*VARIABLES!$B$34 | J11: =IF($A11<VARIABLES!$B$31,0,(IF($A11=VARIABLES!$B$31,0,K10)+H11)*C11*VARIABLES!$B$35) | K11: =IF($A11<VARIABLES!$B$31,0,(IF($A11=VARIABLES!$B$31,0,K10)+H11)*(1+C11)-J11) | L11: =IF($A11<VARIABLES!$B$38,0,IF($A11=VARIABLES!$B$38,VARIABLES!$B$39+VARIABLES!$B$40,VARIABLES!$B$40)) | M11: =L11*VARIABLES!$B$41 | N11: =IF($A11<VARIABLES!$B$38,0,(IF($A11=VARIABLES!$B$38,0,O10)+L11)*C11*VARIABLES!$B$42) | O11: =IF($A11<VARIABLES!$B$38,0,(IF($A11=VARIABLES!$B$38,0,O10)+L11)*(1+C11)-N11) | P11: =IF($A11<VARIABLES!$B$45,0,IF($A11=VARIABLES!$B$45,VARIABLES!$B$46+VARIABLES!$B$47,VARIABLES!$B$47)) | Q11: =P11*VARIABLES!$B$48 | R11: =IF($A11<VARIABLES!$B$45,0,(IF($A11=VARIABLES!$B$45,0,S10)+P11)*C11*VARIABLES!$B$49) | S11: =IF($A11<VARIABLES!$B$45,0,(IF($A11=VARIABLES!$B$45,0,S10)+P11)*(1+C11)-R11) | T11: =IF($A11<VARIABLES!$B$53,0,MIN(VARIABLES!$B$52,INT(($A11-VARIABLES!$B$53)/VARIABLES!$B$54)+1)*VARIABLES!$B$55) | U11: =T11*VARIABLES!$B$57+IF(AND($A11>=VARIABLES!$B$53,MOD($A11-VARIABLES!$B$53,VARIABLES!$B$54)=0,INT(($A11-VARIABLES!$B$53)/VARIABLES!$B$54)<VARIABLES!$B$52),VARIABLES!$B$55*VARIABLES!$B$56,0) | V11: =U11*VARIABLES!$B$58 | W11: =IF($A11<VARIABLES!$B$53,0,(IF($A11<VARIABLES!$B$53+1,0,X10)+U11)*C11*VARIABLES!$B$59) | X11: =IF($A11<VARIABLES!$B$53,0,(IF($A11<VARIABLES!$B$53+1,0,X10)+U11)*(1+C11)-W11) | Y11: =D11+H11+L11+P11+U11 | Z11: =E11+I11+M11+Q11+V11 | AA11: =F11+J11+N11+R11+W11 | AB11: =Y11*VARIABLES!$B$14*VARIABLES!$B$15 | AC11: =Z11+AA11+AB11 | AD11: =G11+K11+O11+S11+X11 | AE11: =0 | AF11: =Z11*VARIABLES!$B$19 | AG11: =AA11*VARIABLES!$B$18 | AH11: =VARIABLES!$B$20 | AI11: =IF(MOD($A11,12)=0,VARIABLES!$B$21,0) | AJ11: =AE11+AF11+AG11+AH11+AI11 | AK11: =IF($A11<VARIABLES!$B$7,VARIABLES!$B$11,0) | AL11: =AC11-AJ11-AK11 | AM11: =AM10+AL11 | AN11: =AN10+AK11
A12: 9 | B12: =TEXT(DATE(VARIABLES!$B$63+INT((VARIABLES!$B$64+$A12-2)/12),MOD(VARIABLES!$B$64+$A12-2,12)+1,1),"mmm-yy") | C12: =IF($A12<VARIABLES!$B$7,VARIABLES!$B$5/12,IF($A12<VARIABLES!$B$8,VARIABLES!$B$6/12,VARIABLES!$B$9/12)) | D12: =IF($A12<VARIABLES!$B$24,0,IF($A12=VARIABLES!$B$24,VARIABLES!$B$25+VARIABLES!$B$26,VARIABLES!$B$26)) | E12: =D12*VARIABLES!$B$27 | F12: =IF($A12<VARIABLES!$B$24,0,(IF($A12=VARIABLES!$B$24,0,G11)+D12)*C12*VARIABLES!$B$28) | G12: =IF($A12<VARIABLES!$B$24,0,(IF($A12=VARIABLES!$B$24,0,G11)+D12)*(1+C12)-F12) | H12: =IF($A12<VARIABLES!$B$31,0,IF($A12=VARIABLES!$B$31,VARIABLES!$B$32+VARIABLES!$B$33,VARIABLES!$B$33)) | I12: =H12*VARIABLES!$B$34 | J12: =IF($A12<VARIABLES!$B$31,0,(IF($A12=VARIABLES!$B$31,0,K11)+H12)*C12*VARIABLES!$B$35) | K12: =IF($A12<VARIABLES!$B$31,0,(IF($A12=VARIABLES!$B$31,0,K11)+H12)*(1+C12)-J12) | L12: =IF($A12<VARIABLES!$B$38,0,IF($A12=VARIABLES!$B$38,VARIABLES!$B$39+VARIABLES!$B$40,VARIABLES!$B$40)) | M12: =L12*VARIABLES!$B$41 | N12: =IF($A12<VARIABLES!$B$38,0,(IF($A12=VARIABLES!$B$38,0,O11)+L12)*C12*VARIABLES!$B$42) | O12: =IF($A12<VARIABLES!$B$38,0,(IF($A12=VARIABLES!$B$38,0,O11)+L12)*(1+C12)-N12) | P12: =IF($A12<VARIABLES!$B$45,0,IF($A12=VARIABLES!$B$45,VARIABLES!$B$46+VARIABLES!$B$47,VARIABLES!$B$47)) | Q12: =P12*VARIABLES!$B$48 | R12: =IF($A12<VARIABLES!$B$45,0,(IF($A12=VARIABLES!$B$45,0,S11)+P12)*C12*VARIABLES!$B$49) | S12: =IF($A12<VARIABLES!$B$45,0,(IF($A12=VARIABLES!$B$45,0,S11)+P12)*(1+C12)-R12) | T12: =IF($A12<VARIABLES!$B$53,0,MIN(VARIABLES!$B$52,INT(($A12-VARIABLES!$B$53)/VARIABLES!$B$54)+1)*VARIABLES!$B$55) | U12: =T12*VARIABLES!$B$57+IF(AND($A12>=VARIABLES!$B$53,MOD($A12-VARIABLES!$B$53,VARIABLES!$B$54)=0,INT(($A12-VARIABLES!$B$53)/VARIABLES!$B$54)<VARIABLES!$B$52),VARIABLES!$B$55*VARIABLES!$B$56,0) | V12: =U12*VARIABLES!$B$58 | W12: =IF($A12<VARIABLES!$B$53,0,(IF($A12<VARIABLES!$B$53+1,0,X11)+U12)*C12*VARIABLES!$B$59) | X12: =IF($A12<VARIABLES!$B$53,0,(IF($A12<VARIABLES!$B$53+1,0,X11)+U12)*(1+C12)-W12) | Y12: =D12+H12+L12+P12+U12 | Z12: =E12+I12+M12+Q12+V12 | AA12: =F12+J12+N12+R12+W12 | AB12: =Y12*VARIABLES!$B$14*VARIABLES!$B$15 | AC12: =Z12+AA12+AB12 | AD12: =G12+K12+O12+S12+X12 | AE12: =0 | AF12: =Z12*VARIABLES!$B$19 | AG12: =AA12*VARIABLES!$B$18 | AH12: =VARIABLES!$B$20 | AI12: =IF(MOD($A12,12)=0,VARIABLES!$B$21,0) | AJ12: =AE12+AF12+AG12+AH12+AI12 | AK12: =IF($A12<VARIABLES!$B$7,VARIABLES!$B$11,0) | AL12: =AC12-AJ12-AK12 | AM12: =AM11+AL12 | AN12: =AN11+AK12
A13: 10 | B13: =TEXT(DATE(VARIABLES!$B$63+INT((VARIABLES!$B$64+$A13-2)/12),MOD(VARIABLES!$B$64+$A13-2,12)+1,1),"mmm-yy") | C13: =IF($A13<VARIABLES!$B$7,VARIABLES!$B$5/12,IF($A13<VARIABLES!$B$8,VARIABLES!$B$6/12,VARIABLES!$B$9/12)) | D13: =IF($A13<VARIABLES!$B$24,0,IF($A13=VARIABLES!$B$24,VARIABLES!$B$25+VARIABLES!$B$26,VARIABLES!$B$26)) | E13: =D13*VARIABLES!$B$27 | F13: =IF($A13<VARIABLES!$B$24,0,(IF($A13=VARIABLES!$B$24,0,G12)+D13)*C13*VARIABLES!$B$28) | G13: =IF($A13<VARIABLES!$B$24,0,(IF($A13=VARIABLES!$B$24,0,G12)+D13)*(1+C13)-F13) | H13: =IF($A13<VARIABLES!$B$31,0,IF($A13=VARIABLES!$B$31,VARIABLES!$B$32+VARIABLES!$B$33,VARIABLES!$B$33)) | I13: =H13*VARIABLES!$B$34 | J13: =IF($A13<VARIABLES!$B$31,0,(IF($A13=VARIABLES!$B$31,0,K12)+H13)*C13*VARIABLES!$B$35) | K13: =IF($A13<VARIABLES!$B$31,0,(IF($A13=VARIABLES!$B$31,0,K12)+H13)*(1+C13)-J13) | L13: =IF($A13<VARIABLES!$B$38,0,IF($A13=VARIABLES!$B$38,VARIABLES!$B$39+VARIABLES!$B$40,VARIABLES!$B$40)) | M13: =L13*VARIABLES!$B$41 | N13: =IF($A13<VARIABLES!$B$38,0,(IF($A13=VARIABLES!$B$38,0,O12)+L13)*C13*VARIABLES!$B$42) | O13: =IF($A13<VARIABLES!$B$38,0,(IF($A13=VARIABLES!$B$38,0,O12)+L13)*(1+C13)-N13) | P13: =IF($A13<VARIABLES!$B$45,0,IF($A13=VARIABLES!$B$45,VARIABLES!$B$46+VARIABLES!$B$47,VARIABLES!$B$47)) | Q13: =P13*VARIABLES!$B$48 | R13: =IF($A13<VARIABLES!$B$45,0,(IF($A13=VARIABLES!$B$45,0,S12)+P13)*C13*VARIABLES!$B$49) | S13: =IF($A13<VARIABLES!$B$45,0,(IF($A13=VARIABLES!$B$45,0,S12)+P13)*(1+C13)-R13) | T13: =IF($A13<VARIABLES!$B$53,0,MIN(VARIABLES!$B$52,INT(($A13-VARIABLES!$B$53)/VARIABLES!$B$54)+1)*VARIABLES!$B$55) | U13: =T13*VARIABLES!$B$57+IF(AND($A13>=VARIABLES!$B$53,MOD($A13-VARIABLES!$B$53,VARIABLES!$B$54)=0,INT(($A13-VARIABLES!$B$53)/VARIABLES!$B$54)<VARIABLES!$B$52),VARIABLES!$B$55*VARIABLES!$B$56,0) | V13: =U13*VARIABLES!$B$58 | W13: =IF($A13<VARIABLES!$B$53,0,(IF($A13<VARIABLES!$B$53+1,0,X12)+U13)*C13*VARIABLES!$B$59) | X13: =IF($A13<VARIABLES!$B$53,0,(IF($A13<VARIABLES!$B$53+1,0,X12)+U13)*(1+C13)-W13) | Y13: =D13+H13+L13+P13+U13 | Z13: =E13+I13+M13+Q13+V13 | AA13: =F13+J13+N13+R13+W13 | AB13: =Y13*VARIABLES!$B$14*VARIABLES!$B$15 | AC13: =Z13+AA13+AB13 | AD13: =G13+K13+O13+S13+X13 | AE13: =0 | AF13: =Z13*VARIABLES!$B$19 | AG13: =AA13*VARIABLES!$B$18 | AH13: =VARIABLES!$B$20 | AI13: =IF(MOD($A13,12)=0,VARIABLES!$B$21,0) | AJ13: =AE13+AF13+AG13+AH13+AI13 | AK13: =IF($A13<VARIABLES!$B$7,VARIABLES!$B$11,0) | AL13: =AC13-AJ13-AK13 | AM13: =AM12+AL13 | AN13: =AN12+AK13
A14: 11 | B14: =TEXT(DATE(VARIABLES!$B$63+INT((VARIABLES!$B$64+$A14-2)/12),MOD(VARIABLES!$B$64+$A14-2,12)+1,1),"mmm-yy") | C14: =IF($A14<VARIABLES!$B$7,VARIABLES!$B$5/12,IF($A14<VARIABLES!$B$8,VARIABLES!$B$6/12,VARIABLES!$B$9/12)) | D14: =IF($A14<VARIABLES!$B$24,0,IF($A14=VARIABLES!$B$24,VARIABLES!$B$25+VARIABLES!$B$26,VARIABLES!$B$26)) | E14: =D14*VARIABLES!$B$27 | F14: =IF($A14<VARIABLES!$B$24,0,(IF($A14=VARIABLES!$B$24,0,G13)+D14)*C14*VARIABLES!$B$28) | G14: =IF($A14<VARIABLES!$B$24,0,(IF($A14=VARIABLES!$B$24,0,G13)+D14)*(1+C14)-F14) | H14: =IF($A14<VARIABLES!$B$31,0,IF($A14=VARIABLES!$B$31,VARIABLES!$B$32+VARIABLES!$B$33,VARIABLES!$B$33)) | I14: =H14*VARIABLES!$B$34 | J14: =IF($A14<VARIABLES!$B$31,0,(IF($A14=VARIABLES!$B$31,0,K13)+H14)*C14*VARIABLES!$B$35) | K14: =IF($A14<VARIABLES!$B$31,0,(IF($A14=VARIABLES!$B$31,0,K13)+H14)*(1+C14)-J14) | L14: =IF($A14<VARIABLES!$B$38,0,IF($A14=VARIABLES!$B$38,VARIABLES!$B$39+VARIABLES!$B$40,VARIABLES!$B$40)) | M14: =L14*VARIABLES!$B$41 | N14: =IF($A14<VARIABLES!$B$38,0,(IF($A14=VARIABLES!$B$38,0,O13)+L14)*C14*VARIABLES!$B$42) | O14: =IF($A14<VARIABLES!$B$38,0,(IF($A14=VARIABLES!$B$38,0,O13)+L14)*(1+C14)-N14) | P14: =IF($A14<VARIABLES!$B$45,0,IF($A14=VARIABLES!$B$45,VARIABLES!$B$46+VARIABLES!$B$47,VARIABLES!$B$47)) | Q14: =P14*VARIABLES!$B$48 | R14: =IF($A14<VARIABLES!$B$45,0,(IF($A14=VARIABLES!$B$45,0,S13)+P14)*C14*VARIABLES!$B$49) | S14: =IF($A14<VARIABLES!$B$45,0,(IF($A14=VARIABLES!$B$45,0,S13)+P14)*(1+C14)-R14) | T14: =IF($A14<VARIABLES!$B$53,0,MIN(VARIABLES!$B$52,INT(($A14-VARIABLES!$B$53)/VARIABLES!$B$54)+1)*VARIABLES!$B$55) | U14: =T14*VARIABLES!$B$57+IF(AND($A14>=VARIABLES!$B$53,MOD($A14-VARIABLES!$B$53,VARIABLES!$B$54)=0,INT(($A14-VARIABLES!$B$53)/VARIABLES!$B$54)<VARIABLES!$B$52),VARIABLES!$B$55*VARIABLES!$B$56,0) | V14: =U14*VARIABLES!$B$58 | W14: =IF($A14<VARIABLES!$B$53,0,(IF($A14<VARIABLES!$B$53+1,0,X13)+U14)*C14*VARIABLES!$B$59) | X14: =IF($A14<VARIABLES!$B$53,0,(IF($A14<VARIABLES!$B$53+1,0,X13)+U14)*(1+C14)-W14) | Y14: =D14+H14+L14+P14+U14 | Z14: =E14+I14+M14+Q14+V14 | AA14: =F14+J14+N14+R14+W14 | AB14: =Y14*VARIABLES!$B$14*VARIABLES!$B$15 | AC14: =Z14+AA14+AB14 | AD14: =G14+K14+O14+S14+X14 | AE14: =0 | AF14: =Z14*VARIABLES!$B$19 | AG14: =AA14*VARIABLES!$B$18 | AH14: =VARIABLES!$B$20 | AI14: =IF(MOD($A14,12)=0,VARIABLES!$B$21,0) | AJ14: =AE14+AF14+AG14+AH14+AI14 | AK14: =IF($A14<VARIABLES!$B$7,VARIABLES!$B$11,0) | AL14: =AC14-AJ14-AK14 | AM14: =AM13+AL14 | AN14: =AN13+AK14
A15: 12 | B15: =TEXT(DATE(VARIABLES!$B$63+INT((VARIABLES!$B$64+$A15-2)/12),MOD(VARIABLES!$B$64+$A15-2,12)+1,1),"mmm-yy") | C15: =IF($A15<VARIABLES!$B$7,VARIABLES!$B$5/12,IF($A15<VARIABLES!$B$8,VARIABLES!$B$6/12,VARIABLES!$B$9/12)) | D15: =IF($A15<VARIABLES!$B$24,0,IF($A15=VARIABLES!$B$24,VARIABLES!$B$25+VARIABLES!$B$26,VARIABLES!$B$26)) | E15: =D15*VARIABLES!$B$27 | F15: =IF($A15<VARIABLES!$B$24,0,(IF($A15=VARIABLES!$B$24,0,G14)+D15)*C15*VARIABLES!$B$28) | G15: =IF($A15<VARIABLES!$B$24,0,(IF($A15=VARIABLES!$B$24,0,G14)+D15)*(1+C15)-F15) | H15: =IF($A15<VARIABLES!$B$31,0,IF($A15=VARIABLES!$B$31,VARIABLES!$B$32+VARIABLES!$B$33,VARIABLES!$B$33)) | I15: =H15*VARIABLES!$B$34 | J15: =IF($A15<VARIABLES!$B$31,0,(IF($A15=VARIABLES!$B$31,0,K14)+H15)*C15*VARIABLES!$B$35) | K15: =IF($A15<VARIABLES!$B$31,0,(IF($A15=VARIABLES!$B$31,0,K14)+H15)*(1+C15)-J15) | L15: =IF($A15<VARIABLES!$B$38,0,IF($A15=VARIABLES!$B$38,VARIABLES!$B$39+VARIABLES!$B$40,VARIABLES!$B$40)) | M15: =L15*VARIABLES!$B$41 | N15: =IF($A15<VARIABLES!$B$38,0,(IF($A15=VARIABLES!$B$38,0,O14)+L15)*C15*VARIABLES!$B$42) | O15: =IF($A15<VARIABLES!$B$38,0,(IF($A15=VARIABLES!$B$38,0,O14)+L15)*(1+C15)-N15) | P15: =IF($A15<VARIABLES!$B$45,0,IF($A15=VARIABLES!$B$45,VARIABLES!$B$46+VARIABLES!$B$47,VARIABLES!$B$47)) | Q15: =P15*VARIABLES!$B$48 | R15: =IF($A15<VARIABLES!$B$45,0,(IF($A15=VARIABLES!$B$45,0,S14)+P15)*C15*VARIABLES!$B$49) | S15: =IF($A15<VARIABLES!$B$45,0,(IF($A15=VARIABLES!$B$45,0,S14)+P15)*(1+C15)-R15) | T15: =IF($A15<VARIABLES!$B$53,0,MIN(VARIABLES!$B$52,INT(($A15-VARIABLES!$B$53)/VARIABLES!$B$54)+1)*VARIABLES!$B$55) | U15: =T15*VARIABLES!$B$57+IF(AND($A15>=VARIABLES!$B$53,MOD($A15-VARIABLES!$B$53,VARIABLES!$B$54)=0,INT(($A15-VARIABLES!$B$53)/VARIABLES!$B$54)<VARIABLES!$B$52),VARIABLES!$B$55*VARIABLES!$B$56,0) | V15: =U15*VARIABLES!$B$58 | W15: =IF($A15<VARIABLES!$B$53,0,(IF($A15<VARIABLES!$B$53+1,0,X14)+U15)*C15*VARIABLES!$B$59) | X15: =IF($A15<VARIABLES!$B$53,0,(IF($A15<VARIABLES!$B$53+1,0,X14)+U15)*(1+C15)-W15) | Y15: =D15+H15+L15+P15+U15 | Z15: =E15+I15+M15+Q15+V15 | AA15: =F15+J15+N15+R15+W15 | AB15: =Y15*VARIABLES!$B$14*VARIABLES!$B$15 | AC15: =Z15+AA15+AB15 | AD15: =G15+K15+O15+S15+X15 | AE15: =0 | AF15: =Z15*VARIABLES!$B$19 | AG15: =AA15*VARIABLES!$B$18 | AH15: =VARIABLES!$B$20 | AI15: =IF(MOD($A15,12)=0,VARIABLES!$B$21,0) | AJ15: =AE15+AF15+AG15+AH15+AI15 | AK15: =IF($A15<VARIABLES!$B$7,VARIABLES!$B$11,0) | AL15: =AC15-AJ15-AK15 | AM15: =AM14+AL15 | AN15: =AN14+AK15
A16: 13 | B16: =TEXT(DATE(VARIABLES!$B$63+INT((VARIABLES!$B$64+$A16-2)/12),MOD(VARIABLES!$B$64+$A16-2,12)+1,1),"mmm-yy") | C16: =IF($A16<VARIABLES!$B$7,VARIABLES!$B$5/12,IF($A16<VARIABLES!$B$8,VARIABLES!$B$6/12,VARIABLES!$B$9/12)) | D16: =IF($A16<VARIABLES!$B$24,0,IF($A16=VARIABLES!$B$24,VARIABLES!$B$25+VARIABLES!$B$26,VARIABLES!$B$26)) | E16: =D16*VARIABLES!$B$27 | F16: =IF($A16<VARIABLES!$B$24,0,(IF($A16=VARIABLES!$B$24,0,G15)+D16)*C16*VARIABLES!$B$28) | G16: =IF($A16<VARIABLES!$B$24,0,(IF($A16=VARIABLES!$B$24,0,G15)+D16)*(1+C16)-F16) | H16: =IF($A16<VARIABLES!$B$31,0,IF($A16=VARIABLES!$B$31,VARIABLES!$B$32+VARIABLES!$B$33,VARIABLES!$B$33)) | I16: =H16*VARIABLES!$B$34 | J16: =IF($A16<VARIABLES!$B$31,0,(IF($A16=VARIABLES!$B$31,0,K15)+H16)*C16*VARIABLES!$B$35) | K16: =IF($A16<VARIABLES!$B$31,0,(IF($A16=VARIABLES!$B$31,0,K15)+H16)*(1+C16)-J16) | L16: =IF($A16<VARIABLES!$B$38,0,IF($A16=VARIABLES!$B$38,VARIABLES!$B$39+VARIABLES!$B$40,VARIABLES!$B$40)) | M16: =L16*VARIABLES!$B$41 | N16: =IF($A16<VARIABLES!$B$38,0,(IF($A16=VARIABLES!$B$38,0,O15)+L16)*C16*VARIABLES!$B$42) | O16: =IF($A16<VARIABLES!$B$38,0,(IF($A16=VARIABLES!$B$38,0,O15)+L16)*(1+C16)-N16) | P16: =IF($A16<VARIABLES!$B$45,0,IF($A16=VARIABLES!$B$45,VARIABLES!$B$46+VARIABLES!$B$47,VARIABLES!$B$47)) | Q16: =P16*VARIABLES!$B$48 | R16: =IF($A16<VARIABLES!$B$45,0,(IF($A16=VARIABLES!$B$45,0,S15)+P16)*C16*VARIABLES!$B$49) | S16: =IF($A16<VARIABLES!$B$45,0,(IF($A16=VARIABLES!$B$45,0,S15)+P16)*(1+C16)-R16) | T16: =IF($A16<VARIABLES!$B$53,0,MIN(VARIABLES!$B$52,INT(($A16-VARIABLES!$B$53)/VARIABLES!$B$54)+1)*VARIABLES!$B$55) | U16: =T16*VARIABLES!$B$57+IF(AND($A16>=VARIABLES!$B$53,MOD($A16-VARIABLES!$B$53,VARIABLES!$B$54)=0,INT(($A16-VARIABLES!$B$53)/VARIABLES!$B$54)<VARIABLES!$B$52),VARIABLES!$B$55*VARIABLES!$B$56,0) | V16: =U16*VARIABLES!$B$58 | W16: =IF($A16<VARIABLES!$B$53,0,(IF($A16<VARIABLES!$B$53+1,0,X15)+U16)*C16*VARIABLES!$B$59) | X16: =IF($A16<VARIABLES!$B$53,0,(IF($A16<VARIABLES!$B$53+1,0,X15)+U16)*(1+C16)-W16) | Y16: =D16+H16+L16+P16+U16 | Z16: =E16+I16+M16+Q16+V16 | AA16: =F16+J16+N16+R16+W16 | AB16: =Y16*VARIABLES!$B$14*VARIABLES!$B$15 | AC16: =Z16+AA16+AB16 | AD16: =G16+K16+O16+S16+X16 | AE16: =0 | AF16: =Z16*VARIABLES!$B$19 | AG16: =AA16*VARIABLES!$B$18 | AH16: =VARIABLES!$B$20 | AI16: =IF(MOD($A16,12)=0,VARIABLES!$B$21,0) | AJ16: =AE16+AF16+AG16+AH16+AI16 | AK16: =IF($A16<VARIABLES!$B$7,VARIABLES!$B$11,0) | AL16: =AC16-AJ16-AK16 | AM16: =AM15+AL16 | AN16: =AN15+AK16
... A99: 96 | B99: =TEXT(DATE(VARIABLES!$B$63+INT((VARIABLES!$B$64+$A99-2)/12),MOD(VARIABLES!$B$64+$A99-2,12)+1,1),"mmm-yy") | C99: =IF($A99<VARIABLES!$B$7,VARIABLES!$B$5/12,IF($A99<VARIABLES!$B$8,VARIABLES!$B$6/12,VARIABLES!$B$9/12)) | D99: =IF($A99<VARIABLES!$B$24,0,IF($A99=VARIABLES!$B$24,VARIABLES!$B$25+VARIABLES!$B$26,VARIABLES!$B$26)) | E99: =D99*VARIABLES!$B$27 | F99: =IF($A99<VARIABLES!$B$24,0,(IF($A99=VARIABLES!$B$24,0,G98)+D99)*C99*VARIABLES!$B$28) | G99: =IF($A99<VARIABLES!$B$24,0,(IF($A99=VARIABLES!$B$24,0,G98)+D99)*(1+C99)-F99) | H99: =IF($A99<VARIABLES!$B$31,0,IF($A99=VARIABLES!$B$31,VARIABLES!$B$32+VARIABLES!$B$33,VARIABLES!$B$33)) | I99: =H99*VARIABLES!$B$34 | J99: =IF($A99<VARIABLES!$B$31,0,(IF($A99=VARIABLES!$B$31,0,K98)+H99)*C99*VARIABLES!$B$35) | K99: =IF($A99<VARIABLES!$B$31,0,(IF($A99=VARIABLES!$B$31,0,K98)+H99)*(1+C99)-J99) | L99: =IF($A99<VARIABLES!$B$38,0,IF($A99=VARIABLES!$B$38,VARIABLES!$B$39+VARIABLES!$B$40,VARIABLES!$B$40)) | M99: =L99*VARIABLES!$B$41 | N99: =IF($A99<VARIABLES!$B$38,0,(IF($A99=VARIABLES!$B$38,0,O98)+L99)*C99*VARIABLES!$B$42) | O99: =IF($A99<VARIABLES!$B$38,0,(IF($A99=VARIABLES!$B$38,0,O98)+L99)*(1+C99)-N99) | P99: =IF($A99<VARIABLES!$B$45,0,IF($A99=VARIABLES!$B$45,VARIABLES!$B$46+VARIABLES!$B$47,VARIABLES!$B$47)) | Q99: =P99*VARIABLES!$B$48 | R99: =IF($A99<VARIABLES!$B$45,0,(IF($A99=VARIABLES!$B$45,0,S98)+P99)*C99*VARIABLES!$B$49) | S99: =IF($A99<VARIABLES!$B$45,0,(IF($A99=VARIABLES!$B$45,0,S98)+P99)*(1+C99)-R99) | T99: =IF($A99<VARIABLES!$B$53,0,MIN(VARIABLES!$B$52,INT(($A99-VARIABLES!$B$53)/VARIABLES!$B$54)+1)*VARIABLES!$B$55) | U99: =T99*VARIABLES!$B$57+IF(AND($A99>=VARIABLES!$B$53,MOD($A99-VARIABLES!$B$53,VARIABLES!$B$54)=0,INT(($A99-VARIABLES!$B$53)/VARIABLES!$B$54)<VARIABLES!$B$52),VARIABLES!$B$55*VARIABLES!$B$56,0) | V99: =U99*VARIABLES!$B$58 | W99: =IF($A99<VARIABLES!$B$53,0,(IF($A99<VARIABLES!$B$53+1,0,X98)+U99)*C99*VARIABLES!$B$59) | X99: =IF($A99<VARIABLES!$B$53,0,(IF($A99<VARIABLES!$B$53+1,0,X98)+U99)*(1+C99)-W99) | Y99: =D99+H99+L99+P99+U99 | Z99: =E99+I99+M99+Q99+V99 | AA99: =F99+J99+N99+R99+W99 | AB99: =Y99*VARIABLES!$B$14*VARIABLES!$B$15 | AC99: =Z99+AA99+AB99 | AD99: =G99+K99+O99+S99+X99 | AE99: =0 | AF99: =Z99*VARIABLES!$B$19 | AG99: =AA99*VARIABLES!$B$18 | AH99: =VARIABLES!$B$20 | AI99: =IF(MOD($A99,12)=0,VARIABLES!$B$21,0) | AJ99: =AE99+AF99+AG99+AH99+AI99 | AK99: =IF($A99<VARIABLES!$B$7,VARIABLES!$B$11,0) | AL99: =AC99-AJ99-AK99 | AM99: =AM98+AL99 | AN99: =AN98+AK99
A100: TOTAL / FINAL (96 months) | Y100: =SUM(Y4:Y99) | Z100: =SUM(Z4:Z99) | AA100: =SUM(AA4:AA99) | AB100: =SUM(AB4:AB99) | AC100: =SUM(AC4:AC99) | AD100: =AD99 | AE100: =SUM(AE4:AE99) | AF100: =SUM(AF4:AF99) | AG100: =SUM(AG4:AG99) | AH100: =SUM(AH4:AH99) | AI100: =SUM(AI4:AI99) | AJ100: =SUM(AJ4:AJ99) | AK100: =SUM(AK4:AK99) | AL100: =SUM(AL4:AL99) | AM100: =AM99 | AN100: =AN99
A102: NOTES: ① Expand group D:X (click + above column D) to view per-client detail. ② Performance fee = simplified monthly accrual (AUM × monthly_return × perf_rate). ③ Exchange fee revenue = total contributions × exch_fee_rate × exch_fee_share (Variables). Applies to ZAR/USDT, USDT/BTC, and USDT/USDPC conversions. ④ Returns: 3-tier: 60% p.a. Y1-3 → 10% Y4 → 50% Y5-8 (next BTC cycle); all adjustable in Variables. ⑤ Reserve provision accumulates monthly (Y1-3) in the Reserve Fund Balance column; no automated drawdown — compare Reserve Fund Bal vs Cumulative Cash to assess Y4 coverage. ⑥ FINOVA CAPITAL costs: 20% of performance fees + 50% of platform fees (no fixed monthly hosting).

Sheet CHARTS
A1: BitWealth (Pty) Ltd — 96-Month Visual Summary · FSP: FINOVA CAPITAL
